Workbook
Name Class: SubjectDetails!$B$10
Name Class_AY: SubjectDetails!$B$10
Name Designation: SubjectDetails!$B$7
Name dir_wt: SubjectDetails!$B$17
Name ext_wt: SubjectDetails!$B$15
Name Faculty: SubjectDetails!$B$6
Name ind_wt: SubjectDetails!$B$18
Name int_wt: SubjectDetails!$B$14
Name spl: SubjectDetails!$B$11
Name Sub_Code: SubjectDetails!$B$8
Name Target: 60%
Name Type: SubjectDetails!$B$9

Sheet SubjectDetails
A1: Dr. D.Y. Patil Educational Federation's
A2: Dr. D. Y. Patil Institute of Management and Entreprenuer Development, Varale, Pune
A3: (Permanently affiliated to Savitribai Phule Pune University, Accredited by NAAC 'A'
A4: Approved by AICTE, Recognized under 2 (f) & 12 (b) sections of UGC Act)
A6: Name of the faculty: | B6: Narsareddy Chude, Sonali Late
A7: Designation: | B7: Assistant Professor
A8: Subject & Code: | B8: Java Programming
A9: Type of Course: | B9: Subject Core
A10: Class & A.Y.: | B10: MCA I SEM I AY 2023-24
A11: Specialization:
B13: % | C13: Marks
A14: Internal Assessment Weightage | B14: 0.34 | C14: 25
A15: External Assessment Weightage | B15: 0.66 | C15: 50
E16: =Faculty -> Narsareddy Chude, Sonali Late
A17: Direct Assessment Weightage | B17: 0.8 | E17: Subject Faculty
A18: Indirect Assessment Weightage | B18: 0.2
A24: Dr. Ravi Chourasiya | E24: Dr. Ashwini Chavan | H24: Dr. Priyanka Singh
A25: (College Examination Officer) | E25: HOD (MCA) | H25: Director

Sheet Rubrics
A1: Dr. D.Y. Patil Educational Federation's
A2: Dr. D. Y. Patil Institute of Management and Entreprenuer Development, Varale, Pune
A3: (Permanently affiliated to Savitribai Phule Pune University, Accredited by NAAC 'A'
A4: Approved by AICTE, Recognized under 2 (f) & 12 (b) sections of UGC Act)
A5: =CONCATENATE("Faculty Name: ", Faculty) -> Faculty Name: Narsareddy Chude, Sonali Late
A6: =CONCATENATE("Subject Name & Code: ", Sub_Code) -> Subject Name & Code: Java Programming
A7: =CONCATENATE("Class: ",Class_AY) -> Class: MCA I SEM I AY 2023-24
A9: Rubrics
A10: Criteria | C10: Excellent (100%) | F10: Good (80%) | I10: Satisfactory (60%) | L10: Needs Improvement (<60%)
A11: Understanding of Concepts | C11: Demonstrates in-depth understanding of accounting principles | F11: Shows solid understanding with minor gaps | I11: Basic understanding; lacks depth | L11: Limited or incorrect understanding
A12: Application of Tools | C12: Applies appropriate accounting tools and ratios with precision | F12: Mostly accurate application of tools | I12: Some errors in applying tools | L12: Incorrect or missing tools
A13: Interpretation & Decision-Making | C13: Insightful interpretation leading to strong recommendations | F13: Good interpretation and relevant decisions | I13: Somewhat relevant conclusions | L13: Weak or unsupported decisions
A14: Structure & Clarity | C14: Well-structured and clearly articulated | F14: Generally clear with minor issues | I14: Some structural issues | L14: Poorly organized and unclear
A15: References & Format | C15: Proper citations and professional format | F15: Minor errors in format | I15: Inconsistent or limited referencing | L15: Lacks proper citations and format
A18: =Faculty -> Narsareddy Chude, Sonali Late
A19: Subject Faculty
A24: =SubjectDetails!$A$24 -> Dr. Ravi Chourasiya | E24: =SubjectDetails!$E$24 -> Dr. Ashwini Chavan | I24: =SubjectDetails!$H$24 -> Dr. Priyanka Singh
A25: =SubjectDetails!$A$25 -> (College Examination Officer) | E25: =SubjectDetails!$E$25 -> HOD (MCA) | I25: =SubjectDetails!$H$25 -> Director

Sheet CO Mapping PO 
A1: Dr. D.Y. Patil Educational Federation's
A2: Dr. D. Y. Patil Institute of Management and Entreprenuer Development, Varale, Pune
A3: (Permanently affiliated to Savitribai Phule Pune University, Accredited by NAAC 'A'
A4: Approved by AICTE, Recognized under 2 (f) & 12 (b) sections of UGC Act)
A6: =CONCATENATE("Faculty Name: ", Faculty) -> Faculty Name: Narsareddy Chude, Sonali Late
A7: =CONCATENATE("Subject Name & Code: ", Sub_Code) -> Subject Name & Code: Java Programming
A8: =CONCATENATE("Class: ",Class_AY) -> Class: MCA I SEM I AY 2023-24
K9: Program OutComes
A10: COURSE OUTCOMES (CO) MAPPING WITH PROGRAM OUTCOMES (PO) | K10: PO1 (Foundation Knowledge): Apply knowledge of mathematics, programming logic and coding fundamentals for solution architecture and problem solving.
B11: PO1 | C11: PO2 | D11: PO3 | E11: PO4 | F11: PO5 | G11: PO6 | H11: PO7 | I11: PO8 | K11: PO2 (Problem Analysis): Identify, review, formulate and analyze problems for primarily focussing on customer requirements using critical thinking frameworks.
A12: CO1 | B12: 2 | C12: 1 | D12: 1 | E12: 2 | F12: - | G12: - | H12: - | I12: 2
A13: CO2 | B13: 2 | C13: 2 | D13: 2 | E13: 2 | F13: - | G13: - | H13: - | I13: 2 | K13: PO3 (Development of Solutions): Design, develop and investigate problems with as an innovative approach for solutions incorporating ESG/SDG goals.
A14: CO3 | B14: 2 | C14: 2 | D14: 2 | E14: 2 | F14: - | G14: - | H14: - | I14: 2
A15: CO4 | B15: 3 | C15: 2 | D15: 3 | E15: 3 | F15: 1 | G15: 1 | H15: - | I15: 2 | K15: PO4 (Modern Tool Usage): Select, adapt and apply modern computational tools such as development of algorithms with an understanding of the limitations including human biases.
A16: CO5 | B16: 3 | C16: 2 | D16: 3 | E16: 3 | F16: 1 | G16: 2 | H16: 1 | I16: 2
A17: CO6 | K17: PO5 (Individual and Teamwork): Function and communicate effectively as an individual or a team leader in diverse and multidisciplinary groups. Use methodologies such as agile.
A18: Average | B18: =AVERAGE(B12:B16) -> 2.4 | C18: =AVERAGE(C12:C16) -> 1.8 | D18: =AVERAGE(D12:D16) -> 2.2 | E18: =AVERAGE(E12:E16) -> 2.4 | F18: =AVERAGE(F12:F16) -> 1 | G18: =AVERAGE(G12:G16) -> 1.5 | H18: =AVERAGE(H12:H16) -> 1 | I18: =AVERAGE(I12:I16) -> 2
A19: 3-HIGH (corresponds to a high correlation) 2-MEDIUM (corresponds to a medium correlation) 1-LOW (corresponds to a low correlation) between CO and PO/PSO | K19: PO6 (Project Management and Finance): Use the principles of project management such as scheduling, work breakdown structure and be conversant with the principles of Finance for profitable project management.
K20: PO7 (Ethics): Commit to professional ethics in managing software projects with financial aspects. Learn to use new technologies for cyber security and insulate customers from malware
K22: PO8 (Life-long learning): Change management skills and the ability to learn, keep up with contemporary technologies and ways of working.
A24: =SubjectDetails!$E$16 -> Narsareddy Chude, Sonali Late | K24: Course OutComes
A25: =SubjectDetails!$E$17 -> Subject Faculty | K25: CO1 Understand Basic Concepts of OOPs, Java, Inheritance, Package. (Understand)
K26: CO2: Understand Exception handling, arrays and Strings and multi-threading in Java (Understand)
K27: CO3: Understand collection framework (Understand)
A28: =SubjectDetails!$A$24 -> Dr. Ravi Chourasiya | E28: =SubjectDetails!$E$24 -> Dr. Ashwini Chavan | I28: =SubjectDetails!$H$24 -> Dr. Priyanka Singh | K28: CO4: Develop GUI using Abstract Windows Toolkit (AWT) and event handling (Apply)
A29: =SubjectDetails!$A$25 -> (College Examination Officer) | E29: =SubjectDetails!$E$25 -> HOD (MCA) | I29: =SubjectDetails!$H$25 -> Director | K29: CO5: Develop Web application using JSP and Servlet, JDBC (Apply)

Sheet CCE1
A1: Dr. D.Y. Patil Educational Federation's
A2: Dr. D. Y. Patil Institute of Management and Entreprenuer Development, Varale, Pune
A3: (Permanently affiliated to Savitribai Phule Pune University, Accredited by NAAC 'A'
A4: Approved by AICTE, Recognized under 2 (f) & 12 (b) sections of UGC Act)
A5: Comprehensive Concurrent Evaluation (CCE) Sheet
A6: =CONCATENATE(Class," ", spl) -> MCA I SEM I AY 2023-24 | C6: =CONCATENATE("Name of Faculty: ", Faculty) -> Name of Faculty: Narsareddy Chude, Sonali Late | D6: =CONCATENATE("Course Name: ", Sub_Code) -> Course Name: Java Programming
A7: Roll No. | B7: Seat No. | C7: Name of the Student | D7: CCE-I (Mid Term 1) | G7: Total Marks Obtained
D8: Q1 | E8: Q2 | F8: Q3
C9: Max Marks → | D9: 10 | E9: 10 | F9: 10 | G9: =SUM(D9:F9) -> 30
C10: CO Mapping → | D10: CO1 | E10: CO1 | F10: CO2
A11: 1 | B11: 23101 | C11: ANERAO ONKAR RANGNATH | D11: 8 | E11: 5 | F11: 6 | G11: =IF(F11<>"AB",SUM(D11:F11),"AB") -> 19
A12: 2 | B12: 23102 | C12: ARGADE ABHISHEK | D12: 8 | E12: 3 | F12: 6 | G12: =IF(F12<>"AB",SUM(D12:F12),"AB") -> 17
A13: 3 | B13: 23103 | C13: BHAGAT DHANANJAY JAIRAM | D13: 3 | E13: 8 | F13: 6 | G13: =IF(F13<>"AB",SUM(D13:F13),"AB") -> 17
A14: 4 | B14: 23104 | C14: BHAGAT SANIKA SATISH | D14: 6 | E14: 8 | F14: 3 | G14: =IF(F14<>"AB",SUM(D14:F14),"AB") -> 17
A15: 5 | B15: 23105 | C15: BHAGWAT PRATIK ANIL | D15: 5 | E15: 5 | F15: 3 | G15: =IF(F15<>"AB",SUM(D15:F15),"AB") -> 13
A16: 6 | B16: 23106 | C16: BHAVIK ANAND SHASHIKANT | D16: 8 | E16: 6 | F16: 5 | G16: =IF(F16<>"AB",SUM(D16:F16),"AB") -> 19
A17: 7 | B17: 23107 | C17: BHOSALE SHIVAJI SANTOSH | D17: 3 | E17: 8 | F17: 8 | G17: =IF(F17<>"AB",SUM(D17:F17),"AB") -> 19
A18: 8 | B18: 23108 | C18: BRAMHANE DIPAK LAXMAN | D18: 8 | E18: 8 | F18: 8 | G18: =IF(F18<>"AB",SUM(D18:F18),"AB") -> 24
A19: 9 | B19: 23109 | C19: CHANDANKHEDE SEJAL ASHOK | D19: 8 | E19: 5 | F19: 6 | G19: =IF(F19<>"AB",SUM(D19:F19),"AB") -> 19
A20: 10 | B20: 23110 | C20: CHAUDHARY AKHILESH JEEVAN | D20: 8 | E20: 8 | F20: 5 | G20: =IF(F20<>"AB",SUM(D20:F20),"AB") -> 21
A21: 11 | B21: 23111 | C21: CHAUHAN ASHUTOSH SANJAYSINGH | D21: 5 | E21: 8 | F21: 8 | G21: =IF(F21<>"AB",SUM(D21:F21),"AB") -> 21
A22: 12 | B22: 23112 | C22: DHAGE SIDDHESH SUNIL | D22: 4 | E22: 4 | F22: 7 | G22: =IF(F22<>"AB",SUM(D22:F22),"AB") -> 15
... A121: 111 | B121: 23256 | C121: WAHATULE PAVAN RAOSAHEB | D121: 5 | E121: 7 | F121: 7 | G121: =IF(F121<>"AB",SUM(D121:F121),"AB") -> 19
D122: =D10 -> CO1 | E122: =E10 -> CO1 | F122: =F10 -> CO2 | G122: =G10 -> 0
B123: 1 | C123: No of Students (y) | D123: =IFERROR(COUNT(D11:D121),"NA") -> 111 | E123: =IFERROR(COUNT(E11:E121),"NA") -> 111 | F123: =IFERROR(COUNT(F11:F121),"NA") -> 111 | G123: =IFERROR(COUNT(G11:G121),"NA") -> 111
B124: 2 | C124: =CONCATENATE("No of students more than ",70, "% = (x1)") -> No of students more than 70% = (x1) | D124: =COUNTIF(D11:D121,">="&D9*70%) -> 41 | E124: =COUNTIF(E11:E121,">="&E9*70%) -> 48 | F124: =COUNTIF(F11:F121,">="&F9*70%) -> 56 | G124: =COUNTIF(G11:G121,">="&G9*70%) -> 27
B125: 3 | C125: =CONCATENATE("No of students between 70 and ",60, "% = (x2)") -> No of students between 70 and 60% = (x2) | D125: =COUNTIFS(D11:D121,">="&D9*60%,D11:D121,"<"&D9*70%) -> 36 | E125: =COUNTIFS(E11:E121,">="&E9*60%,E11:E121,"<"&E9*70%) -> 41 | F125: =COUNTIFS(F11:F121,">="&F9*60%,F11:F121,"<"&F9*70%) -> 31 | G125: =COUNTIFS(G11:G121,">="&G9*60%,G11:G121,"<"&G9*70%) -> 57
B126: 4 | C126: =CONCATENATE("No of students between 60 and ",50, "% = (x3)") -> No of students between 60 and 50% = (x3) | D126: =COUNTIFS(D11:D121,">="&D9*50%,D11:D121,"<"&D9*60%) -> 25 | E126: =COUNTIFS(E11:E121,">="&E9*50%,E11:E121,"<"&E9*60%) -> 14 | F126: =COUNTIFS(F11:F121,">="&F9*50%,F11:F121,"<"&F9*60%) -> 20 | G126: =COUNTIFS(G11:G121,">="&G9*50%,G11:G121,"<"&G9*60%) -> 25
B127: 5 | C127: No of students between 40 and 50 % = (x4) | D127: =COUNTIFS(D11:D121,">="&D9*40%,D11:D121,"<"&D9*50%) -> 7 | E127: =COUNTIFS(E11:E121,">="&E9*40%,E11:E121,"<"&E9*50%) -> 7 | F127: =COUNTIFS(F11:F121,">="&F9*40%,F11:F121,"<"&F9*50%) -> 2 | G127: =COUNTIFS(G11:G121,">="&G9*40%,G11:G121,"<"&G9*50%) -> 2
B128: 6 | C128: No of students between less than 40 % = (x5) | D128: =COUNTIF(D11:D121,"<"&D9*40%) -> 2 | E128: =COUNTIF(E11:E121,"<"&E9*40%) -> 1 | F128: =COUNTIF(F11:F121,"<"&F9*40%) -> 2 | G128: =COUNTIF(G11:G121,"<"&G9*40%) -> 0
B129: 7 | C129: CO Attainment Percentage | D129: =(D124*3+D125*2+D126*1)/(COUNT(D8:D121)*3)*100 -> 65.47619 | E129: =(E124*3+E125*2+E126*1)/(COUNT(E8:E121)*3)*100 -> 71.428571 | F129: =(F124*3+F125*2+F126*1)/(COUNT(F8:F121)*3)*100 -> 74.404762 | G129: =(G124*3+G125*2+G126*1)/(COUNT(G8:G121)*3)*100 -> 65.47619
B130: 8 | C130: CO Benchmark Level | D130: =IF(D129<>"NA",IF(D129>=70,3,IF(D129>=60,2,IF(D129>=50,1,"0"))),"NA") -> 2 | E130: =IF(E129<>"NA",IF(E129>=70,3,IF(E129>=60,2,IF(E129>=50,1,"0"))),"NA") -> 3 | F130: =IF(F129<>"NA",IF(F129>=70,3,IF(F129>=60,2,IF(F129>=50,1,"0"))),"NA") -> 3 | G130: =IF(G129<>"NA",IF(G129>=70,3,IF(G129>=60,2,IF(G129>=50,1,"0"))),"NA") -> 2
A134: =Faculty -> Narsareddy Chude, Sonali Late
A135: =SubjectDetails!E17 -> Subject Faculty

Sheet CCE2
A1: Dr. D.Y. Patil Educational Federation's
A2: Dr. D. Y. Patil Institute of Management and Entreprenuer Development, Varale, Pune
A3: (Permanently affiliated to Savitribai Phule Pune University, Accredited by NAAC 'A'
A4: Approved by AICTE, Recognized under 2 (f) & 12 (b) sections of UGC Act)
A5: Comprehensive Concurrent Evaluation (CCE) Sheet
A6: =CONCATENATE(Class," ", spl) -> MCA I SEM I AY 2023-24 | C6: =CONCATENATE("Name of Faculty: ", Faculty) -> Name of Faculty: Narsareddy Chude, Sonali Late | D6: =CONCATENATE("Course Name: ", Sub_Code) -> Course Name: Java Programming
A7: Roll No. | B7: Seat No. | C7: Name of the Student | D7: CCE-II (Assignment) | I7: Total Marks Obtained
D8: Q1 | E8: Q2 | F8: Q3 | G8: Q4 | H8: Q5
C9: Max Marks → | D9: 5 | E9: 5 | F9: 5 | G9: 5 | H9: 5 | I9: =D9+E9+F9+G9+H9 -> 25
C10: CO Mapping → | D10: CO1 | E10: CO2 | F10: CO3 | G10: CO4 | H10: CO5
A11: 1 | B11: 23101 | C11: ANERAO ONKAR RANGNATH | D11: 3 | E11: 3 | F11: 3 | G11: 3 | H11: 2 | I11: =IF(E11<>"AB",SUM(D11:H11),"AB") -> 14
A12: 2 | B12: 23102 | C12: ARGADE ABHISHEK | D12: 3 | E12: 5 | F12: 5 | G12: 3 | H12: 5 | I12: =IF(E12<>"AB",SUM(D12:H12),"AB") -> 21
A13: 3 | B13: 23103 | C13: BHAGAT DHANANJAY JAIRAM | D13: 3 | E13: 5 | F13: 3 | G13: 5 | H13: 3 | I13: =IF(E13<>"AB",SUM(D13:H13),"AB") -> 19
A14: 4 | B14: 23104 | C14: BHAGAT SANIKA SATISH | D14: 2 | E14: 3 | F14: 2 | G14: 5 | H14: 2 | I14: =IF(E14<>"AB",SUM(D14:H14),"AB") -> 14
A15: 5 | B15: 23105 | C15: BHAGWAT PRATIK ANIL | D15: 5 | E15: 3 | F15: 5 | G15: 5 | H15: 3 | I15: =IF(E15<>"AB",SUM(D15:H15),"AB") -> 21
A16: 6 | B16: 23106 | C16: BHAVIK ANAND SHASHIKANT | D16: 3 | E16: 3 | F16: 3 | G16: 3 | H16: 5 | I16: =IF(E16<>"AB",SUM(D16:H16),"AB") -> 17
A17: 7 | B17: 23107 | C17: BHOSALE SHIVAJI SANTOSH | D17: 2 | E17: 5 | F17: 3 | G17: 5 | H17: 3 | I17: =IF(E17<>"AB",SUM(D17:H17),"AB") -> 18
A18: 8 | B18: 23108 | C18: BRAMHANE DIPAK LAXMAN | D18: 3 | E18: 2 | F18: 3 | G18: 5 | H18: 3 | I18: =IF(E18<>"AB",SUM(D18:H18),"AB") -> 16
A19: 9 | B19: 23109 | C19: CHANDANKHEDE SEJAL ASHOK | D19: 5 | E19: 3 | F19: 5 | G19: 3 | H19: 3 | I19: =IF(E19<>"AB",SUM(D19:H19),"AB") -> 19
A20: 10 | B20: 23110 | C20: CHAUDHARY AKHILESH JEEVAN | D20: 3 | E20: 3 | F20: 3 | G20: 3 | H20: 4 | I20: =IF(E20<>"AB",SUM(D20:H20),"AB") -> 16
A21: 11 | B21: 23111 | C21: CHAUHAN ASHUTOSH SANJAYSINGH | D21: 3 | E21: 2 | F21: 3 | G21: 5 | H21: 4 | I21: =IF(E21<>"AB",SUM(D21:H21),"AB") -> 17
A22: 12 | B22: 23112 | C22: DHAGE SIDDHESH SUNIL | D22: 3 | E22: 4 | F22: 2 | G22: 2 | H22: 5 | I22: =IF(E22<>"AB",SUM(D22:H22),"AB") -> 16
... A121: 111 | B121: 23256 | C121: WAHATULE PAVAN RAOSAHEB | D121: 5 | E121: 4 | F121: 4 | G121: 4 | H121: 4 | I121: =IF(E121<>"AB",SUM(D121:H121),"AB") -> 21
D122: =D10 -> CO1 | E122: =E10 -> CO2 | F122: =F10 -> CO3 | G122: =G10 -> CO4 | H122: =H10 -> CO5
B123: 1 | C123: No of Students (y) | D123: =IFERROR(COUNT(D11:D121),"NA") -> 111 | E123: =IFERROR(COUNT(E11:E121),"NA") -> 111 | F123: =IFERROR(COUNT(F11:F121),"NA") -> 111 | G123: =IFERROR(COUNT(G11:G121),"NA") -> 111 | H123: =IFERROR(COUNT(H11:H121),"NA") -> 111
B124: 2 | C124: =CONCATENATE("No of students more than ",70, "% = (x1)") -> No of students more than 70% = (x1) | D124: =COUNTIF(D11:D121,">="&D9*70%) -> 66 | E124: =COUNTIF(E11:E121,">="&E9*70%) -> 73 | F124: =COUNTIF(F11:F121,">="&F9*70%) -> 62 | G124: =COUNTIF(G11:G121,">="&G9*70%) -> 77 | H124: =COUNTIF(H11:H121,">="&H9*70%) -> 67
B125: 3 | C125: =CONCATENATE("No of students between 70 and ",60, "% = (x2)") -> No of students between 70 and 60% = (x2) | D125: =COUNTIFS(D11:D121,">="&D9*60%,D11:D121,"<"&D9*70%) -> 39 | E125: =COUNTIFS(E11:E121,">="&E9*60%,E11:E121,"<"&E9*70%) -> 32 | F125: =COUNTIFS(F11:F121,">="&F9*60%,F11:F121,"<"&F9*70%) -> 38 | G125: =COUNTIFS(G11:G121,">="&G9*60%,G11:G121,"<"&G9*70%) -> 25 | H125: =COUNTIFS(H11:H121,">="&H9*60%,H11:H121,"<"&H9*70%) -> 37
B126: 4 | C126: =CONCATENATE("No of students between 60 and ",50, "% = (x3)") -> No of students between 60 and 50% = (x3) | D126: =COUNTIFS(D11:D121,">="&D9*50%,D11:D121,"<"&D9*60%) -> 0 | E126: =COUNTIFS(E11:E121,">="&E9*50%,E11:E121,"<"&E9*60%) -> 0 | F126: =COUNTIFS(F11:F121,">="&F9*50%,F11:F121,"<"&F9*60%) -> 0 | G126: =COUNTIFS(G11:G121,">="&G9*50%,G11:G121,"<"&G9*60%) -> 0 | H126: =COUNTIFS(H11:H121,">="&H9*50%,H11:H121,"<"&H9*60%) -> 0
B127: 5 | C127: No of students between 40 and 50 % = (x4) | D127: =COUNTIFS(D11:D121,">="&D9*40%,D11:D121,"<"&D9*50%) -> 6 | E127: =COUNTIFS(E11:E121,">="&E9*40%,E11:E121,"<"&E9*50%) -> 6 | F127: =COUNTIFS(F11:F121,">="&F9*40%,F11:F121,"<"&F9*50%) -> 11 | G127: =COUNTIFS(G11:G121,">="&G9*40%,G11:G121,"<"&G9*50%) -> 9 | H127: =COUNTIFS(H11:H121,">="&H9*40%,H11:H121,"<"&H9*50%) -> 7
B128: 6 | C128: No of students between less than 40 % = (x5) | D128: =COUNTIF(D11:D121,"<"&D9*40%) -> 0 | E128: =COUNTIF(E11:E121,"<"&E9*40%) -> 0 | F128: =COUNTIF(F11:F121,"<"&F9*40%) -> 0 | G128: =COUNTIF(G11:G121,"<"&G9*40%) -> 0 | H128: =COUNTIF(H11:H121,"<"&H9*40%) -> 0
B129: 7 | C129: CO Attainment Percentage | D129: =(D124*3+D125*2+D126*1)/(COUNT(D8:D121)*3)*100 -> 82.142857 | E129: =(E124*3+E125*2+E126*1)/(COUNT(E8:E121)*3)*100 -> 84.22619 | F129: =(F124*3+F125*2+F126*1)/(COUNT(F8:F121)*3)*100 -> 77.97619 | G129: =(G124*3+G125*2+G126*1)/(COUNT(G8:G121)*3)*100 -> 83.630952 | H129: =(H124*3+H125*2+H126*1)/(COUNT(H8:H121)*3)*100 -> 81.845238
B130: 8 | C130: CO Benchmark Level | D130: =IF(D129<>"NA",IF(D129>=70,3,IF(D129>=60,2,IF(D129>=50,1,"0"))),"NA") -> 3 | E130: =IF(E129<>"NA",IF(E129>=70,3,IF(E129>=60,2,IF(E129>=50,1,"0"))),"NA") -> 3 | F130: =IF(F129<>"NA",IF(F129>=70,3,IF(F129>=60,2,IF(F129>=50,1,"0"))),"NA") -> 3 | G130: =IF(G129<>"NA",IF(G129>=70,3,IF(G129>=60,2,IF(G129>=50,1,"0"))),"NA") -> 3 | H130: =IF(H129<>"NA",IF(H129>=70,3,IF(H129>=60,2,IF(H129>=50,1,"0"))),"NA") -> 3

Sheet CCE3
A1: Dr. D.Y. Patil Educational Federation's
A2: Dr. D. Y. Patil Institute of Management and Entreprenuer Development, Varale, Pune
A3: (Permanently affiliated to Savitribai Phule Pune University, Accredited by NAAC 'A'
A4: Approved by AICTE, Recognized under 2 (f) & 12 (b) sections of UGC Act)
A5: Comprehensive Concurrent Evaluation (CCE) Sheet
A6: =CONCATENATE(Class," ", spl) -> MCA I SEM I AY 2023-24 | C6: =CONCATENATE("Name of Faculty: ", Faculty) -> Name of Faculty: Narsareddy Chude, Sonali Late | D6: =CONCATENATE("Course Name: ", Sub_Code) -> Course Name: Java Programming
A7: Roll No. | B7: Seat No. | C7: Name of the Student | D7: CCE-III (End Term) | N7: Total Marks Obtained
D8: Q1 | E8: Q2 | F8: Q3 | G8: Q4 | H8: Q5
C9: Max Marks → | D9: CO1 | E9: CO2 | F9: CO3 | G9: CO4 | H9: CO5 | N9: =D9+E9+F9+G9+H9+I9+J9+K9+L9+M9 -> #VALUE!
C10: CO Mapping → | D10: 10 | E10: 10 | F10: 10 | G10: 10 | H10: 10
A11: 1 | B11: 23101 | C11: ANERAO ONKAR RANGNATH | D11: 8 | E11: 8 | F11: 8 | G11: 5 | H11: 8 | N11: =IF(D11<>"AB",SUM(D11:M11),"AB") -> 37
A12: 2 | B12: 23102 | C12: ARGADE ABHISHEK | D12: 5 | E12: 8 | F12: 8 | G12: 6 | H12: 8 | N12: =IF(D12<>"AB",SUM(D12:M12),"AB") -> 35
A13: 3 | B13: 23103 | C13: BHAGAT DHANANJAY JAIRAM | D13: 5 | E13: 8 | F13: 6 | G13: 5 | H13: 5 | N13: =IF(D13<>"AB",SUM(D13:M13),"AB") -> 29
A14: 4 | B14: 23104 | C14: BHAGAT SANIKA SATISH | D14: 8 | E14: 8 | F14: 6 | G14: 3 | H14: 6 | N14: =IF(D14<>"AB",SUM(D14:M14),"AB") -> 31
A15: 5 | B15: 23105 | C15: BHAGWAT PRATIK ANIL | D15: 8 | E15: 5 | F15: 5 | G15: 6 | H15: 3 | N15: =IF(D15<>"AB",SUM(D15:M15),"AB") -> 27
A16: 6 | B16: 23106 | C16: BHAVIK ANAND SHASHIKANT | D16: 8 | E16: 8 | F16: 8 | G16: 6 | H16: 3 | N16: =IF(D16<>"AB",SUM(D16:M16),"AB") -> 33
A17: 7 | B17: 23107 | C17: BHOSALE SHIVAJI SANTOSH | D17: 8 | E17: 8 | F17: 8 | G17: 8 | H17: 8 | N17: =IF(D17<>"AB",SUM(D17:M17),"AB") -> 40
A18: 8 | B18: 23108 | C18: BRAMHANE DIPAK LAXMAN | D18: 6 | E18: 8 | F18: 8 | G18: 8 | H18: 3 | N18: =IF(D18<>"AB",SUM(D18:M18),"AB") -> 33
A19: 9 | B19: 23109 | C19: CHANDANKHEDE SEJAL ASHOK | D19: 5 | E19: 8 | F19: 3 | G19: 8 | H19: 8 | N19: =IF(D19<>"AB",SUM(D19:M19),"AB") -> 32
A20: 10 | B20: 23110 | C20: CHAUDHARY AKHILESH JEEVAN | D20: 4 | E20: 8 | F20: 6 | G20: 8 | H20: 8 | N20: =IF(D20<>"AB",SUM(D20:M20),"AB") -> 34
A21: 11 | B21: 23111 | C21: CHAUHAN ASHUTOSH SANJAYSINGH | D21: 6 | E21: 8 | F21: 6 | G21: 8 | H21: 8 | N21: =IF(D21<>"AB",SUM(D21:M21),"AB") -> 36
A22: 12 | B22: 23112 | C22: DHAGE SIDDHESH SUNIL | D22: 8 | E22: 6 | F22: 7 | G22: 6 | H22: 7 | N22: =IF(D22<>"AB",SUM(D22:M22),"AB") -> 34
... A118: 108 | B118: 23253 | C118: THATHAGAR VAIBHAV DHARMENDRA | D118: 7 | E118: 8 | F118: 5 | G118: 5 | H118: 6 | N118: =IF(D118<>"AB",SUM(D118:M118),"AB") -> 31
A119: 109 | B119: 23254 | C119: VARGANTI AARTI YALLAPPA | D119: 5 | E119: 6 | F119: 7 | G119: 5 | H119: 5
A120: 110 | B120: 23255 | C120: WADHAVE SHUBHAM SUDHAKAR | D120: 7 | E120: 5 | F120: 7 | G120: 7 | H120: 7
A121: 111 | B121: 23256 | C121: WAHATULE PAVAN RAOSAHEB | D121: 7 | E121: 7 | F121: 6 | G121: 6 | H121: 6
D122: =D9 -> CO1 | E122: =E9 -> CO2 | F122: =F9 -> CO3 | G122: =G9 -> CO4 | H122: =H9 -> CO5
B123: 1 | C123: No of Students (y) | D123: =IFERROR(COUNT(D11:D121),"NA") -> 111 | E123: =IFERROR(COUNT(E11:E121),"NA") -> 111 | F123: =IFERROR(COUNT(F11:F121),"NA") -> 111 | G123: =IFERROR(COUNT(G11:G121),"NA") -> 111 | H123: =IFERROR(COUNT(H11:H121),"NA") -> 111
B124: 2 | C124: =CONCATENATE("No of students more than ",70, "% = (x1)") -> No of students more than 70% = (x1) | D124: =COUNTIF(D11:D121,">="&D10*70%) -> 61 | E124: =COUNTIF(E11:E121,">="&E10*70%) -> 86 | F124: =COUNTIF(F11:F121,">="&F10*70%) -> 80 | G124: =COUNTIF(G11:G121,">="&G10*70%) -> 82 | H124: =COUNTIF(H11:H121,">="&H10*70%) -> 79
B125: 3 | C125: =CONCATENATE("No of students between 70 and ",60, "% = (x2)") -> No of students between 70 and 60% = (x2) | D125: =COUNTIFS(D11:D121,">="&D10*60%,D11:D121,"<"&D10*70%) -> 18 | E125: =COUNTIFS(E11:E121,">="&E10*60%,E11:E121,"<"&E10*70%) -> 21 | F125: =COUNTIFS(F11:F121,">="&F10*60%,F11:F121,"<"&F10*70%) -> 20 | G125: =COUNTIFS(G11:G121,">="&G10*60%,G11:G121,"<"&G10*70%) -> 20 | H125: =COUNTIFS(H11:H121,">="&H10*60%,H11:H121,"<"&H10*70%) -> 26
B126: 4 | C126: =CONCATENATE("No of students between 60 and ",50, "% = (x3)") -> No of students between 60 and 50% = (x3) | D126: =COUNTIFS(D11:D121,">="&D10*50%,D11:D121,"<"&D10*60%) -> 31 | E126: =COUNTIFS(E11:E121,">="&E10*50%,E11:E121,"<"&E10*60%) -> 3 | F126: =COUNTIFS(F11:F121,">="&F10*50%,F11:F121,"<"&F10*60%) -> 3 | G126: =COUNTIFS(G11:G121,">="&G10*50%,G11:G121,"<"&G10*60%) -> 4 | H126: =COUNTIFS(H11:H121,">="&H10*50%,H11:H121,"<"&H10*60%) -> 2
B127: 5 | C127: No of students between 40 and 50 % = (x4) | D127: =COUNTIFS(D11:D121,">="&D10*40%,D11:D121,"<"&D10*50%) -> 1 | E127: =COUNTIFS(E11:E121,">="&E10*40%,E11:E121,"<"&E10*50%) -> 1 | F127: =COUNTIFS(F11:F121,">="&F10*40%,F11:F121,"<"&F10*50%) -> 7 | G127: =COUNTIFS(G11:G121,">="&G10*40%,G11:G121,"<"&G10*50%) -> 4 | H127: =COUNTIFS(H11:H121,">="&H10*40%,H11:H121,"<"&H10*50%) -> 1
B128: 6 | C128: No of students between less than 40 % = (x5) | D128: =COUNTIF(D11:D121,"<"&D10*40%) -> 0 | E128: =COUNTIF(E11:E121,"<"&E10*40%) -> 0 | F128: =COUNTIF(F11:F121,"<"&F10*40%) -> 1 | G128: =COUNTIF(G11:G121,"<"&G10*40%) -> 1 | H128: =COUNTIF(H11:H121,"<"&H10*40%) -> 3
B129: 7 | C129: CO Attainment Percentage | D129: =(D124*3+D125*2+D126*1)/(COUNT(D8:D121)*3)*100 -> 74.404762 | E129: =(E124*3+E125*2+E126*1)/(COUNT(E8:E121)*3)*100 -> 90.178571 | F129: =(F124*3+F125*2+F126*1)/(COUNT(F8:F121)*3)*100 -> 84.22619 | G129: =(G124*3+G125*2+G126*1)/(COUNT(G8:G121)*3)*100 -> 86.309524 | H129: =(H124*3+H125*2+H126*1)/(COUNT(H8:H121)*3)*100 -> 86.607143
B130: 8 | C130: CO Benchmark Level | D130: =IF(D129<>"NA",IF(D129>=70,3,IF(D129>=60,2,IF(D129>=50,1,"0"))),"NA") -> 3 | E130: =IF(E129<>"NA",IF(E129>=70,3,IF(E129>=60,2,IF(E129>=50,1,"0"))),"NA") -> 3 | F130: =IF(F129<>"NA",IF(F129>=70,3,IF(F129>=60,2,IF(F129>=50,1,"0"))),"NA") -> 3 | G130: =IF(G129<>"NA",IF(G129>=70,3,IF(G129>=60,2,IF(G129>=50,1,"0"))),"NA") -> 3 | H130: =IF(H129<>"NA",IF(H129>=70,3,IF(H129>=60,2,IF(H129>=50,1,"0"))),"NA") -> 3

Sheet CCE
A1: Dr. D.Y. Patil Educational Federation's
A2: Dr. D. Y. Patil Institute of Management and Entreprenuer Development, Varale, Pune
A3: (Permanently affiliated to Savitribai Phule Pune University, Accredited by NAAC 'A'
A4: Approved by AICTE, Recognized under 2 (f) & 12 (b) sections of UGC Act)
A5: Comprehensive Concurrent Evaluation (CCE) Sheet
A6: =CONCATENATE(Class," ", spl) -> MCA I SEM I AY 2023-24 | C6: =CONCATENATE("Name of Faculty: ", Faculty) -> Name of Faculty: Narsareddy Chude, Sonali Late | D6: =CONCATENATE("Course Name: ", Sub_Code) -> Course Name: Java Programming
A7: Roll No. | B7: Seat No. | C7: Name | D7: CCE#1 (30) | E7: CCE#2 (20) | F7: CCE#3 (50) | G7: Total (100) | H7: Final (25)
A8: 1 | B8: 22101 | C8: NAIK ANKIT JIVAN | D8: ='CCE1'!G11 -> 19 | E8: ='CCE2'!I11 -> 14 | F8: ='CCE3'!N11 -> 37 | G8: =SUM(Table3[[#This Row],[CCE'#1 (30)]:[CCE'#3 (50)]]) -> 70 | H8: =G8/4 -> 17.5
A9: 2 | B9: 22102 | C9: ARGADE RAVISHANKAR UTTAM | D9: ='CCE1'!G12 -> 17 | E9: ='CCE2'!I12 -> 21 | F9: ='CCE3'!N12 -> 35 | G9: =SUM(Table3[[#This Row],[CCE'#1 (30)]:[CCE'#3 (50)]]) -> 73 | H9: =G9/4 -> 18.25
A10: 3 | B10: 22103 | C10: ANERAO ONKAR RANGNATH | D10: ='CCE1'!G13 -> 17 | E10: ='CCE2'!I13 -> 19 | F10: ='CCE3'!N13 -> 29 | G10: =SUM(Table3[[#This Row],[CCE'#1 (30)]:[CCE'#3 (50)]]) -> 65 | H10: =G10/4 -> 16.25
A11: 4 | B11: 22104 | C11: MORE KIRAN SUNIL | D11: ='CCE1'!G14 -> 17 | E11: ='CCE2'!I14 -> 14 | F11: ='CCE3'!N14 -> 31 | G11: =SUM(Table3[[#This Row],[CCE'#1 (30)]:[CCE'#3 (50)]]) -> 62 | H11: =G11/4 -> 15.5
A12: 5 | B12: 22105 | C12: KSHIRSAGAR GAURAV SHRIKANT | D12: ='CCE1'!G15 -> 13 | E12: ='CCE2'!I15 -> 21 | F12: ='CCE3'!N15 -> 27 | G12: =SUM(Table3[[#This Row],[CCE'#1 (30)]:[CCE'#3 (50)]]) -> 61 | H12: =G12/4 -> 15.25
A13: 6 | B13: 22106 | C13: SHIRSAT MEGHA SHARAD | D13: ='CCE1'!G16 -> 19 | E13: ='CCE2'!I16 -> 17 | F13: ='CCE3'!N16 -> 33 | G13: =SUM(Table3[[#This Row],[CCE'#1 (30)]:[CCE'#3 (50)]]) -> 69 | H13: =G13/4 -> 17.25
A14: 7 | B14: 22107 | C14: INGALE RAHUL SUNIL | D14: ='CCE1'!G17 -> 19 | E14: ='CCE2'!I17 -> 18 | F14: ='CCE3'!N17 -> 40 | G14: =SUM(Table3[[#This Row],[CCE'#1 (30)]:[CCE'#3 (50)]]) -> 77 | H14: =G14/4 -> 19.25
A15: 8 | B15: 22108 | C15: MD TABISH ANWAR | D15: ='CCE1'!G18 -> 24 | E15: ='CCE2'!I18 -> 16 | F15: ='CCE3'!N18 -> 33 | G15: =SUM(Table3[[#This Row],[CCE'#1 (30)]:[CCE'#3 (50)]]) -> 73 | H15: =G15/4 -> 18.25
A16: 9 | B16: 22109 | C16: PUND SUYOG BHARAT | D16: ='CCE1'!G19 -> 19 | E16: ='CCE2'!I19 -> 19 | F16: ='CCE3'!N19 -> 32 | G16: =SUM(Table3[[#This Row],[CCE'#1 (30)]:[CCE'#3 (50)]]) -> 70 | H16: =G16/4 -> 17.5
A17: 10 | B17: 22110 | C17: JAGTAP DNYANESHWAR RAGHUNATH | D17: ='CCE1'!G20 -> 21 | E17: ='CCE2'!I20 -> 16 | F17: ='CCE3'!N20 -> 34 | G17: =SUM(Table3[[#This Row],[CCE'#1 (30)]:[CCE'#3 (50)]]) -> 71 | H17: =G17/4 -> 17.75
A18: 11 | B18: 22111 | C18: MAHAJAN PRATHAMESH JAGDISH | D18: ='CCE1'!G21 -> 21 | E18: ='CCE2'!I21 -> 17 | F18: ='CCE3'!N21 -> 36 | G18: =SUM(Table3[[#This Row],[CCE'#1 (30)]:[CCE'#3 (50)]]) -> 74 | H18: =G18/4 -> 18.5
A19: 12 | B19: 22112 | C19: PATHAN ALIZABEE AKHTAR KHAN | D19: ='CCE1'!G22 -> 15 | E19: ='CCE2'!I22 -> 16 | F19: ='CCE3'!N22 -> 34 | G19: =SUM(Table3[[#This Row],[CCE'#1 (30)]:[CCE'#3 (50)]]) -> 65 | H19: =G19/4 -> 16.25
... A25: 18 | B25: 22118 | C25: SHINDE MAHESH DHANAJI | D25: ='CCE1'!G28 -> 14 | E25: ='CCE2'!I28 -> 19 | F25: ='CCE3'!N28 -> 34 | G25: =SUM(Table3[[#This Row],[CCE'#1 (30)]:[CCE'#3 (50)]]) -> 67 | H25: =G25/4 -> 16.75
A26: 19 | B26: 22119 | C26: BHISE DIPAK VETALA | D26: ='CCE1'!G11 -> 19 | E26: ='CCE2'!I29 -> 21 | F26: ='CCE3'!N29 -> 35 | G26: =SUM(Table3[[#This Row],[CCE'#1 (30)]:[CCE'#3 (50)]]) -> 75 | H26: =G26/4 -> 18.75
A27: 20 | B27: 22120 | C27: BHAGWAT SHREYAS RAVINDRA | D27: ='CCE1'!G12 -> 17 | E27: ='CCE2'!I30 -> 22 | F27: ='CCE3'!N30 -> 34 | G27: =SUM(Table3[[#This Row],[CCE'#1 (30)]:[CCE'#3 (50)]]) -> 73 | H27: =G27/4 -> 18.25
A28: 21 | B28: 22121 | C28: RAHUL VILAS THORAT | D28: ='CCE1'!G13 -> 17 | E28: ='CCE2'!I31 -> 13 | F28: ='CCE3'!N31 -> 35 | G28: =SUM(Table3[[#This Row],[CCE'#1 (30)]:[CCE'#3 (50)]]) -> 65 | H28: =G28/4 -> 16.25
A29: 22 | B29: 22122 | C29: AVINASH BAPU MANE | D29: ='CCE1'!G14 -> 17 | E29: ='CCE2'!I32 -> 19 | F29: ='CCE3'!N32 -> 36 | G29: =SUM(Table3[[#This Row],[CCE'#1 (30)]:[CCE'#3 (50)]]) -> 72 | H29: =G29/4 -> 18
A30: 23 | B30: 22123 | C30: SHELKE VAIBHAV MACHHINDRA | D30: ='CCE1'!G15 -> 13 | E30: ='CCE2'!I33 -> 22 | F30: ='CCE3'!N33 -> 35 | G30: =SUM(Table3[[#This Row],[CCE'#1 (30)]:[CCE'#3 (50)]]) -> 70 | H30: =G30/4 -> 17.5
A31: 24 | B31: 22124 | C31: VIJAY SUDHAKAR LOKARE | D31: ='CCE1'!G16 -> 19 | E31: ='CCE2'!I34 -> 21 | F31: ='CCE3'!N34 -> 33 | G31: =SUM(Table3[[#This Row],[CCE'#1 (30)]:[CCE'#3 (50)]]) -> 73 | H31: =G31/4 -> 18.25
A32: 25 | B32: 22125 | C32: CHANDANKHEDE SEJAL ASHOK | D32: ='CCE1'!G17 -> 19 | E32: ='CCE2'!I35 -> 18 | F32: ='CCE3'!N35 -> 35 | G32: =SUM(Table3[[#This Row],[CCE'#1 (30)]:[CCE'#3 (50)]]) -> 72 | H32: =G32/4 -> 18
A33: 26 | B33: 22126 | C33: VAISHNAVI SAYAJI PINGAT | D33: ='CCE1'!G18 -> 24 | E33: ='CCE2'!I36 -> 19 | F33: ='CCE3'!N36 -> 39 | G33: =SUM(Table3[[#This Row],[CCE'#1 (30)]:[CCE'#3 (50)]]) -> 82 | H33: =G33/4 -> 20.5
A34: 27 | B34: 22127 | C34: BORSE NIKITA BHALERAO | D34: ='CCE1'!G19 -> 19 | E34: ='CCE2'!I37 -> 20 | F34: ='CCE3'!N37 -> 37 | G34: =SUM(Table3[[#This Row],[CCE'#1 (30)]:[CCE'#3 (50)]]) -> 76 | H34: =G34/4 -> 19
A35: 28 | B35: 22128 | C35: RADHIKA NARAYAN SHELAR | D35: ='CCE1'!G20 -> 21 | E35: ='CCE2'!I38 -> 19 | F35: ='CCE3'!N38 -> 34 | G35: =SUM(Table3[[#This Row],[CCE'#1 (30)]:[CCE'#3 (50)]]) -> 74 | H35: =G35/4 -> 18.5
A36: 29 | B36: 22129 | C36: BRAMHANE DIPAK LAXMAN | D36: ='CCE1'!G21 -> 21 | E36: ='CCE2'!I39 -> 19 | F36: ='CCE3'!N39 -> 31 | G36: =SUM(Table3[[#This Row],[CCE'#1 (30)]:[CCE'#3 (50)]]) -> 71 | H36: =G36/4 -> 17.75
A37: 30 | B37: 22130 | C37: PHATKE SAKSHI SANTOSH | D37: ='CCE1'!G22 -> 15 | E37: ='CCE2'!I40 -> 18 | F37: ='CCE3'!N40 -> 33 | G37: =SUM(Table3[[#This Row],[CCE'#1 (30)]:[CCE'#3 (50)]]) -> 66 | H37: =G37/4 -> 16.5
... A86: 79 | B86: 22211 | C86: GANDAGE GANPATI DAYANAND | D86: ='CCE1'!G71 -> 22 | E86: ='CCE2'!I89 -> 18 | F86: ='CCE3'!N89 -> 35 | G86: =SUM(Table3[[#This Row],[CCE'#1 (30)]:[CCE'#3 (50)]]) -> 75 | H86: =G86/4 -> 18.75
A87: 80 | B87: 22212 | C87: SURYAWANSHI DIVYA BAJRANG | D87: ='CCE1'!G11 -> 19 | E87: ='CCE2'!I90 -> 21 | F87: ='CCE3'!N90 -> 37 | G87: =SUM(Table3[[#This Row],[CCE'#1 (30)]:[CCE'#3 (50)]]) -> 77 | H87: =G87/4 -> 19.25
A88: 81 | B88: 22213 | C88: KAMBLE YOGESH ARJUN | D88: ='CCE1'!G12 -> 17 | E88: ='CCE2'!I91 -> 22 | F88: ='CCE3'!N91 -> 36 | G88: =SUM(Table3[[#This Row],[CCE'#1 (30)]:[CCE'#3 (50)]]) -> 75 | H88: =G88/4 -> 18.75
A89: 82 | B89: 22214 | C89: CHAUHAN MANAV JIGAR KUMAR | D89: ='CCE1'!G13 -> 17 | E89: ='CCE2'!I92 -> 18 | F89: ='CCE3'!N92 -> 32 | G89: =SUM(Table3[[#This Row],[CCE'#1 (30)]:[CCE'#3 (50)]]) -> 67 | H89: =G89/4 -> 16.75
A90: 83 | B90: 22215 | C90: AJAY SATISH MANE | D90: ='CCE1'!G14 -> 17 | E90: ='CCE2'!I93 -> 21 | F90: ='CCE3'!N93 -> 31 | G90: =SUM(Table3[[#This Row],[CCE'#1 (30)]:[CCE'#3 (50)]]) -> 69 | H90: =G90/4 -> 17.25
A91: 84 | B91: 22216 | C91: CHOUDHARI SIDDHESH MURALIDHAR | D91: ='CCE1'!G15 -> 13 | E91: ='CCE2'!I94 -> 19 | F91: ='CCE3'!N94 -> 35 | G91: =SUM(Table3[[#This Row],[CCE'#1 (30)]:[CCE'#3 (50)]]) -> 67 | H91: =G91/4 -> 16.75
A92: 85 | B92: 22217 | C92: VARGANTI AARTI YALLAPPA | D92: ='CCE1'!G16 -> 19 | E92: ='CCE2'!I95 -> 20 | F92: ='CCE3'!N95 -> 34 | G92: =SUM(Table3[[#This Row],[CCE'#1 (30)]:[CCE'#3 (50)]]) -> 73 | H92: =G92/4 -> 18.25
A93: 86 | B93: 22218 | C93: KHAIRE PRATIKSHA KAILAS | D93: ='CCE1'!G17 -> 19 | E93: ='CCE2'!I96 -> 20 | F93: ='CCE3'!N96 -> 35 | G93: =SUM(Table3[[#This Row],[CCE'#1 (30)]:[CCE'#3 (50)]]) -> 74 | H93: =G93/4 -> 18.5
...

Sheet CO Int. Attn
A1: Dr. D.Y. Patil Educational Federation's
A2: Dr. D. Y. Patil Institute of Management and Entreprenuer Development, Varale, Pune
A3: (Permanently affiliated to Savitribai Phule Pune University, Accredited by NAAC 'A'
A4: Approved by AICTE, Recognized under 2 (f) & 12 (b) sections of UGC Act)
A6: =CONCATENATE("Faculty Name: ", Faculty) -> Faculty Name: Narsareddy Chude, Sonali Late | F6: Benchmarks | I6: 3 | K6: 70 | L6: % of Students to get | P6: 0.6
A7: =CONCATENATE("Subject Name & Code: ", Sub_Code) -> Subject Name & Code: Java Programming | I7: 2 | K7: 60 | R7: 60
A8: =CONCATENATE("Class: ",Class_AY) -> Class: MCA I SEM I AY 2023-24 | I8: 1 | K8: 50
A11: Sr. No | B11: Seat No. | C11: Name of the Student | D11: CCE1 (Mid Term: 30) | F11: CCE2 (Assignment :20) | K11: CCE3 (End term:50) | P11: Combined Assessment Marks for COs (100) | U11: Total Marks Obtained (25)
D12: CO1 | E12: CO2 | F12: CO1 | G12: CO2 | H12: CO3 | I12: CO4 | J12: CO5 | K12: CO1 | L12: CO2 | M12: CO3 | N12: CO4 | O12: CO5 | P12: CO1 | Q12: CO2 | R12: CO3 | S12: CO4 | T12: CO5
D13: ='CCE1'!D9+'CCE1'!E9 -> 20 | E13: ='CCE1'!F9 -> 10 | F13: ='CCE2'!D9 -> 5 | G13: ='CCE2'!E9 -> 5 | H13: ='CCE2'!F9 -> 5 | I13: ='CCE2'!G9 -> 5 | J13: ='CCE2'!H9 -> 5 | K13: ='CCE3'!D9+'CCE3'!E9 -> #VALUE! | L13: ='CCE3'!F9+'CCE3'!G9 -> #VALUE! | M13: ='CCE3'!H9+'CCE3'!I9 -> #VALUE! | N13: ='CCE3'!K9+'CCE3'!K9 -> 0 | O13: ='CCE3'!L9+'CCE3'!M9 -> 0 | P13: =D13+F13+K13 -> #VALUE! | Q13: =E13+G13+L13 -> #VALUE! | R13: =#REF!+H13+M13 -> #REF! | S13: =#REF!+I13+N13 -> #REF! | T13: =#REF!+J13+O13 -> #REF! | U13: =SUM(P13:T13) -> #VALUE!
A14: 1 | B14: 23101 | C14: ANERAO ONKAR RANGNATH | D14: ='CCE1'!D11+'CCE1'!E11 -> 13 | E14: ='CCE1'!E11+'CCE1'!F11 -> 11 | F14: ='CCE2'!D11 -> 3 | G14: ='CCE2'!E11 -> 3 | H14: ='CCE2'!F11 -> 3 | I14: ='CCE2'!G11 -> 3 | J14: ='CCE2'!H11 -> 2 | K14: ='CCE3'!D11+'CCE3'!E11 -> 16 | L14: ='CCE3'!F11+'CCE3'!G11 -> 13 | M14: ='CCE3'!H11+'CCE3'!I11 -> 8 | N14: ='CCE3'!J11+'CCE3'!K11 -> 0 | O14: ='CCE3'!L11+'CCE3'!M11 -> 0 | P14: =IFERROR(SUM(D14,F14,K14),"AB") -> 32 | Q14: =IFERROR(SUM(E14,G14,L14),"AB") -> 27 | R14: =IFERROR(SUM(#REF!,H14,M14),"AB") -> AB | S14: =IFERROR(SUM(#REF!,I14,N14),"AB") -> AB | T14: =IFERROR(SUM(#REF!,J14,O14),"AB") -> AB | U14: =IFERROR(SUM(P14:T14),"AB") -> 59
A15: 2 | B15: 23102 | C15: ARGADE ABHISHEK | D15: ='CCE1'!D12+'CCE1'!E12 -> 11 | E15: ='CCE1'!E12+'CCE1'!F12 -> 9 | F15: ='CCE2'!D12 -> 3 | G15: ='CCE2'!E12 -> 5 | H15: ='CCE2'!F12 -> 5 | I15: ='CCE2'!G12 -> 3 | J15: ='CCE2'!H12 -> 5 | K15: ='CCE3'!D12+'CCE3'!E12 -> 13 | L15: ='CCE3'!F12+'CCE3'!G12 -> 14 | M15: ='CCE3'!H12+'CCE3'!I12 -> 8 | N15: ='CCE3'!J12+'CCE3'!K12 -> 0 | O15: ='CCE3'!L12+'CCE3'!M12 -> 0 | P15: =IFERROR(SUM(D15,F15,K15),"AB") -> 27 | Q15: =IFERROR(SUM(E15,G15,L15),"AB") -> 28 | R15: =IFERROR(SUM(#REF!,H15,M15),"AB") -> AB | S15: =IFERROR(SUM(#REF!,I15,N15),"AB") -> AB | T15: =IFERROR(SUM(#REF!,J15,O15),"AB") -> AB | U15: =IFERROR(SUM(P15:T15),"AB") -> 55
A16: 3 | B16: 23103 | C16: BHAGAT DHANANJAY JAIRAM | D16: ='CCE1'!D13+'CCE1'!E13 -> 11 | E16: ='CCE1'!E13+'CCE1'!F13 -> 14 | F16: ='CCE2'!D13 -> 3 | G16: ='CCE2'!E13 -> 5 | H16: ='CCE2'!F13 -> 3 | I16: ='CCE2'!G13 -> 5 | J16: ='CCE2'!H13 -> 3 | K16: ='CCE3'!D13+'CCE3'!E13 -> 13 | L16: ='CCE3'!F13+'CCE3'!G13 -> 11 | M16: ='CCE3'!H13+'CCE3'!I13 -> 5 | N16: ='CCE3'!J13+'CCE3'!K13 -> 0 | O16: ='CCE3'!L13+'CCE3'!M13 -> 0 | P16: =IFERROR(SUM(D16,F16,K16),"AB") -> 27 | Q16: =IFERROR(SUM(E16,G16,L16),"AB") -> 30 | R16: =IFERROR(SUM(#REF!,H16,M16),"AB") -> AB | S16: =IFERROR(SUM(#REF!,I16,N16),"AB") -> AB | T16: =IFERROR(SUM(#REF!,J16,O16),"AB") -> AB | U16: =IFERROR(SUM(P16:T16),"AB") -> 57
A17: 4 | B17: 23104 | C17: BHAGAT SANIKA SATISH | D17: ='CCE1'!D14+'CCE1'!E14 -> 14 | E17: ='CCE1'!E14+'CCE1'!F14 -> 11 | F17: ='CCE2'!D14 -> 2 | G17: ='CCE2'!E14 -> 3 | H17: ='CCE2'!F14 -> 2 | I17: ='CCE2'!G14 -> 5 | J17: ='CCE2'!H14 -> 2 | K17: ='CCE3'!D14+'CCE3'!E14 -> 16 | L17: ='CCE3'!F14+'CCE3'!G14 -> 9 | M17: ='CCE3'!H14+'CCE3'!I14 -> 6 | N17: ='CCE3'!J14+'CCE3'!K14 -> 0 | O17: ='CCE3'!L14+'CCE3'!M14 -> 0 | P17: =IFERROR(SUM(D17,F17,K17),"AB") -> 32 | Q17: =IFERROR(SUM(E17,G17,L17),"AB") -> 23 | R17: =IFERROR(SUM(#REF!,H17,M17),"AB") -> AB | S17: =IFERROR(SUM(#REF!,I17,N17),"AB") -> AB | T17: =IFERROR(SUM(#REF!,J17,O17),"AB") -> AB | U17: =IFERROR(SUM(P17:T17),"AB") -> 55
A18: 5 | B18: 23105 | C18: BHAGWAT PRATIK ANIL | D18: ='CCE1'!D15+'CCE1'!E15 -> 10 | E18: ='CCE1'!E15+'CCE1'!F15 -> 8 | F18: ='CCE2'!D15 -> 5 | G18: ='CCE2'!E15 -> 3 | H18: ='CCE2'!F15 -> 5 | I18: ='CCE2'!G15 -> 5 | J18: ='CCE2'!H15 -> 3 | K18: ='CCE3'!D15+'CCE3'!E15 -> 13 | L18: ='CCE3'!F15+'CCE3'!G15 -> 11 | M18: ='CCE3'!H15+'CCE3'!I15 -> 3 | N18: ='CCE3'!J15+'CCE3'!K15 -> 0 | O18: ='CCE3'!L15+'CCE3'!M15 -> 0 | P18: =IFERROR(SUM(D18,F18,K18),"AB") -> 28 | Q18: =IFERROR(SUM(E18,G18,L18),"AB") -> 22 | R18: =IFERROR(SUM(#REF!,H18,M18),"AB") -> AB | S18: =IFERROR(SUM(#REF!,I18,N18),"AB") -> AB | T18: =IFERROR(SUM(#REF!,J18,O18),"AB") -> AB | U18: =IFERROR(SUM(P18:T18),"AB") -> 50
A19: 6 | B19: 23106 | C19: BHAVIK ANAND SHASHIKANT | D19: ='CCE1'!D16+'CCE1'!E16 -> 14 | E19: ='CCE1'!E16+'CCE1'!F16 -> 11 | F19: ='CCE2'!D16 -> 3 | G19: ='CCE2'!E16 -> 3 | H19: ='CCE2'!F16 -> 3 | I19: ='CCE2'!G16 -> 3 | J19: ='CCE2'!H16 -> 5 | K19: ='CCE3'!D16+'CCE3'!E16 -> 16 | L19: ='CCE3'!F16+'CCE3'!G16 -> 14 | M19: ='CCE3'!H16+'CCE3'!I16 -> 3 | N19: ='CCE3'!J16+'CCE3'!K16 -> 0 | O19: ='CCE3'!L16+'CCE3'!M16 -> 0 | P19: =IFERROR(SUM(D19,F19,K19),"AB") -> 33 | Q19: =IFERROR(SUM(E19,G19,L19),"AB") -> 28 | R19: =IFERROR(SUM(#REF!,H19,M19),"AB") -> AB | S19: =IFERROR(SUM(#REF!,I19,N19),"AB") -> AB | T19: =IFERROR(SUM(#REF!,J19,O19),"AB") -> AB | U19: =IFERROR(SUM(P19:T19),"AB") -> 61
A20: 7 | B20: 23107 | C20: BHOSALE SHIVAJI SANTOSH | D20: ='CCE1'!D17+'CCE1'!E17 -> 11 | E20: ='CCE1'!E17+'CCE1'!F17 -> 16 | F20: ='CCE2'!D17 -> 2 | G20: ='CCE2'!E17 -> 5 | H20: ='CCE2'!F17 -> 3 | I20: ='CCE2'!G17 -> 5 | J20: ='CCE2'!H17 -> 3 | K20: ='CCE3'!D17+'CCE3'!E17 -> 16 | L20: ='CCE3'!F17+'CCE3'!G17 -> 16 | M20: ='CCE3'!H17+'CCE3'!I17 -> 8 | N20: ='CCE3'!J17+'CCE3'!K17 -> 0 | O20: ='CCE3'!L17+'CCE3'!M17 -> 0 | P20: =IFERROR(SUM(D20,F20,K20),"AB") -> 29 | Q20: =IFERROR(SUM(E20,G20,L20),"AB") -> 37 | R20: =IFERROR(SUM(#REF!,H20,M20),"AB") -> AB | S20: =IFERROR(SUM(#REF!,I20,N20),"AB") -> AB | T20: =IFERROR(SUM(#REF!,J20,O20),"AB") -> AB | U20: =IFERROR(SUM(P20:T20),"AB") -> 66
A21: 8 | B21: 23108 | C21: BRAMHANE DIPAK LAXMAN | D21: ='CCE1'!D18+'CCE1'!E18 -> 16 | E21: ='CCE1'!E18+'CCE1'!F18 -> 16 | F21: ='CCE2'!D18 -> 3 | G21: ='CCE2'!E18 -> 2 | H21: ='CCE2'!F18 -> 3 | I21: ='CCE2'!G18 -> 5 | J21: ='CCE2'!H18 -> 3 | K21: ='CCE3'!D18+'CCE3'!E18 -> 14 | L21: ='CCE3'!F18+'CCE3'!G18 -> 16 | M21: ='CCE3'!H18+'CCE3'!I18 -> 3 | N21: ='CCE3'!J18+'CCE3'!K18 -> 0 | O21: ='CCE3'!L18+'CCE3'!M18 -> 0 | P21: =IFERROR(SUM(D21,F21,K21),"AB") -> 33 | Q21: =IFERROR(SUM(E21,G21,L21),"AB") -> 34 | R21: =IFERROR(SUM(#REF!,H21,M21),"AB") -> AB | S21: =IFERROR(SUM(#REF!,I21,N21),"AB") -> AB | T21: =IFERROR(SUM(#REF!,J21,O21),"AB") -> AB | U21: =IFERROR(SUM(P21:T21),"AB") -> 67
A22: 9 | B22: 23109 | C22: CHANDANKHEDE SEJAL ASHOK | D22: ='CCE1'!D19+'CCE1'!E19 -> 13 | E22: ='CCE1'!E19+'CCE1'!F19 -> 11 | F22: ='CCE2'!D19 -> 5 | G22: ='CCE2'!E19 -> 3 | H22: ='CCE2'!F19 -> 5 | I22: ='CCE2'!G19 -> 3 | J22: ='CCE2'!H19 -> 3 | K22: ='CCE3'!D19+'CCE3'!E19 -> 13 | L22: ='CCE3'!F19+'CCE3'!G19 -> 11 | M22: ='CCE3'!H19+'CCE3'!I19 -> 8 | N22: ='CCE3'!J19+'CCE3'!K19 -> 0 | O22: ='CCE3'!L19+'CCE3'!M19 -> 0 | P22: =IFERROR(SUM(D22,F22,K22),"AB") -> 31 | Q22: =IFERROR(SUM(E22,G22,L22),"AB") -> 25 | R22: =IFERROR(SUM(#REF!,H22,M22),"AB") -> AB | S22: =IFERROR(SUM(#REF!,I22,N22),"AB") -> AB | T22: =IFERROR(SUM(#REF!,J22,O22),"AB") -> AB | U22: =IFERROR(SUM(P22:T22),"AB") -> 56
A23: 10 | B23: 23110 | C23: CHAUDHARY AKHILESH JEEVAN | D23: ='CCE1'!D20+'CCE1'!E20 -> 16 | E23: ='CCE1'!E20+'CCE1'!F20 -> 13 | F23: ='CCE2'!D20 -> 3 | G23: ='CCE2'!E20 -> 3 | H23: ='CCE2'!F20 -> 3 | I23: ='CCE2'!G20 -> 3 | J23: ='CCE2'!H20 -> 4 | K23: ='CCE3'!D20+'CCE3'!E20 -> 12 | L23: ='CCE3'!F20+'CCE3'!G20 -> 14 | M23: ='CCE3'!H20+'CCE3'!I20 -> 8 | N23: ='CCE3'!J20+'CCE3'!K20 -> 0 | O23: ='CCE3'!L20+'CCE3'!M20 -> 0 | P23: =IFERROR(SUM(D23,F23,K23),"AB") -> 31 | Q23: =IFERROR(SUM(E23,G23,L23),"AB") -> 30 | R23: =IFERROR(SUM(#REF!,H23,M23),"AB") -> AB | S23: =IFERROR(SUM(#REF!,I23,N23),"AB") -> AB | T23: =IFERROR(SUM(#REF!,J23,O23),"AB") -> AB | U23: =IFERROR(SUM(P23:T23),"AB") -> 61
A24: 11 | B24: 23111 | C24: CHAUHAN ASHUTOSH SANJAYSINGH | D24: ='CCE1'!D21+'CCE1'!E21 -> 13 | E24: ='CCE1'!E21+'CCE1'!F21 -> 16 | F24: ='CCE2'!D21 -> 3 | G24: ='CCE2'!E21 -> 2 | H24: ='CCE2'!F21 -> 3 | I24: ='CCE2'!G21 -> 5 | J24: ='CCE2'!H21 -> 4 | K24: ='CCE3'!D21+'CCE3'!E21 -> 14 | L24: ='CCE3'!F21+'CCE3'!G21 -> 14 | M24: ='CCE3'!H21+'CCE3'!I21 -> 8 | N24: ='CCE3'!J21+'CCE3'!K21 -> 0 | O24: ='CCE3'!L21+'CCE3'!M21 -> 0 | P24: =IFERROR(SUM(D24,F24,K24),"AB") -> 30 | Q24: =IFERROR(SUM(E24,G24,L24),"AB") -> 32 | R24: =IFERROR(SUM(#REF!,H24,M24),"AB") -> AB | S24: =IFERROR(SUM(#REF!,I24,N24),"AB") -> AB | T24: =IFERROR(SUM(#REF!,J24,O24),"AB") -> AB | U24: =IFERROR(SUM(P24:T24),"AB") -> 62
A25: 12 | B25: 23112 | C25: DHAGE SIDDHESH SUNIL | D25: ='CCE1'!D22+'CCE1'!E22 -> 8 | E25: ='CCE1'!E22+'CCE1'!F22 -> 11 | F25: ='CCE2'!D22 -> 3 | G25: ='CCE2'!E22 -> 4 | H25: ='CCE2'!F22 -> 2 | I25: ='CCE2'!G22 -> 2 | J25: ='CCE2'!H22 -> 5 | K25: ='CCE3'!D22+'CCE3'!E22 -> 14 | L25: ='CCE3'!F22+'CCE3'!G22 -> 13 | M25: ='CCE3'!H22+'CCE3'!I22 -> 7 | N25: ='CCE3'!J22+'CCE3'!K22 -> 0 | O25: ='CCE3'!L22+'CCE3'!M22 -> 0 | P25: =IFERROR(SUM(D25,F25,K25),"AB") -> 25 | Q25: =IFERROR(SUM(E25,G25,L25),"AB") -> 28 | R25: =IFERROR(SUM(#REF!,H25,M25),"AB") -> AB | S25: =IFERROR(SUM(#REF!,I25,N25),"AB") -> AB | T25: =IFERROR(SUM(#REF!,J25,O25),"AB") -> AB | U25: =IFERROR(SUM(P25:T25),"AB") -> 53
... A121: 108 | B121: 23253 | C121: THATHAGAR VAIBHAV DHARMENDRA | D121: ='CCE1'!D118+'CCE1'!E118 -> 11 | E121: ='CCE1'!E118+'CCE1'!F118 -> 14 | F121: ='CCE2'!D118 -> 5 | G121: ='CCE2'!E118 -> 5 | H121: ='CCE2'!F118 -> 4 | I121: ='CCE2'!G118 -> 3 | J121: ='CCE2'!H118 -> 5 | K121: ='CCE3'!D118+'CCE3'!E118 -> 15 | L121: ='CCE3'!F118+'CCE3'!G118 -> 10 | M121: ='CCE3'!H118+'CCE3'!I118 -> 6 | N121: ='CCE3'!J118+'CCE3'!K118 -> 0 | O121: ='CCE3'!L118+'CCE3'!M118 -> 0 | P121: =IFERROR(SUM(D121,F121,K121),"AB") -> 31 | Q121: =IFERROR(SUM(E121,G121,L121),"AB") -> 29 | R121: =IFERROR(SUM(#REF!,H121,M121),"AB") -> AB | S121: =IFERROR(SUM(#REF!,I121,N121),"AB") -> AB | T121: =IFERROR(SUM(#REF!,J121,O121),"AB") -> AB | U121: =IFERROR(SUM(P121:T121),"AB") -> 60
A122: 109 | B122: 23254 | C122: VARGANTI AARTI YALLAPPA
A123: 110 | B123: 23255 | C123: WADHAVE SHUBHAM SUDHAKAR
A124: 111 | B124: 23256 | C124: WAHATULE PAVAN RAOSAHEB
C128: =CONCATENATE("No of students more than ",P6* 100, "% = (x)") -> No of students more than 60% = (x) | D128: =COUNTIF(D14:D121,CONCATENATE(">=",$D$13*$P$6)) -> 84 | E128: =COUNTIF(E14:E121,CONCATENATE(">=",$E$13*$P$6)) -> 108 | F128: =COUNTIF(F14:F121,CONCATENATE(">=",$F$13*$P$6)) -> 102 | G128: =COUNTIF(G14:G121,CONCATENATE(">=",$G$13*$P$6)) -> 102 | H128: =COUNTIF(H14:H121,CONCATENATE(">=",$D$13*$P$6)) -> 0 | I128: =COUNTIF(I14:I121,CONCATENATE(">=",$D$13*$P$6)) -> 0 | J128: =COUNTIF(J14:J121,CONCATENATE(">=",$D$13*$P$6)) -> 0 | K128: =COUNTIF(K14:K121,CONCATENATE(">=",$K$13*$P$6)) -> 0 | L128: =COUNTIF(L14:L121,CONCATENATE(">=",$L$13*$P$6)) -> 0 | M128: =COUNTIF(M14:M121,CONCATENATE(">=",$M$13*$P$6)) -> 0 | N128: =COUNTIF(N14:N121,CONCATENATE(">=",$N$13*$P$6)) -> 108 | O128: =COUNTIF(O14:O121,CONCATENATE(">=",$O$13*$P$6)) -> 108 | P128: =COUNTIF(P14:P121,CONCATENATE(">=",$P$13*$P$6)) -> 0 | Q128: =COUNTIF(Q14:Q121,CONCATENATE(">=",$Q$13*$P$6)) -> 0 | R128: =COUNTIF(R14:R121,CONCATENATE(">=",$R$13*$P$6)) -> 0 | S128: =COUNTIF(S14:S121,CONCATENATE(">=",$S$13*$P$6)) -> 0 | T128: =COUNTIF(T14:T121,CONCATENATE(">=",$T$13*$P$6)) -> 0 | U128: =COUNTIF(U14:U121,CONCATENATE(">=",$U$13*$P$6)) -> 0
C129: No of Students (y) | D129: =COUNT(D14:D121) -> 108 | E129: =COUNT(E14:E121) -> 108 | F129: =COUNT(F14:F121) -> 108 | G129: =COUNT(G14:G121) -> 108 | H129: =COUNT(H14:H121) -> 108 | I129: =COUNT(I14:I121) -> 108 | J129: =COUNT(J14:J121) -> 108 | K129: =COUNT(K14:K121) -> 108 | ... U129: =COUNT(U14:U121) -> 108
C130: CO Attainment Percentage | D130: =IFERROR(D128/D129,"NA")*100 -> 77.777778 | E130: =IFERROR(E128/E129,"NA")*100 -> 100 | F130: =IFERROR(F128/F129,"NA")*100 -> 94.444444 | G130: =IFERROR(G128/G129,"NA")*100 -> 94.444444 | H130: NA | I130: NA | J130: NA | K130: =IFERROR(K128/K129,"NA")*100 -> 0 | L130: =IFERROR(L128/L129,"NA")*100 -> 0 | M130: =IFERROR(M128/M129,"NA")*100 -> 0 | N130: =IFERROR(N128/N129,"NA")*100 -> 100 | O130: =IFERROR(O128/O129,"NA")*100 -> 100 | P130: =IFERROR(P128/P129,"NA")*100 -> 0 | Q130: =IFERROR(Q128/Q129,"NA")*100 -> 0 | R130: =IFERROR(R128/R129,"NA")*100 -> #VALUE! | ... U130: =IFERROR(U128/U129,"NA")*100 -> 0
C131: CO Attainment Level | D131: =IF(D130<>"NA",IF(D130>=$K6,$I6,IF(D130>=$K7,$I7,IF(D130>=$K8,$I8,"0"))),"NA") -> 3 | E131: =IF(E130<>"NA",IF(E130>=$K6,$I6,IF(E130>=$K7,$I7,IF(E130>=$K8,$I8,"0"))),"NA") -> 3 | F131: =IF(F130<>"NA",IF(F130>=$K6,$I6,IF(F130>=$K7,$I7,IF(F130>=$K8,$I8,"0"))),"NA") -> 3 | G131: =IF(G130<>"NA",IF(G130>=$K6,$I6,IF(G130>=$K7,$I7,IF(G130>=$K8,$I8,"0"))),"NA") -> 3 | H131: =IF(H130<>"NA",IF(H130>=$K6,$I6,IF(H130>=$K7,$I7,IF(H130>=$K8,$I8,"0"))),"NA") -> NA | I131: =IF(I130<>"NA",IF(I130>=$K6,$I6,IF(I130>=$K7,$I7,IF(I130>=$K8,$I8,"0"))),"NA") -> NA | J131: =IF(J130<>"NA",IF(J130>=$K6,$I6,IF(J130>=$K7,$I7,IF(J130>=$K8,$I8,"0"))),"NA") -> NA | K131: =IF(K130<>"NA",IF(K130>=$K6,$I6,IF(K130>=$K7,$I7,IF(K130>=$K8,$I8,"0"))),"NA") -> 0 | ... U131: =IF(U130<>"NA",IF(U130>=$K6,$I6,IF(U130>=$K7,$I7,IF(U130>=$K8,$I8,"0"))),"NA") -> 0
C133: Attainment based on Comprehensive Concurrent Evaluation (CCE) = Avg. of all COs | D133: =AVERAGE(P131:T131) -> #VALUE! | E133: =AVERAGE(D130:U130) -> #VALUE!
B138: =Faculty -> Narsareddy Chude, Sonali Late
A144: =SubjectDetails!A24 -> Dr. Ravi Chourasiya | D144: =SubjectDetails!E24 -> Dr. Ashwini Chavan | K144: =SubjectDetails!H24 -> Dr. Priyanka Singh
A145: =SubjectDetails!A25 -> (College Examination Officer) | D145: =SubjectDetails!E25 -> HOD (MCA) | K145: =SubjectDetails!H25 -> Director

Sheet CO Ext. Attn
A1: Dr. D.Y. Patil Educational Federation's
A2: Dr. D. Y. Patil Institute of Management and Entreprenuer Development, Varale, Pune
A3: (Permanently affiliated to Savitribai Phule Pune University, Accredited by NAAC 'A'
A4: Approved by AICTE, Recognized under 2 (f) & 12 (b) sections of UGC Act)
A6: =CONCATENATE("Faculty Name: ", Faculty) -> Faculty Name: Narsareddy Chude, Sonali Late | D6: Benchmark | F6: 3 | G6: 0.7 | H6: Percentage of Students to get | J6: 0.6
A7: =CONCATENATE("Subject Name & Code: ", Sub_Code) -> Subject Name & Code: Java Programming | F7: 2 | G7: 0.6
A8: =CONCATENATE("Class: ",Class_AY) -> Class: MCA I SEM I AY 2023-24 | F8: 1 | G8: 0.5
A10: Course Outcome Attainment Calculations - External Assessment (SPPU)
A11: Roll No. | B11: Seat No. | C11: Name of the Student | D11: Equal Weightage to all COs
D13: 50
A14: 1 | B14: 2032303491 | C14: MANE SHARVI MAHENDRA | D14: 33
A15: 2 | B15: 2032303500 | C15: SAYYAD TARNUM ISMAIL | D15: 32
A16: 3 | B16: 2032303484 | C16: SALUNKHE SANIYA SANTOSH | D16: 30
A17: 4 | B17: 2032303481 | C17: AKHARE PRATIK RAJENDRA | D17: 27
A18: 5 | B18: 2032303483 | C18: VEDANT NILKANTH THATE | D18: 31
A19: 6 | B19: 2032303463 | C19: CHANNE VIJAY SAKHARAM | D19: 31
A20: 7 | B20: 2032303487 | C20: PRAJWAL KISHOR SATPUTE | D20: 32
A21: 8 | B21: 2032303455 | C21: SHIRSAT MEGHA SHARAD | D21: 33
A22: 9 | B22: 2032303516 | C22: PRATIKSHA VISHWASRAO JAWARE | D22: 27
A23: 10 | B23: 2032303515 | C23: KOLTE PRAJAKTA ANIL | D23: 34
A24: 11 | B24: 2032303502 | C24: JAGTAP PRATHAMESH BHAUSAHEB | D24: 30
A25: 12 | B25: 2032303513 | C25: SANJIVANI SUNIL RAUT | D25: 27
... A120: 107 | B120: 2032303555 | C120: JISHAN VAHED SHAIKH | D120: 37
B122: 1 | C122: No of Students (y) | D122: =IFERROR(COUNT(D12:D119),"NA") -> 107
B123: 2 | C123: =CONCATENATE("No of students more than ",70, "% = (x1)") -> No of students more than 70% = (x1) | D123: =COUNTIF(D14:D120,">="&D13*70%) -> 15
B124: 3 | C124: =CONCATENATE("No of students between 70 and ",60, "% = (x2)") -> No of students between 70 and 60% = (x2) | D124: =COUNTIFS(D14:D120,">="&D13*60%,D14:D120,"<"&D13*70%) -> 71
B125: 4 | C125: =CONCATENATE("No of students between 60 and ",50, "% = (x3)") -> No of students between 60 and 50% = (x3) | D125: =COUNTIFS(D14:D120,">="&D13*50%,D14:D120,"<"&D13*60%) -> 4
B126: 5 | C126: No of students between 40 and 50 % = (x4) | D126: =COUNTIFS(D14:D120,">="&D13*40%,D14:D120,"<"&D13*50%) -> 17
B127: 6 | C127: No of students between less than 40 % = (x5) | D127: =COUNTIF(D14:D120,"<"&D13*40%) -> 0
B128: 7 | C128: CO Attainment Percentage | D128: =(D123*3+D124*2+D125*1)/(COUNT(D5:D119)*3)*100 -> 59.501558
B129: 8 | C129: CO Benchmark Level | D129: =IF(D128<>"NA",IF(D128>=70,3,IF(D128>=60,2,IF(D128>=50,1,"0"))),"NA") -> 1

Sheet OverallCO Attainment
A1: Dr. D.Y. Patil Educational Federation's
A2: Dr. D. Y. Patil Institute of Management and Entreprenuer Development, Varale, Pune
A3: (Permanently affiliated to Savitribai Phule Pune University, Accredited by NAAC 'A'
A4: Approved by AICTE, Recognized under 2 (f) & 12 (b) sections of UGC Act)
B5: =CONCATENATE("Faculty Name: ", Faculty) -> Faculty Name: Narsareddy Chude, Sonali Late
B6: =CONCATENATE("Subject Name & Code: ", Sub_Code) -> Subject Name & Code: Java Programming
B7: =CONCATENATE("Class: ",Class_AY) -> Class: MCA I SEM I AY 2023-24
B9: OVERALL CO ATTAINMENT FOR COURSE
B10: Particulars | C10: CO1 | D10: CO2 | E10: CO3 | F10: CO4 | G10: CO5
B11: CO ATTAINMENT PERCENTAGE - INTERNAL ASSESSMENT (A1) | C11: =AVERAGE('CCE1'!D129,'CCE2'!D129,'CCE3'!D129) -> 74.007937 | D11: =AVERAGE('CCE1'!E129,'CCE2'!E129,'CCE3'!E129) -> 81.944444 | E11: =AVERAGE('CCE1'!F129,'CCE2'!F129,'CCE3'!F129) -> 78.869048 | F11: =AVERAGE('CCE2'!G129,'CCE3'!G129) -> 84.970238 | G11: =AVERAGE('CCE2'!H129,'CCE3'!H129) -> 84.22619
B12: CO ATTAINMENT PERCENTAGE - EXTERNAL ASSESSMENT (SPPU) (A2) | C12: ='CO Ext. Attn'!D128 -> 59.501558 | D12: 59.501558 | E12: 59.501558 | F12: 59.501558 | G12: 59.501558
B13: CO ATTAINMENT PERCENTAGE - DIRECT ASSESSMENT Direct Attainment=(Int. Weightage X A1) + ( Ext. Weightage X A2) | C13: =(0.34*C11)+(0.66*C12) -> 64.433726 | D13: =(0.34*D11)+(0.66*D12) -> 67.132139 | E13: =(0.34*E11)+(0.66*E12) -> 66.086504 | F13: =(0.34*F11)+(0.66*F12) -> 68.160909 | G13: =(0.34*G11)+(0.66*G12) -> 67.907933
B14: CO ATTAINMENT PERCENTAGE - INDIRECT (SURVEY) | C14: ='Course Exit'!D105 -> 83.908046 | D14: ='Course Exit'!E105 -> 87.586207 | E14: ='Course Exit'!F105 -> 85.517241 | F14: ='Course Exit'!G105 -> 82.068966 | G14: ='Course Exit'!H105 -> 82.068966
B15: OVERALL CO ATTAINMENT FOR COURSE | C15: =(0.8*C13)+(0.2*C14) -> 68.32859 | D15: =(0.8*D13)+(0.2*D14) -> 71.222953 | E15: =(0.8*E13)+(0.2*E14) -> 69.972652 | F15: =(0.8*F13)+(0.2*F14) -> 70.94252 | G15: =(0.8*G13)+(0.2*G14) -> 70.740139
B16: CO ATTAINMENT LEVEL | C16: =IF(C15>=$E20,3,IF(C15>=$E21,2,IF(C15>=$E22,1,0))) -> 2 | D16: =IF(D15>=$E20,3,IF(D15>=$E21,2,IF(D15>=$E22,1,0))) -> 3 | E16: =IF(E15>=$E20,3,IF(E15>=$E21,2,IF(E15>=$E22,1,0))) -> 2 | F16: =IF(F15>=$E20,3,IF(F15>=$E21,2,IF(F15>=$E22,1,0))) -> 3 | G16: =IF(G15>=$E20,3,IF(G15>=$E21,2,IF(G15>=$E22,1,0))) -> 3
B18: Percentage of Students to get 60% of Marks
B20: Benchmark | D20: 3 | E20: 70
D21: 2 | E21: 60
D22: 1 | E22: 50
B24: =Faculty -> Narsareddy Chude, Sonali Late
B25: =SubjectDetails!$E$17 -> Subject Faculty
A30: =SubjectDetails!$A$24 -> Dr. Ravi Chourasiya | D30: =SubjectDetails!$E$24 -> Dr. Ashwini Chavan | H30: =SubjectDetails!$H$24 -> Dr. Priyanka Singh
A31: =SubjectDetails!$A$25 -> (College Examination Officer) | D31: =SubjectDetails!$E$25 -> HOD (MCA) | H31: =SubjectDetails!$H$25 -> Director

Sheet CO PO Attainment
B1: Dr. D.Y. Patil Educational Federation's
B2: Dr. D. Y. Patil Institute of Management and Entreprenuer Development, Varale, Pune
B3: (Permanently affiliated to Savitribai Phule Pune University, Accredited by NAAC 'A'
B4: Approved by AICTE, Recognized under 2 (f) & 12 (b) sections of UGC Act)
B6: =CONCATENATE("Faculty Name: ", Faculty) -> Faculty Name: Narsareddy Chude, Sonali Late
B7: =CONCATENATE("Subject Name & Code: ", Sub_Code) -> Subject Name & Code: Java Programming
B8: =CONCATENATE("Class: ",Class_AY) -> Class: MCA I SEM I AY 2023-24
B9: CO-PO Attainment Calculations
B10: Overall CO Attainment % | D10: PO1 | E10: PO2 | F10: PO3 | G10: PO4 | H10: PO5 | I10: PO6 | J10: PO7 | K10: PO8
B11: Average Mapping (M) | D11: ='CO Mapping PO '!B18 -> 2.4 | E11: ='CO Mapping PO '!C18 -> 1.8 | F11: ='CO Mapping PO '!D18 -> 2.2 | G11: ='CO Mapping PO '!E18 -> 2.4 | H11: ='CO Mapping PO '!F18 -> 1 | I11: ='CO Mapping PO '!G18 -> 1.5 | J11: ='CO Mapping PO '!H18 -> 1 | K11: ='CO Mapping PO '!I18 -> 2
B12: CO1 | C12: ='OverallCO Attainment'!C15 -> 68.32859 | D12: 2 | E12: 1 | F12: 1 | G12: 2 | H12: 0 | I12: 0 | J12: 0 | K12: 2
B13: CO2 | C13: ='OverallCO Attainment'!D15 -> 71.222953 | D13: 2 | E13: 2 | F13: 2 | G13: 2 | H13: 0 | I13: 0 | J13: 0 | K13: 2
B14: CO3 | C14: ='OverallCO Attainment'!E15 -> 69.972652 | D14: 2 | E14: 2 | F14: 2 | G14: 2 | H14: 0 | I14: 0 | J14: 0 | K14: 2
B15: CO4 | C15: ='OverallCO Attainment'!F15 -> 70.94252 | D15: 3 | E15: 2 | F15: 3 | G15: 3 | H15: 1 | I15: 1 | J15: 0 | K15: 2
B16: CO5 | C16: ='OverallCO Attainment'!G15 -> 70.740139 | D16: 3 | E16: 2 | F16: 3 | G16: 3 | H16: 1 | I16: 2 | J16: 1 | K16: 2
C17: Perecentage | D17: =(C12*D12+C13*D13+C14*D14+C15*D15+C16*D16)/(D12+D13+D14+D15+D16) -> 70.341364 | E17: =(C12*E12+C13*E13+C14*E14+C15*E15+C16*E16)/(E12+E13+E14+E15+E16) -> 70.453902 | F17: =(C12*F12+C13*F13+C14*F14+C15*F15+C16*F16)/(F12+F13+F14+F15+F16) -> 70.524343 | G17: =(C12*G12+C13*G13+C14*G14+C15*G15+C16*G16)/(G12+G13+G14+G15+G16) -> 70.341364 | H17: =(C12*H12+C13*H13+C14*H14+C15*H15+C16*H16)/(H12+H13+H14+H15+H16) -> 70.84133 | I17: =(C12*I12+C13*I13+C14*I14+C15*I15+C16*I16)/(I12+I13+I14+I15+I16) -> 70.8076 | J17: =(C12*J12+C13*J13+C14*J14+C15*J15+C16*J16)/(J12+J13+J14+J15+J16) -> 70.740139 | K17: =(C12*K12+C13*K13+C14*K14+C15*K15+C16*K16)/(K12+K13+K14+K15+K16) -> 70.241371
C18: Level | D18: =D17/100*3 -> 2.1102409 | E18: =E17/100*3 -> 2.1136171 | F18: =F17/100*3 -> 2.1157303 | G18: =G17/100*3 -> 2.1102409 | H18: =H17/100*3 -> 2.1252399 | I18: =I17/100*3 -> 2.124228 | J18: =J17/100*3 -> 2.1222042 | K18: =K17/100*3 -> 2.1072411
B24: =Faculty -> Narsareddy Chude, Sonali Late
B25: =Designation -> Assistant Professor
B31: =SubjectDetails!$A$24 -> Dr. Ravi Chourasiya | E31: =SubjectDetails!$E$24 -> Dr. Ashwini Chavan | I31: =SubjectDetails!$H$24 -> Dr. Priyanka Singh
B32: =SubjectDetails!$A$25 -> (College Examination Officer) | E32: =SubjectDetails!$E$25 -> HOD (MCA) | I32: =SubjectDetails!$H$25 -> Director

Sheet Course Exit
A1: Dr. D.Y. Patil Educational Federation's
A2: Dr. D. Y. Patil Institute of Management and Entreprenuer Development, Varale, Pune
A3: (Permanently affiliated to Savitribai Phule Pune University, Accredited by NAAC 'A'
A4: Approved by AICTE, Recognized under 2 (f) & 12 (b) sections of UGC Act)
A5: Indirect Attainment
A6: =CONCATENATE(Class," ", spl) -> MCA I SEM I AY 2023-24 | D6: Course Exit Survey
B7: Seat No. | C7: Name of the Student | L7: Total Marks Obtained
D8: CO1 | E8: CO2 | F8: CO3 | G8: CO4 | H8: CO5
D9: 5 | E9: 5 | F9: 5 | G9: 5 | H9: 5 | L9: =SUM(D9:K9) -> 25
B10: 1 | C10: Harshada Burte | D10: 2 | E10: 5 | F10: 2 | G10: 3 | H10: 2 | L10: =IF(F10<>"AB",SUM(D10:K10),"AB") -> 14
B11: 2 | C11: Sachin Chavan | D11: 2 | E11: 5 | F11: 3 | G11: 2 | H11: 4 | L11: =IF(F11<>"AB",SUM(D11:K11),"AB") -> 16
B12: 3 | C12: Abhishek Chemate | D12: 2 | E12: 2 | F12: 2 | G12: 4 | H12: 3 | L12: =IF(F12<>"AB",SUM(D12:K12),"AB") -> 13
B13: 4 | C13: Yatin Darekar | D13: 4 | E13: 5 | F13: 4 | G13: 5 | H13: 5 | L13: =IF(F13<>"AB",SUM(D13:K13),"AB") -> 23
B14: 5 | C14: AKASH DATE | D14: 4 | E14: 4 | F14: 4 | G14: 4 | H14: 4 | L14: =IF(F14<>"AB",SUM(D14:K14),"AB") -> 20
B15: 6 | C15: Shivam Deshmukh | D15: 4 | E15: 5 | F15: 5 | G15: 5 | H15: 4 | L15: =IF(F15<>"AB",SUM(D15:K15),"AB") -> 23
B16: 7 | C16: Vaishnavi Deshmukh | D16: 4 | E16: 5 | F16: 4 | G16: 4 | H16: 4 | L16: =IF(F16<>"AB",SUM(D16:K16),"AB") -> 21
B17: 8 | C17: Dhotrikar Aditya | D17: 5 | E17: 5 | F17: 5 | G17: 4 | H17: 4 | L17: =IF(F17<>"AB",SUM(D17:K17),"AB") -> 23
B18: 9 | C18: Dube Akanksha | D18: 4 | E18: 4 | F18: 4 | G18: 4 | H18: 4 | L18: =IF(F18<>"AB",SUM(D18:K18),"AB") -> 20
B19: 10 | C19: Ganesh Katiyar | D19: 5 | E19: 5 | F19: 5 | G19: 4 | H19: 5 | L19: =IF(F19<>"AB",SUM(D19:K19),"AB") -> 24
B20: 11 | C20: Gurame Rutuja | D20: 5 | E20: 4 | F20: 5 | G20: 4 | H20: 4 | L20: =IF(F20<>"AB",SUM(D20:K20),"AB") -> 22
B21: 12 | C21: Kadu Prajwal | D21: 4 | E21: 5 | F21: 5 | G21: 4 | H21: 5 | L21: =IF(F21<>"AB",SUM(D21:K21),"AB") -> 23
... B96: 87 | C96: Priyanka Yadav | D96: 5 | E96: 5 | F96: 5 | G96: 5 | H96: 4 | L96: =IF(F96<>"AB",SUM(D96:K96),"AB") -> 24
C98: Total No. of Students | D98: 87 | E98: 87 | F98: 87 | G98: 87 | H98: 87
C99: No. of students Strongly Disagree | D99: =COUNTIF(D10:D96,"=1") -> 0 | E99: =COUNTIF(E10:E96,"=1") -> 0 | F99: =COUNTIF(F10:F96,"=1") -> 0 | G99: =COUNTIF(G10:G96,"=1") -> 0 | H99: =COUNTIF(H10:H96,"=1") -> 1
C100: No. of students Disagree | D100: =COUNTIF(D10:D96,"=2") -> 6 | E100: =COUNTIF(E10:E96,"=2") -> 5 | F100: =COUNTIF(F10:F96,"=2") -> 7 | G100: =COUNTIF(G10:G96,"=2") -> 9 | H100: =COUNTIF(H10:H96,"=2") -> 2
C101: No. of students Neutral | D101: =COUNTIF(D10:D96,"=3") -> 3 | E101: =COUNTIF(E10:E96,"=3") -> 1 | F101: =COUNTIF(F10:F96,"=3") -> 2 | G101: =COUNTIF(G10:G96,"=3") -> 6 | H101: =COUNTIF(H10:H96,"=3") -> 5
C102: No. of students Strongly Agree | D102: =COUNTIF(D10:D96,"=4") -> 46 | E102: =COUNTIF(E10:E96,"=4") -> 37 | F102: =COUNTIF(F10:F96,"=4") -> 38 | G102: =COUNTIF(G10:G96,"=4") -> 39 | H102: =COUNTIF(H10:H96,"=4") -> 58
C103: No. of students Agree | D103: =COUNTIF(D10:D96,"=5") -> 32 | E103: =COUNTIF(E10:E96,"=5") -> 44 | F103: =COUNTIF(F10:F96,"=5") -> 40 | G103: =COUNTIF(G10:G96,"=5") -> 33 | H103: =COUNTIF(H10:H96,"=5") -> 21
C104: Average | D104: =AVERAGE(D10:D96) -> 4.1954023 | E104: =AVERAGE(E10:E96) -> 4.3793103 | F104: =AVERAGE(F10:F96) -> 4.2758621 | G104: =AVERAGE(G10:G96) -> 4.1034483 | H104: =AVERAGE(H10:H96) -> 4.1034483 | L104: =AVERAGE(L10:L103) -> 21.057471
C105: Attainment | D105: =D104/5*100 -> 83.908046 | E105: =E104/5*100 -> 87.586207 | F105: =F104/5*100 -> 85.517241 | G105: =G104/5*100 -> 82.068966 | H105: =H104/5*100 -> 82.068966 | L105: =L104/25*100 -> 84.229885
M106: Overall Semester wise Attainment
B113: =SubjectDetails!$A$24 -> Dr. Ravi Chourasiya | D113: =SubjectDetails!$E$24 -> Dr. Ashwini Chavan | J113: =SubjectDetails!$H$24 -> Dr. Priyanka Singh
B114: =SubjectDetails!$A$25 -> (College Examination Officer) | D114: =SubjectDetails!$E$25 -> HOD (MCA) | I114: =SubjectDetails!$H$25 -> Director

Sheet In Direct
A1: Dr. D.Y. Patil Educational Federation's
A2: Dr. D. Y. Patil Institute of Management and Entreprenuer Development, Varale, Pune
A3: (Permanently affiliated to Savitribai Phule Pune University, Accredited by NAAC 'A'
A4: Approved by AICTE, Recognized under 2 (f) & 12 (b) sections of UGC Act)
A5: Indirect Attainment
A6: =CONCATENATE(Class," ", spl) -> MCA I SEM I AY 2023-24 | D6: Student Exit Survey
A7: Roll No. | B7: Seat No. | C7: Name of the Student | L7: Total Marks Obtained
