Workbook
Name Class: SubjectDetails!$B$10
Name Class_AY: SubjectDetails!$B$10
Name Designation: SubjectDetails!$B$7
Name dir_wt: SubjectDetails!$B$17
Name ext_wt: SubjectDetails!$B$15
Name Faculty: SubjectDetails!$B$6
Name ind_wt: SubjectDetails!$B$18
Name int_wt: SubjectDetails!$B$14
Name spl: SubjectDetails!$B$11
Name Sub_Code: SubjectDetails!$B$8
Name Target: 60%
Name Type: SubjectDetails!$B$9

Sheet SubjectDetails
A1: Dr. D.Y. Patil Educational Federation's
A2: Dr. D. Y. Patil Institute of Management and Entreprenuer Development, Varale, Pune
A3: (Permanently affiliated to Savitribai Phule Pune University, Accredited by NAAC 'A'
A4: Approved by AICTE, Recognized under 2 (f) & 12 (b) sections of UGC Act)
A6: Name of the faculty: | B6: Dr. Ashwini Chavan,
A7: Designation: | B7: Assistant Professor
A8: Subject & Code: | B8: Network Technologies
A9: Type of Course: | B9: Subject Core
A10: Class & A.Y.: | B10: MCA I SEM I AY 2023-24
A11: Specialization:
B13: % | C13: Marks
A14: Internal Assessment Weightage | B14: 0.33 | C14: 25
A15: External Assessment Weightage | B15: 0.67 | C15: 50
E16: =Faculty -> Dr. Ashwini Chavan,
A17: Direct Assessment Weightage | B17: 0.8 | E17: Subject Faculty
A18: Indirect Assessment Weightage | B18: 0.2
A24: Dr. Ravi Chourasiya | E24: Dr. Ashwini Chavan | H24: Dr. Priyanka Singh
A25: (College Examination Officer) | E25: HOD (MCA) | H25: Director

Sheet Rubrics
A1: Dr. D.Y. Patil Educational Federation's
A2: Dr. D. Y. Patil Institute of Management and Entreprenuer Development, Varale, Pune
A3: (Permanently affiliated to Savitribai Phule Pune University, Accredited by NAAC 'A'
A4: Approved by AICTE, Recognized under 2 (f) & 12 (b) sections of UGC Act)
A5: =CONCATENATE("Faculty Name: ", Faculty) -> Faculty Name: Dr. Ashwini Chavan,
A6: =CONCATENATE("Subject Name & Code: ", Sub_Code) -> Subject Name & Code: Network Technologies
A7: =CONCATENATE("Class: ",Class_AY) -> Class: MCA I SEM I AY 2023-24
A9: Rubrics
A10: Criteria | C10: Excellent (100%) | F10: Good (80%) | I10: Satisfactory (60%) | L10: Needs Improvement (<60%)
A11: Understanding of Concepts
A12: Application of Tools
A13: Interpretation & Decision-Making
A14: Structure & Clarity
A15: References & Format
A18: =Faculty -> Dr. Ashwini Chavan,
A19: Subject Faculty
A24: =SubjectDetails!$A$24 -> Dr. Ravi Chourasiya | E24: =SubjectDetails!$E$24 -> Dr. Ashwini Chavan | I24: =SubjectDetails!$H$24 -> Dr. Priyanka Singh
A25: =SubjectDetails!$A$25 -> (College Examination Officer) | E25: =SubjectDetails!$E$25 -> HOD (MCA) | I25: =SubjectDetails!$H$25 -> Director

Sheet CO Mapping PO 
A1: Dr. D.Y. Patil Educational Federation's
A2: Dr. D. Y. Patil Institute of Management and Entreprenuer Development, Varale, Pune
A3: (Permanently affiliated to Savitribai Phule Pune University, Accredited by NAAC 'A'
A4: Approved by AICTE, Recognized under 2 (f) & 12 (b) sections of UGC Act)
A6: =CONCATENATE("Faculty Name: ", Faculty) -> Faculty Name: Dr. Ashwini Chavan,
A7: =CONCATENATE("Subject Name & Code: ", Sub_Code) -> Subject Name & Code: Network Technologies
A8: =CONCATENATE("Class: ",Class_AY) -> Class: MCA I SEM I AY 2023-24
K9: Program OutComes
A10: COURSE OUTCOMES (CO) MAPPING WITH PROGRAM OUTCOMES (PO) | K10: PO1 (Foundation Knowledge): Apply knowledge of mathematics, programming logic and coding fundamentals for solution architecture and problem solving.
B11: PO1 | C11: PO2 | D11: PO3 | E11: PO4 | F11: PO5 | G11: PO6 | H11: PO7 | I11: PO8 | K11: PO2 (Problem Analysis): Identify, review, formulate and analyze problems for primarily focussing on customer requirements using critical thinking frameworks.
A12: CO1 | B12: 2 | C12: 1 | D12: - | E12: - | F12: - | G12: - | H12: - | I12: 1
A13: CO2 | B13: 3 | C13: 1 | D13: 1 | E13: - | F13: - | G13: - | H13: - | I13: 1 | K13: PO3 (Development of Solutions): Design, develop and investigate problems with as an innovative approach for solutions incorporating ESG/SDG goals.
A14: CO3 | B14: 3 | C14: - | D14: - | E14: - | F14: - | G14: - | H14: - | I14: 1
A15: CO4 | B15: 2 | C15: - | D15: 1 | E15: - | F15: - | G15: - | H15: 2 | I15: 1 | K15: PO4 (Modern Tool Usage): Select, adapt and apply modern computational tools such as development of algorithms with an understanding of the limitations including human biases.
A16: CO5 | B16: 2 | C16: - | D16: 3 | E16: 2 | F16: - | G16: - | H16: - | I16: 2
K17: PO5 (Individual and Teamwork): Function and communicate effectively as an individual or a team leader in diverse and multidisciplinary groups. Use methodologies such as agile.
A18: Average | B18: =AVERAGE(B12:B17) -> 2.4 | C18: =AVERAGE(C12:C17) -> 1 | D18: =AVERAGE(D12:D17) -> 1.6666667 | E18: =AVERAGE(E12:E17) -> 2 | F18: =AVERAGE(F12:F17) -> #DIV/0! | G18: =AVERAGE(G12:G17) -> #DIV/0! | H18: =AVERAGE(H12:H17) -> 2 | I18: =AVERAGE(I12:I17) -> 1.2
A19: 3-HIGH (corresponds to a high correlation) 2-MEDIUM (corresponds to a medium correlation) 1-LOW (corresponds to a low correlation) between CO and PO/PSO | K19: PO6 (Project Management and Finance): Use the principles of project management such as scheduling, work breakdown structure and be conversant with the principles of Finance for profitable project management.
K20: PO7 (Ethics): Commit to professional ethics in managing software projects with financial aspects. Learn to use new technologies for cyber security and insulate customers from malware
K22: PO8 (Life-long learning): Change management skills and the ability to learn, keep up with contemporary technologies and ways of working.
A24: =SubjectDetails!$E$16 -> Dr. Ashwini Chavan, | K24: Course OutComes
A25: =SubjectDetails!$E$17 -> Subject Faculty | K25: Understand the basic concepts of Computer Network, and principle of layering
K26: Apply the error detection and correction techniques used in data transmission | L26: Apply the error detection and correction techniques used in data transmission | M26: Apply the error detection and correction techniques used in data transmission | N26: Apply the error detection and correction techniques used in data transmission | O26: Apply the error detection and correction techniques used in data transmission | P26: Apply the error detection and correction techniques used in data transmission | Q26: Apply the error detection and correction techniques used in data transmission | R26: Apply the error detection and correction techniques used in data transmission | S26: Apply the error detection and correction techniques used in data transmission | T26: Apply the error detection and correction techniques used in data transmission | U26: Apply the error detection and correction techniques used in data transmission | V26: Apply the error detection and correction techniques used in data transmission | W26: Apply the error detection and correction techniques used in data transmission
K27: Apply IP addressing schemes and sub netting | L27: Apply IP addressing schemes and sub netting | M27: Apply IP addressing schemes and sub netting | N27: Apply IP addressing schemes and sub netting | O27: Apply IP addressing schemes and sub netting | P27: Apply IP addressing schemes and sub netting | Q27: Apply IP addressing schemes and sub netting | R27: Apply IP addressing schemes and sub netting | S27: Apply IP addressing schemes and sub netting | T27: Apply IP addressing schemes and sub netting | U27: Apply IP addressing schemes and sub netting | V27: Apply IP addressing schemes and sub netting | W27: Apply IP addressing schemes and sub netting
A28: =SubjectDetails!$A$24 -> Dr. Ravi Chourasiya | E28: =SubjectDetails!$E$24 -> Dr. Ashwini Chavan | I28: =SubjectDetails!$H$24 -> Dr. Priyanka Singh | K28: Understand the concept of routing protocols, Application layer protocols and Network Security | L28: Understand the concept of routing protocols, Application layer protocols and Network Security | M28: Understand the concept of routing protocols, Application layer protocols and Network Security | N28: Understand the concept of routing protocols, Application layer protocols and Network Security | O28: Understand the concept of routing protocols, Application layer protocols and Network Security | P28: Understand the concept of routing protocols, Application layer protocols and Network Security | Q28: Understand the concept of routing protocols, Application layer protocols and Network Security | R28: Understand the concept of routing protocols, Application layer protocols and Network Security | S28: Understand the concept of routing protocols, Application layer protocols and Network Security | T28: Understand the concept of routing protocols, Application layer protocols and Network Security | U28: Understand the concept of routing protocols, Application layer protocols and Network Security | V28: Understand the concept of routing protocols, Application layer protocols and Network Security | W28: Understand the concept of routing protocols, Application layer protocols and Network Security
A29: =SubjectDetails!$A$25 -> (College Examination Officer) | E29: =SubjectDetails!$E$25 -> HOD (MCA) | I29: =SubjectDetails!$H$25 -> Director | K29: Apply the socket programming basics to create a simple chat application | L29: Apply the socket programming basics to create a simple chat application | M29: Apply the socket programming basics to create a simple chat application | N29: Apply the socket programming basics to create a simple chat application | O29: Apply the socket programming basics to create a simple chat application | P29: Apply the socket programming basics to create a simple chat application | Q29: Apply the socket programming basics to create a simple chat application | R29: Apply the socket programming basics to create a simple chat application | S29: Apply the socket programming basics to create a simple chat application | T29: Apply the socket programming basics to create a simple chat application | U29: Apply the socket programming basics to create a simple chat application | V29: Apply the socket programming basics to create a simple chat application | W29: Apply the socket programming basics to create a simple chat application

Sheet CCE1
A1: Dr. D.Y. Patil Educational Federation's
A2: Dr. D. Y. Patil Institute of Management and Entreprenuer Development, Varale, Pune
A3: (Permanently affiliated to Savitribai Phule Pune University, Accredited by NAAC 'A'
A4: Approved by AICTE, Recognized under 2 (f) & 12 (b) sections of UGC Act)
A5: Comprehensive Concurrent Evaluation (CCE) Sheet
A6: =CONCATENATE(Class," ", spl) -> MCA I SEM I AY 2023-24 | C6: =CONCATENATE("Name of Faculty: ", Faculty) -> Name of Faculty: Dr. Ashwini Chavan, | D6: =CONCATENATE("Course Name: ", Sub_Code) -> Course Name: Network Technologies
A7: Roll No. | B7: Seat No. | C7: Name of the Student | D7: CCE-I (Mid Term 1) | J7: Total Marks Obtained
D8: Q1 | E8: Q2 | F8: Q3
C9: Max Marks → | D9: 10 | E9: 10 | F9: 10 | J9: =SUM(D9:I9) -> 30
C10: CO Mapping → | D10: CO1 | E10: CO2 | F10: CO3
A11: 1 | B11: 22101 | C11: NAIK ANKIT JIVAN | D11: 9 | E11: 10 | F11: 10 | J11: =IF(F11<>"AB",SUM(D11:I11),"AB") -> 29
A12: 2 | B12: 22102 | C12: ARGADE RAVISHANKAR UTTAM | D12: 10 | E12: 9 | F12: 9 | J12: =IF(F12<>"AB",SUM(D12:I12),"AB") -> 28
A13: 3 | B13: 22103 | C13: ANERAO ONKAR RANGNATH | D13: 10 | E13: 10 | F13: 9 | J13: =IF(F13<>"AB",SUM(D13:I13),"AB") -> 29
A14: 4 | B14: 22104 | C14: MORE KIRAN SUNIL | D14: 10 | E14: 8 | F14: 8 | J14: =IF(F14<>"AB",SUM(D14:I14),"AB") -> 26
A15: 5 | B15: 22105 | C15: KSHIRSAGAR GAURAV SHRIKANT | D15: 10 | E15: 8 | F15: 8 | J15: =IF(F15<>"AB",SUM(D15:I15),"AB") -> 26
A16: 6 | B16: 22106 | C16: SHIRSAT MEGHA SHARAD | D16: 8 | E16: 9 | F16: 8 | J16: =IF(F16<>"AB",SUM(D16:I16),"AB") -> 25
A17: 7 | B17: 22107 | C17: INGALE RAHUL SUNIL | D17: 9 | E17: 10 | F17: 9 | J17: =IF(F17<>"AB",SUM(D17:I17),"AB") -> 28
A18: 8 | B18: 22108 | C18: MD TABISH ANWAR | D18: 9 | E18: 10 | F18: 10 | J18: =IF(F18<>"AB",SUM(D18:I18),"AB") -> 29
A19: 9 | B19: 22109 | C19: PUND SUYOG BHARAT | D19: 10 | E19: 10 | F19: 10 | J19: =IF(F19<>"AB",SUM(D19:I19),"AB") -> 30
A20: 10 | B20: 22110 | C20: JAGTAP DNYANESHWAR RAGHUNATH | D20: 8 | E20: 8 | F20: 10 | J20: =IF(F20<>"AB",SUM(D20:I20),"AB") -> 26
A21: 11 | B21: 22111 | C21: MAHAJAN PRATHAMESH JAGDISH | D21: 10 | E21: 10 | F21: 9 | J21: =IF(F21<>"AB",SUM(D21:I21),"AB") -> 29
A22: 12 | B22: 22112 | C22: PATHAN ALIZABEE AKHTAR KHAN | D22: 9 | E22: 9 | F22: 9 | J22: =IF(F22<>"AB",SUM(D22:I22),"AB") -> 27
... A118: 108 | B118: 22240 | C118: KISHOR LAXMAN HAKE | D118: 10 | E118: 8 | F118: 9 | J118: =IF(F118<>"AB",SUM(D118:I118),"AB") -> 27
A119: Total | C119: =COUNT(A11:A118) -> 108
A123: =Faculty -> Dr. Ashwini Chavan,
A124: =SubjectDetails!E17 -> Subject Faculty
A127: =SubjectDetails!A24 -> Dr. Ravi Chourasiya | D127: =SubjectDetails!E24 -> Dr. Ashwini Chavan | I127: =SubjectDetails!H24 -> Dr. Priyanka Singh
A128: =SubjectDetails!A25 -> (College Examination Officer) | D128: =SubjectDetails!E25 -> HOD (MCA) | I128: =SubjectDetails!H25 -> Director

Sheet CCE2
A1: Dr. D.Y. Patil Educational Federation's
A2: Dr. D. Y. Patil Institute of Management and Entreprenuer Development, Varale, Pune
A3: (Permanently affiliated to Savitribai Phule Pune University, Accredited by NAAC 'A'
A4: Approved by AICTE, Recognized under 2 (f) & 12 (b) sections of UGC Act)
A5: Comprehensive Concurrent Evaluation (CCE) Sheet
A6: =CONCATENATE(Class," ", spl) -> MCA I SEM I AY 2023-24 | C6: =CONCATENATE("Name of Faculty: ", Faculty) -> Name of Faculty: Dr. Ashwini Chavan, | D6: =CONCATENATE("Course Name: ", Sub_Code) -> Course Name: Network Technologies
A7: Roll No. | B7: Seat No. | C7: Name of the Student | D7: CCE-II (Assignment) | L7: Total Marks Obtained
D8: Q1 | E8: Q2 | F8: Q3 | G8: Q4 | H8: Q5 | I8: Q6 | J8: Q7 | K8: Q8
C9: Max Marks → | D9: 5 | E9: 5 | F9: 5 | G9: 5 | H9: 5 | I9: 5 | J9: 5 | K9: 5 | L9: =D9+E9+F9+G9+H9+I9+J9+K9 -> 40
C10: CO Mapping → | D10: CO1 | E10: CO2 | F10: CO2 | G10: CO2 | H10: CO3 | I10: CO3 | J10: CO4 | K10: CO4
A11: 1 | B11: 22101 | C11: NAIK ANKIT JIVAN | D11: 4 | E11: 5 | F11: 5 | G11: 5 | H11: 5 | I11: 5 | J11: 4 | K11: 4 | L11: =IF(E11<>"AB",SUM(D11:K11),"AB") -> 37
A12: 2 | B12: 22102 | C12: ARGADE RAVISHANKAR UTTAM | D12: 5 | E12: 5 | F12: 3 | G12: 3 | H12: 3 | I12: 3 | J12: 3 | K12: 4 | L12: =IF(E12<>"AB",SUM(D12:K12),"AB") -> 29
A13: 3 | B13: 22103 | C13: ANERAO ONKAR RANGNATH | D13: 4 | E13: 5 | F13: 3 | G13: 3 | H13: 3 | I13: 3 | J13: 4 | K13: 3 | L13: =IF(E13<>"AB",SUM(D13:K13),"AB") -> 28
A14: 4 | B14: 22104 | C14: MORE KIRAN SUNIL | D14: 3 | E14: 3 | F14: 5 | G14: 5 | H14: 5 | I14: 4 | J14: 3 | K14: 4 | L14: =IF(E14<>"AB",SUM(D14:K14),"AB") -> 32
A15: 5 | B15: 22105 | C15: KSHIRSAGAR GAURAV SHRIKANT | D15: 5 | E15: 5 | F15: 5 | G15: 5 | H15: 5 | I15: 3 | J15: 3 | K15: 3 | L15: =IF(E15<>"AB",SUM(D15:K15),"AB") -> 34
A16: 6 | B16: 22106 | C16: SHIRSAT MEGHA SHARAD | D16: 4 | E16: 4 | F16: 4 | G16: 3 | H16: 3 | I16: 4 | J16: 5 | K16: 3 | L16: =IF(E16<>"AB",SUM(D16:K16),"AB") -> 30
A17: 7 | B17: 22107 | C17: INGALE RAHUL SUNIL | D17: 3 | E17: 3 | F17: 3 | G17: 5 | H17: 5 | I17: 4 | J17: 3 | K17: 3 | L17: =IF(E17<>"AB",SUM(D17:K17),"AB") -> 29
A18: 8 | B18: 22108 | C18: MD TABISH ANWAR | D18: 5 | E18: 5 | F18: 5 | G18: 3 | H18: 3 | I18: 5 | J18: 5 | K18: 3 | L18: =IF(E18<>"AB",SUM(D18:K18),"AB") -> 34
A19: 9 | B19: 22109 | C19: PUND SUYOG BHARAT | D19: 5 | E19: 5 | F19: 4 | G19: 3 | H19: 3 | I19: 5 | J19: 3 | K19: 4 | L19: =IF(E19<>"AB",SUM(D19:K19),"AB") -> 32
A20: 10 | B20: 22110 | C20: JAGTAP DNYANESHWAR RAGHUNATH | D20: 5 | E20: 5 | F20: 5 | G20: 5 | H20: 4 | I20: 5 | J20: 5 | K20: 3 | L20: =IF(E20<>"AB",SUM(D20:K20),"AB") -> 37
A21: 11 | B21: 22111 | C21: MAHAJAN PRATHAMESH JAGDISH | D21: 3 | E21: 4 | F21: 4 | G21: 3 | H21: 5 | I21: 4 | J21: 3 | K21: 3 | L21: =IF(E21<>"AB",SUM(D21:K21),"AB") -> 29
A22: 12 | B22: 22112 | C22: PATHAN ALIZABEE AKHTAR KHAN | D22: 3 | E22: 3 | F22: 4 | G22: 3 | H22: 4 | I22: 5 | J22: 3 | K22: 3 | L22: =IF(E22<>"AB",SUM(D22:K22),"AB") -> 28
... A118: 108 | B118: 22240 | C118: KISHOR LAXMAN HAKE | D118: 2 | E118: 3 | F118: 2 | G118: 3 | H118: 3 | I118: 3 | J118: 2 | K118: 3 | L118: =IF(E118<>"AB",SUM(D118:K118),"AB") -> 21
A119: Total No. of Students: | C119: =COUNT(A11:A118) -> 108
C124: =Faculty -> Dr. Ashwini Chavan,
C125: =SubjectDetails!E17 -> Subject Faculty
A129: =SubjectDetails!A24 -> Dr. Ravi Chourasiya | D129: =SubjectDetails!E24 -> Dr. Ashwini Chavan | K129: =SubjectDetails!H24 -> Dr. Priyanka Singh
A130: =SubjectDetails!A25 -> (College Examination Officer) | D130: =SubjectDetails!E25 -> HOD (MCA) | K130: =SubjectDetails!H25 -> Director

Sheet CCE3
A1: Dr. D.Y. Patil Educational Federation's
A2: Dr. D. Y. Patil Institute of Management and Entreprenuer Development, Varale, Pune
A3: (Permanently affiliated to Savitribai Phule Pune University, Accredited by NAAC 'A'
A4: Approved by AICTE, Recognized under 2 (f) & 12 (b) sections of UGC Act)
A5: Comprehensive Concurrent Evaluation (CCE) Sheet
A6: =CONCATENATE(Class," ", spl) -> MCA I SEM I AY 2023-24 | C6: =CONCATENATE("Name of Faculty: ", Faculty) -> Name of Faculty: Dr. Ashwini Chavan, | D6: =CONCATENATE("Course Name: ", Sub_Code) -> Course Name: Network Technologies
A7: Roll No. | B7: Seat No. | C7: Name of the Student | D7: CCE-III (End Term) | N7: Total Marks Obtained
D8: Q1 | E8: Q2 | F8: Q3 | G8: Q4 | H8: Q5
C9: Max Marks → | D9: 10 | E9: 10 | F9: 10 | G9: 10 | H9: 10 | N9: =D9+E9+F9+G9+H9+I9+J9+K9+L9+M9 -> 50
C10: CO Mapping → | D10: CO1 | E10: CO2 | F10: CO3 | G10: CO4 | H10: CO5
A11: 1 | B11: 22101 | C11: NAIK ANKIT JIVAN | D11: 6 | E11: 8 | F11: 8 | G11: 8 | H11: 9 | N11: =IF(D11<>"AB",SUM(D11:M11),"AB") -> 39
A12: 2 | B12: 22102 | C12: ARGADE RAVISHANKAR UTTAM | D12: 5 | E12: 8 | F12: 6 | G12: 8 | H12: 5 | N12: =IF(D12<>"AB",SUM(D12:M12),"AB") -> 32
A13: 3 | B13: 22103 | C13: ANERAO ONKAR RANGNATH | D13: 9 | E13: 8 | F13: 9 | G13: 9 | H13: 8 | N13: =IF(D13<>"AB",SUM(D13:M13),"AB") -> 43
A14: 4 | B14: 22104 | C14: MORE KIRAN SUNIL | D14: 9 | E14: 8 | F14: 8 | G14: 8 | H14: 9 | N14: =IF(D14<>"AB",SUM(D14:M14),"AB") -> 42
A15: 5 | B15: 22105 | C15: KSHIRSAGAR GAURAV SHRIKANT | D15: 8 | E15: 9 | F15: 6 | G15: 5 | H15: 9 | N15: =IF(D15<>"AB",SUM(D15:M15),"AB") -> 37
A16: 6 | B16: 22106 | C16: SHIRSAT MEGHA SHARAD | D16: 8 | E16: 4 | F16: 8 | G16: 8 | H16: 8 | N16: =IF(D16<>"AB",SUM(D16:M16),"AB") -> 36
A17: 7 | B17: 22107 | C17: INGALE RAHUL SUNIL | D17: 8 | E17: 9 | F17: 9 | G17: 7 | H17: 8 | N17: =IF(D17<>"AB",SUM(D17:M17),"AB") -> 41
A18: 8 | B18: 22108 | C18: MD TABISH ANWAR | D18: 7 | E18: 8 | F18: 9 | G18: 7 | H18: 8 | N18: =IF(D18<>"AB",SUM(D18:M18),"AB") -> 39
A19: 9 | B19: 22109 | C19: PUND SUYOG BHARAT | D19: 9 | E19: 8 | F19: 9 | G19: 8 | H19: 7 | N19: =IF(D19<>"AB",SUM(D19:M19),"AB") -> 41
A20: 10 | B20: 22110 | C20: JAGTAP DNYANESHWAR RAGHUNATH | D20: 8 | E20: 8 | F20: 7 | G20: 9 | H20: 9 | N20: =IF(D20<>"AB",SUM(D20:M20),"AB") -> 41
A21: 11 | B21: 22111 | C21: MAHAJAN PRATHAMESH JAGDISH | D21: 10 | E21: 9 | F21: 9 | G21: 10 | H21: 7 | N21: =IF(D21<>"AB",SUM(D21:M21),"AB") -> 45
A22: 12 | B22: 22112 | C22: PATHAN ALIZABEE AKHTAR KHAN | D22: 9 | E22: 8 | F22: 8 | G22: 9 | H22: 9 | N22: =IF(D22<>"AB",SUM(D22:M22),"AB") -> 43
... A118: 108 | B118: 22240 | C118: KISHOR LAXMAN HAKE | D118: 8 | E118: 9 | F118: 10 | G118: 8 | H118: 9 | N118: =IF(D118<>"AB",SUM(D118:M118),"AB") -> 44
A119: Total No. of Students: | C119: =COUNT(A11:A118) -> 108
C123: =Faculty -> Dr. Ashwini Chavan,
C124: =SubjectDetails!E17 -> Subject Faculty
A126: =SubjectDetails!A24 -> Dr. Ravi Chourasiya | D126: =SubjectDetails!E24 -> Dr. Ashwini Chavan | H126: =SubjectDetails!H24 -> Dr. Priyanka Singh
A127: =SubjectDetails!A25 -> (College Examination Officer) | D127: =SubjectDetails!E25 -> HOD (MCA) | H127: =SubjectDetails!H25 -> Director

Sheet CCE
A1: Dr. D.Y. Patil Educational Federation's
A2: Dr. D. Y. Patil Institute of Management and Entreprenuer Development, Varale, Pune
A3: (Permanently affiliated to Savitribai Phule Pune University, Accredited by NAAC 'A'
A4: Approved by AICTE, Recognized under 2 (f) & 12 (b) sections of UGC Act)
A5: Comprehensive Concurrent Evaluation (CCE) Sheet
A6: =CONCATENATE(Class," ", spl) -> MCA I SEM I AY 2023-24 | C6: =CONCATENATE("Name of Faculty: ", Faculty) -> Name of Faculty: Dr. Ashwini Chavan, | D6: =CONCATENATE("Course Name: ", Sub_Code) -> Course Name: Network Technologies
A7: Roll No. | B7: Seat No. | C7: Name | D7: CCE#1 (30) | E7: CCE#2 (20) | F7: CCE#3 (50) | G7: Total (100) | H7: Final (25)
A8: 1 | B8: 22101 | C8: NAIK ANKIT JIVAN | D8: ='CCE1'!J11 -> 29 | E8: ='CCE2'!L11 -> 37 | F8: ='CCE3'!N11 -> 39 | G8: =SUM(Table3[[#This Row],[CCE'#1 (30)]:[CCE'#3 (50)]]) -> 105 | H8: =Table3[[#This Row],[Total (100)]]/('CCE1'!$J$9+'CCE2'!$L$9+'CCE3'!$N$9)*25 -> 21.875
A9: 2 | B9: 22102 | C9: ARGADE RAVISHANKAR UTTAM | D9: ='CCE1'!J12 -> 28 | E9: ='CCE2'!L12 -> 29 | F9: ='CCE3'!N12 -> 32 | G9: =SUM(Table3[[#This Row],[CCE'#1 (30)]:[CCE'#3 (50)]]) -> 89 | H9: =Table3[[#This Row],[Total (100)]]/('CCE1'!$J$9+'CCE2'!$L$9+'CCE3'!$N$9)*25 -> 18.541667
A10: 3 | B10: 22103 | C10: ANERAO ONKAR RANGNATH | D10: ='CCE1'!J13 -> 29 | E10: ='CCE2'!L13 -> 28 | F10: ='CCE3'!N13 -> 43 | G10: =SUM(Table3[[#This Row],[CCE'#1 (30)]:[CCE'#3 (50)]]) -> 100 | H10: =Table3[[#This Row],[Total (100)]]/('CCE1'!$J$9+'CCE2'!$L$9+'CCE3'!$N$9)*25 -> 20.833333
A11: 4 | B11: 22104 | C11: MORE KIRAN SUNIL | D11: ='CCE1'!J14 -> 26 | E11: ='CCE2'!L14 -> 32 | F11: ='CCE3'!N14 -> 42 | G11: =SUM(Table3[[#This Row],[CCE'#1 (30)]:[CCE'#3 (50)]]) -> 100 | H11: =Table3[[#This Row],[Total (100)]]/('CCE1'!$J$9+'CCE2'!$L$9+'CCE3'!$N$9)*25 -> 20.833333
A12: 5 | B12: 22105 | C12: KSHIRSAGAR GAURAV SHRIKANT | D12: ='CCE1'!J15 -> 26 | E12: ='CCE2'!L15 -> 34 | F12: ='CCE3'!N15 -> 37 | G12: =SUM(Table3[[#This Row],[CCE'#1 (30)]:[CCE'#3 (50)]]) -> 97 | H12: =Table3[[#This Row],[Total (100)]]/('CCE1'!$J$9+'CCE2'!$L$9+'CCE3'!$N$9)*25 -> 20.208333
A13: 6 | B13: 22106 | C13: SHIRSAT MEGHA SHARAD | D13: ='CCE1'!J16 -> 25 | E13: ='CCE2'!L16 -> 30 | F13: ='CCE3'!N16 -> 36 | G13: =SUM(Table3[[#This Row],[CCE'#1 (30)]:[CCE'#3 (50)]]) -> 91 | H13: =Table3[[#This Row],[Total (100)]]/('CCE1'!$J$9+'CCE2'!$L$9+'CCE3'!$N$9)*25 -> 18.958333
A14: 7 | B14: 22107 | C14: INGALE RAHUL SUNIL | D14: ='CCE1'!J17 -> 28 | E14: ='CCE2'!L17 -> 29 | F14: ='CCE3'!N17 -> 41 | G14: =SUM(Table3[[#This Row],[CCE'#1 (30)]:[CCE'#3 (50)]]) -> 98 | H14: =Table3[[#This Row],[Total (100)]]/('CCE1'!$J$9+'CCE2'!$L$9+'CCE3'!$N$9)*25 -> 20.416667
A15: 8 | B15: 22108 | C15: MD TABISH ANWAR | D15: ='CCE1'!J18 -> 29 | E15: ='CCE2'!L18 -> 34 | F15: ='CCE3'!N18 -> 39 | G15: =SUM(Table3[[#This Row],[CCE'#1 (30)]:[CCE'#3 (50)]]) -> 102 | H15: =Table3[[#This Row],[Total (100)]]/('CCE1'!$J$9+'CCE2'!$L$9+'CCE3'!$N$9)*25 -> 21.25
A16: 9 | B16: 22109 | C16: PUND SUYOG BHARAT | D16: ='CCE1'!J19 -> 30 | E16: ='CCE2'!L19 -> 32 | F16: ='CCE3'!N19 -> 41 | G16: =SUM(Table3[[#This Row],[CCE'#1 (30)]:[CCE'#3 (50)]]) -> 103 | H16: =Table3[[#This Row],[Total (100)]]/('CCE1'!$J$9+'CCE2'!$L$9+'CCE3'!$N$9)*25 -> 21.458333
A17: 10 | B17: 22110 | C17: JAGTAP DNYANESHWAR RAGHUNATH | D17: ='CCE1'!J20 -> 26 | E17: ='CCE2'!L20 -> 37 | F17: ='CCE3'!N20 -> 41 | G17: =SUM(Table3[[#This Row],[CCE'#1 (30)]:[CCE'#3 (50)]]) -> 104 | H17: =Table3[[#This Row],[Total (100)]]/('CCE1'!$J$9+'CCE2'!$L$9+'CCE3'!$N$9)*25 -> 21.666667
A18: 11 | B18: 22111 | C18: MAHAJAN PRATHAMESH JAGDISH | D18: ='CCE1'!J21 -> 29 | E18: ='CCE2'!L21 -> 29 | F18: ='CCE3'!N21 -> 45 | G18: =SUM(Table3[[#This Row],[CCE'#1 (30)]:[CCE'#3 (50)]]) -> 103 | H18: =Table3[[#This Row],[Total (100)]]/('CCE1'!$J$9+'CCE2'!$L$9+'CCE3'!$N$9)*25 -> 21.458333
A19: 12 | B19: 22112 | C19: PATHAN ALIZABEE AKHTAR KHAN | D19: ='CCE1'!J22 -> 27 | E19: ='CCE2'!L22 -> 28 | F19: ='CCE3'!N22 -> 43 | G19: =SUM(Table3[[#This Row],[CCE'#1 (30)]:[CCE'#3 (50)]]) -> 98 | H19: =Table3[[#This Row],[Total (100)]]/('CCE1'!$J$9+'CCE2'!$L$9+'CCE3'!$N$9)*25 -> 20.416667
... A25: 18 | B25: 22118 | C25: SHINDE MAHESH DHANAJI | D25: ='CCE1'!J28 -> 27 | E25: ='CCE2'!L28 -> 33 | F25: ='CCE3'!N28 -> 47 | G25: =SUM(Table3[[#This Row],[CCE'#1 (30)]:[CCE'#3 (50)]]) -> 107 | H25: =Table3[[#This Row],[Total (100)]]/('CCE1'!$J$9+'CCE2'!$L$9+'CCE3'!$N$9)*25 -> 22.291667
A26: 19 | B26: 22119 | C26: BHISE DIPAK VETALA | D26: ='CCE1'!J11 -> 29 | E26: ='CCE2'!L29 -> 30 | F26: ='CCE3'!N29 -> 44 | G26: =SUM(Table3[[#This Row],[CCE'#1 (30)]:[CCE'#3 (50)]]) -> 103 | H26: =Table3[[#This Row],[Total (100)]]/('CCE1'!$J$9+'CCE2'!$L$9+'CCE3'!$N$9)*25 -> 21.458333
A27: 20 | B27: 22120 | C27: BHAGWAT SHREYAS RAVINDRA | D27: ='CCE1'!J12 -> 28 | E27: ='CCE2'!L30 -> 20 | F27: ='CCE3'!N30 -> 41 | G27: =SUM(Table3[[#This Row],[CCE'#1 (30)]:[CCE'#3 (50)]]) -> 89 | H27: =Table3[[#This Row],[Total (100)]]/('CCE1'!$J$9+'CCE2'!$L$9+'CCE3'!$N$9)*25 -> 18.541667
A28: 21 | B28: 22121 | C28: RAHUL VILAS THORAT | D28: ='CCE1'!J13 -> 29 | E28: ='CCE2'!L31 -> 36 | F28: ='CCE3'!N31 -> 41 | G28: =SUM(Table3[[#This Row],[CCE'#1 (30)]:[CCE'#3 (50)]]) -> 106 | H28: =Table3[[#This Row],[Total (100)]]/('CCE1'!$J$9+'CCE2'!$L$9+'CCE3'!$N$9)*25 -> 22.083333
A29: 22 | B29: 22122 | C29: AVINASH BAPU MANE | D29: ='CCE1'!J14 -> 26 | E29: ='CCE2'!L32 -> 31 | F29: ='CCE3'!N32 -> 44 | G29: =SUM(Table3[[#This Row],[CCE'#1 (30)]:[CCE'#3 (50)]]) -> 101 | H29: =Table3[[#This Row],[Total (100)]]/('CCE1'!$J$9+'CCE2'!$L$9+'CCE3'!$N$9)*25 -> 21.041667
A30: 23 | B30: 22123 | C30: SHELKE VAIBHAV MACHHINDRA | D30: ='CCE1'!J15 -> 26 | E30: ='CCE2'!L33 -> 32 | F30: ='CCE3'!N33 -> 40 | G30: =SUM(Table3[[#This Row],[CCE'#1 (30)]:[CCE'#3 (50)]]) -> 98 | H30: =Table3[[#This Row],[Total (100)]]/('CCE1'!$J$9+'CCE2'!$L$9+'CCE3'!$N$9)*25 -> 20.416667
A31: 24 | B31: 22124 | C31: VIJAY SUDHAKAR LOKARE | D31: ='CCE1'!J16 -> 25 | E31: ='CCE2'!L34 -> 29 | F31: ='CCE3'!N34 -> 45 | G31: =SUM(Table3[[#This Row],[CCE'#1 (30)]:[CCE'#3 (50)]]) -> 99 | H31: =Table3[[#This Row],[Total (100)]]/('CCE1'!$J$9+'CCE2'!$L$9+'CCE3'!$N$9)*25 -> 20.625
A32: 25 | B32: 22125 | C32: CHANDANKHEDE SEJAL ASHOK | D32: ='CCE1'!J17 -> 28 | E32: ='CCE2'!L35 -> 32 | F32: ='CCE3'!N35 -> 45 | G32: =SUM(Table3[[#This Row],[CCE'#1 (30)]:[CCE'#3 (50)]]) -> 105 | H32: =Table3[[#This Row],[Total (100)]]/('CCE1'!$J$9+'CCE2'!$L$9+'CCE3'!$N$9)*25 -> 21.875
A33: 26 | B33: 22126 | C33: VAISHNAVI SAYAJI PINGAT | D33: ='CCE1'!J18 -> 29 | E33: ='CCE2'!L36 -> 32 | F33: ='CCE3'!N36 -> 46 | G33: =SUM(Table3[[#This Row],[CCE'#1 (30)]:[CCE'#3 (50)]]) -> 107 | H33: =Table3[[#This Row],[Total (100)]]/('CCE1'!$J$9+'CCE2'!$L$9+'CCE3'!$N$9)*25 -> 22.291667
A34: 27 | B34: 22127 | C34: BORSE NIKITA BHALERAO | D34: ='CCE1'!J19 -> 30 | E34: ='CCE2'!L37 -> 29 | F34: ='CCE3'!N37 -> 45 | G34: =SUM(Table3[[#This Row],[CCE'#1 (30)]:[CCE'#3 (50)]]) -> 104 | H34: =Table3[[#This Row],[Total (100)]]/('CCE1'!$J$9+'CCE2'!$L$9+'CCE3'!$N$9)*25 -> 21.666667
A35: 28 | B35: 22128 | C35: RADHIKA NARAYAN SHELAR | D35: ='CCE1'!J20 -> 26 | E35: ='CCE2'!L38 -> 32 | F35: ='CCE3'!N38 -> 44 | G35: =SUM(Table3[[#This Row],[CCE'#1 (30)]:[CCE'#3 (50)]]) -> 102 | H35: =Table3[[#This Row],[Total (100)]]/('CCE1'!$J$9+'CCE2'!$L$9+'CCE3'!$N$9)*25 -> 21.25
A36: 29 | B36: 22129 | C36: BRAMHANE DIPAK LAXMAN | D36: ='CCE1'!J21 -> 29 | E36: ='CCE2'!L39 -> 34 | F36: ='CCE3'!N39 -> 45 | G36: =SUM(Table3[[#This Row],[CCE'#1 (30)]:[CCE'#3 (50)]]) -> 108 | H36: =Table3[[#This Row],[Total (100)]]/('CCE1'!$J$9+'CCE2'!$L$9+'CCE3'!$N$9)*25 -> 22.5
A37: 30 | B37: 22130 | C37: PHATKE SAKSHI SANTOSH | D37: ='CCE1'!J22 -> 27 | E37: ='CCE2'!L40 -> 35 | F37: ='CCE3'!N40 -> 43 | G37: =SUM(Table3[[#This Row],[CCE'#1 (30)]:[CCE'#3 (50)]]) -> 105 | H37: =Table3[[#This Row],[Total (100)]]/('CCE1'!$J$9+'CCE2'!$L$9+'CCE3'!$N$9)*25 -> 21.875
... A86: 79 | B86: 22211 | C86: GANDAGE GANPATI DAYANAND | D86: ='CCE1'!J71 -> 25 | E86: ='CCE2'!L89 -> 36 | F86: ='CCE3'!N89 -> 48 | G86: =SUM(Table3[[#This Row],[CCE'#1 (30)]:[CCE'#3 (50)]]) -> 109 | H86: =Table3[[#This Row],[Total (100)]]/('CCE1'!$J$9+'CCE2'!$L$9+'CCE3'!$N$9)*25 -> 22.708333
A87: 80 | B87: 22212 | C87: SURYAWANSHI DIVYA BAJRANG | D87: ='CCE1'!J11 -> 29 | E87: ='CCE2'!L90 -> 36 | F87: ='CCE3'!N90 -> 44 | G87: =SUM(Table3[[#This Row],[CCE'#1 (30)]:[CCE'#3 (50)]]) -> 109 | H87: =Table3[[#This Row],[Total (100)]]/('CCE1'!$J$9+'CCE2'!$L$9+'CCE3'!$N$9)*25 -> 22.708333
A88: 81 | B88: 22213 | C88: KAMBLE YOGESH ARJUN | D88: ='CCE1'!J12 -> 28 | E88: ='CCE2'!L91 -> 31 | F88: ='CCE3'!N91 -> 45 | G88: =SUM(Table3[[#This Row],[CCE'#1 (30)]:[CCE'#3 (50)]]) -> 104 | H88: =Table3[[#This Row],[Total (100)]]/('CCE1'!$J$9+'CCE2'!$L$9+'CCE3'!$N$9)*25 -> 21.666667
A89: 82 | B89: 22214 | C89: CHAUHAN MANAV JIGAR KUMAR | D89: ='CCE1'!J13 -> 29 | E89: ='CCE2'!L92 -> 31 | F89: ='CCE3'!N92 -> 30 | G89: =SUM(Table3[[#This Row],[CCE'#1 (30)]:[CCE'#3 (50)]]) -> 90 | H89: =Table3[[#This Row],[Total (100)]]/('CCE1'!$J$9+'CCE2'!$L$9+'CCE3'!$N$9)*25 -> 18.75
A90: 83 | B90: 22215 | C90: AJAY SATISH MANE | D90: ='CCE1'!J14 -> 26 | E90: ='CCE2'!L93 -> 31 | F90: ='CCE3'!N93 -> 45 | G90: =SUM(Table3[[#This Row],[CCE'#1 (30)]:[CCE'#3 (50)]]) -> 102 | H90: =Table3[[#This Row],[Total (100)]]/('CCE1'!$J$9+'CCE2'!$L$9+'CCE3'!$N$9)*25 -> 21.25
A91: 84 | B91: 22216 | C91: CHOUDHARI SIDDHESH MURALIDHAR | D91: ='CCE1'!J15 -> 26 | E91: ='CCE2'!L94 -> 30 | F91: ='CCE3'!N94 -> 46 | G91: =SUM(Table3[[#This Row],[CCE'#1 (30)]:[CCE'#3 (50)]]) -> 102 | H91: =Table3[[#This Row],[Total (100)]]/('CCE1'!$J$9+'CCE2'!$L$9+'CCE3'!$N$9)*25 -> 21.25
A92: 85 | B92: 22217 | C92: VARGANTI AARTI YALLAPPA | D92: ='CCE1'!J16 -> 25 | E92: ='CCE2'!L95 -> 35 | F92: ='CCE3'!N95 -> 44 | G92: =SUM(Table3[[#This Row],[CCE'#1 (30)]:[CCE'#3 (50)]]) -> 104 | H92: =Table3[[#This Row],[Total (100)]]/('CCE1'!$J$9+'CCE2'!$L$9+'CCE3'!$N$9)*25 -> 21.666667
A93: 86 | B93: 22218 | C93: KHAIRE PRATIKSHA KAILAS | D93: ='CCE1'!J17 -> 28 | E93: ='CCE2'!L96 -> 30 | F93: ='CCE3'!N96 -> 46 | G93: =SUM(Table3[[#This Row],[CCE'#1 (30)]:[CCE'#3 (50)]]) -> 104 | H93: =Table3[[#This Row],[Total (100)]]/('CCE1'!$J$9+'CCE2'!$L$9+'CCE3'!$N$9)*25 -> 21.666667
...

Sheet CO Int. Attn
A1: Dr. D.Y. Patil Educational Federation's
A2: Dr. D. Y. Patil Institute of Management and Entreprenuer Development, Varale, Pune
A3: (Permanently affiliated to Savitribai Phule Pune University, Accredited by NAAC 'A'
A4: Approved by AICTE, Recognized under 2 (f) & 12 (b) sections of UGC Act)
A6: =CONCATENATE("Faculty Name: ", Faculty) -> Faculty Name: Dr. Ashwini Chavan, | I6: Benchmarks | L6: 3 | N6: 70 | O6: % of Students to get | S6: 0.6
A7: =CONCATENATE("Subject Name & Code: ", Sub_Code) -> Subject Name & Code: Network Technologies | L7: 2 | N7: 60 | U7: 60
A8: =CONCATENATE("Class: ",Class_AY) -> Class: MCA I SEM I AY 2023-24 | L8: 1 | N8: 50
A11: Sr. No | B11: Seat No. | C11: Name of the Student | D11: CCE1 (Mid Term: 30) | I11: CCE2 (Assignment :20) | N11: CCE3 (End term:50) | S11: Combined Assessment Marks for COs (100) | X11: Total Marks Obtained (25)
D12: CO1 | E12: CO2 | F12: CO3 | G12: CO4 | H12: CO5 | I12: CO1 | J12: CO2 | K12: CO3 | L12: CO4 | M12: CO5 | N12: CO1 | O12: CO2 | P12: CO3 | Q12: CO4 | R12: CO5 | S12: CO1 | T12: CO2 | U12: CO3 | V12: CO4 | W12: CO5
D13: ='CCE1'!D9+'CCE1'!E9 -> 20 | E13: ='CCE1'!F9+'CCE1'!G9 -> 10 | F13: ='CCE1'!H9+'CCE1'!I9 -> 0 | G13: 0 | H13: 0 | I13: ='CCE2'!D9+'CCE2'!E9 -> 10 | J13: ='CCE2'!F9+'CCE2'!G9 -> 10 | K13: 0 | L13: 0 | M13: 0 | N13: 10 | O13: 10 | P13: 10 | Q13: 10 | R13: 10 | S13: =D13+I13+N13 -> 40 | T13: =E13+J13+O13 -> 30 | U13: =F13+K13+P13 -> 10 | V13: =G13+L13+Q13 -> 10 | W13: =H13+M13+R13 -> 10 | X13: =SUM(S13:W13) -> 100
A14: 1 | B14: 22101 | C14: NAIK ANKIT JIVAN | D14: ='CCE1'!D11+'CCE1'!E11 -> 19 | E14: ='CCE1'!E11+'CCE1'!F11 -> 20 | F14: ='CCE1'!F11+'CCE1'!G11 -> 10 | I14: ='CCE2'!D11+'CCE2'!E11 -> 9 | J14: ='CCE2'!F11+'CCE2'!G11 -> 10 | N14: ='CCE3'!D11 -> 6 | O14: ='CCE3'!E11 -> 8 | P14: ='CCE3'!F11 -> 8 | Q14: ='CCE3'!G11 -> 8 | R14: ='CCE3'!H11 -> 9 | S14: =IFERROR(SUM(D14,I14,N14),"AB") -> 34 | T14: =IFERROR(SUM(E14,J14,O14),"AB") -> 38 | U14: =IFERROR(SUM(F14,K14,P14),"AB") -> 18 | V14: =IFERROR(SUM(G14,L14,Q14),"AB") -> 8 | W14: =IFERROR(SUM(H14,M14,R14),"AB") -> 9 | X14: =IFERROR(SUM(S14:W14),"AB") -> 107
A15: 2 | B15: 22102 | C15: ARGADE RAVISHANKAR UTTAM | D15: ='CCE1'!D12+'CCE1'!E12 -> 19 | E15: ='CCE1'!E12+'CCE1'!F12 -> 18 | F15: ='CCE1'!F12+'CCE1'!G12 -> 9 | I15: ='CCE2'!D12+'CCE2'!E12 -> 10 | J15: ='CCE2'!F12+'CCE2'!G12 -> 6 | N15: ='CCE3'!D12 -> 5 | O15: ='CCE3'!E12 -> 8 | P15: ='CCE3'!F12 -> 6 | Q15: ='CCE3'!G12 -> 8 | R15: ='CCE3'!H12 -> 5 | S15: =IFERROR(SUM(D15,I15,N15),"AB") -> 34 | T15: =IFERROR(SUM(E15,J15,O15),"AB") -> 32 | U15: =IFERROR(SUM(F15,K15,P15),"AB") -> 15 | V15: =IFERROR(SUM(G15,L15,Q15),"AB") -> 8 | W15: =IFERROR(SUM(H15,M15,R15),"AB") -> 5 | X15: =IFERROR(SUM(S15:W15),"AB") -> 94
A16: 3 | B16: 22103 | C16: ANERAO ONKAR RANGNATH | D16: ='CCE1'!D13+'CCE1'!E13 -> 20 | E16: ='CCE1'!E13+'CCE1'!F13 -> 19 | F16: ='CCE1'!F13+'CCE1'!G13 -> 9 | I16: ='CCE2'!D13+'CCE2'!E13 -> 9 | J16: ='CCE2'!F13+'CCE2'!G13 -> 6 | N16: ='CCE3'!D13 -> 9 | O16: ='CCE3'!E13 -> 8 | P16: ='CCE3'!F13 -> 9 | Q16: ='CCE3'!G13 -> 9 | R16: ='CCE3'!H13 -> 8 | S16: =IFERROR(SUM(D16,I16,N16),"AB") -> 38 | T16: =IFERROR(SUM(E16,J16,O16),"AB") -> 33 | U16: =IFERROR(SUM(F16,K16,P16),"AB") -> 18 | V16: =IFERROR(SUM(G16,L16,Q16),"AB") -> 9 | W16: =IFERROR(SUM(H16,M16,R16),"AB") -> 8 | X16: =IFERROR(SUM(S16:W16),"AB") -> 106
A17: 4 | B17: 22104 | C17: MORE KIRAN SUNIL | D17: ='CCE1'!D14+'CCE1'!E14 -> 18 | E17: ='CCE1'!E14+'CCE1'!F14 -> 16 | F17: ='CCE1'!F14+'CCE1'!G14 -> 8 | I17: ='CCE2'!D14+'CCE2'!E14 -> 6 | J17: ='CCE2'!F14+'CCE2'!G14 -> 10 | N17: ='CCE3'!D14 -> 9 | O17: ='CCE3'!E14 -> 8 | P17: ='CCE3'!F14 -> 8 | Q17: ='CCE3'!G14 -> 8 | R17: ='CCE3'!H14 -> 9 | S17: =IFERROR(SUM(D17,I17,N17),"AB") -> 33 | T17: =IFERROR(SUM(E17,J17,O17),"AB") -> 34 | U17: =IFERROR(SUM(F17,K17,P17),"AB") -> 16 | V17: =IFERROR(SUM(G17,L17,Q17),"AB") -> 8 | W17: =IFERROR(SUM(H17,M17,R17),"AB") -> 9 | X17: =IFERROR(SUM(S17:W17),"AB") -> 100
A18: 5 | B18: 22105 | C18: KSHIRSAGAR GAURAV SHRIKANT | D18: ='CCE1'!D15+'CCE1'!E15 -> 18 | E18: ='CCE1'!E15+'CCE1'!F15 -> 16 | F18: ='CCE1'!F15+'CCE1'!G15 -> 8 | I18: ='CCE2'!D15+'CCE2'!E15 -> 10 | J18: ='CCE2'!F15+'CCE2'!G15 -> 10 | N18: ='CCE3'!D15 -> 8 | O18: ='CCE3'!E15 -> 9 | P18: ='CCE3'!F15 -> 6 | Q18: ='CCE3'!G15 -> 5 | R18: ='CCE3'!H15 -> 9 | S18: =IFERROR(SUM(D18,I18,N18),"AB") -> 36 | T18: =IFERROR(SUM(E18,J18,O18),"AB") -> 35 | U18: =IFERROR(SUM(F18,K18,P18),"AB") -> 14 | V18: =IFERROR(SUM(G18,L18,Q18),"AB") -> 5 | W18: =IFERROR(SUM(H18,M18,R18),"AB") -> 9 | X18: =IFERROR(SUM(S18:W18),"AB") -> 99
A19: 6 | B19: 22106 | C19: SHIRSAT MEGHA SHARAD | D19: ='CCE1'!D16+'CCE1'!E16 -> 17 | E19: ='CCE1'!E16+'CCE1'!F16 -> 17 | F19: ='CCE1'!F16+'CCE1'!G16 -> 8 | I19: ='CCE2'!D16+'CCE2'!E16 -> 8 | J19: ='CCE2'!F16+'CCE2'!G16 -> 7 | N19: ='CCE3'!D16 -> 8 | O19: ='CCE3'!E16 -> 4 | P19: ='CCE3'!F16 -> 8 | Q19: ='CCE3'!G16 -> 8 | R19: ='CCE3'!H16 -> 8 | S19: =IFERROR(SUM(D19,I19,N19),"AB") -> 33 | T19: =IFERROR(SUM(E19,J19,O19),"AB") -> 28 | U19: =IFERROR(SUM(F19,K19,P19),"AB") -> 16 | V19: =IFERROR(SUM(G19,L19,Q19),"AB") -> 8 | W19: =IFERROR(SUM(H19,M19,R19),"AB") -> 8 | X19: =IFERROR(SUM(S19:W19),"AB") -> 93
A20: 7 | B20: 22107 | C20: INGALE RAHUL SUNIL | D20: ='CCE1'!D17+'CCE1'!E17 -> 19 | E20: ='CCE1'!E17+'CCE1'!F17 -> 19 | F20: ='CCE1'!F17+'CCE1'!G17 -> 9 | I20: ='CCE2'!D17+'CCE2'!E17 -> 6 | J20: ='CCE2'!F17+'CCE2'!G17 -> 8 | N20: ='CCE3'!D17 -> 8 | O20: ='CCE3'!E17 -> 9 | P20: ='CCE3'!F17 -> 9 | Q20: ='CCE3'!G17 -> 7 | R20: ='CCE3'!H17 -> 8 | S20: =IFERROR(SUM(D20,I20,N20),"AB") -> 33 | T20: =IFERROR(SUM(E20,J20,O20),"AB") -> 36 | U20: =IFERROR(SUM(F20,K20,P20),"AB") -> 18 | V20: =IFERROR(SUM(G20,L20,Q20),"AB") -> 7 | W20: =IFERROR(SUM(H20,M20,R20),"AB") -> 8 | X20: =IFERROR(SUM(S20:W20),"AB") -> 102
A21: 8 | B21: 22108 | C21: MD TABISH ANWAR | D21: ='CCE1'!D18+'CCE1'!E18 -> 19 | E21: ='CCE1'!E18+'CCE1'!F18 -> 20 | F21: ='CCE1'!F18+'CCE1'!G18 -> 10 | I21: ='CCE2'!D18+'CCE2'!E18 -> 10 | J21: ='CCE2'!F18+'CCE2'!G18 -> 8 | N21: ='CCE3'!D18 -> 7 | O21: ='CCE3'!E18 -> 8 | P21: ='CCE3'!F18 -> 9 | Q21: ='CCE3'!G18 -> 7 | R21: ='CCE3'!H18 -> 8 | S21: =IFERROR(SUM(D21,I21,N21),"AB") -> 36 | T21: =IFERROR(SUM(E21,J21,O21),"AB") -> 36 | U21: =IFERROR(SUM(F21,K21,P21),"AB") -> 19 | V21: =IFERROR(SUM(G21,L21,Q21),"AB") -> 7 | W21: =IFERROR(SUM(H21,M21,R21),"AB") -> 8 | X21: =IFERROR(SUM(S21:W21),"AB") -> 106
A22: 9 | B22: 22109 | C22: PUND SUYOG BHARAT | D22: ='CCE1'!D19+'CCE1'!E19 -> 20 | E22: ='CCE1'!E19+'CCE1'!F19 -> 20 | F22: ='CCE1'!F19+'CCE1'!G19 -> 10 | I22: ='CCE2'!D19+'CCE2'!E19 -> 10 | J22: ='CCE2'!F19+'CCE2'!G19 -> 7 | N22: ='CCE3'!D19 -> 9 | O22: ='CCE3'!E19 -> 8 | P22: ='CCE3'!F19 -> 9 | Q22: ='CCE3'!G19 -> 8 | R22: ='CCE3'!H19 -> 7 | S22: =IFERROR(SUM(D22,I22,N22),"AB") -> 39 | T22: =IFERROR(SUM(E22,J22,O22),"AB") -> 35 | U22: =IFERROR(SUM(F22,K22,P22),"AB") -> 19 | V22: =IFERROR(SUM(G22,L22,Q22),"AB") -> 8 | W22: =IFERROR(SUM(H22,M22,R22),"AB") -> 7 | X22: =IFERROR(SUM(S22:W22),"AB") -> 108
A23: 10 | B23: 22110 | C23: JAGTAP DNYANESHWAR RAGHUNATH | D23: ='CCE1'!D20+'CCE1'!E20 -> 16 | E23: ='CCE1'!E20+'CCE1'!F20 -> 18 | F23: ='CCE1'!F20+'CCE1'!G20 -> 10 | I23: ='CCE2'!D20+'CCE2'!E20 -> 10 | J23: ='CCE2'!F20+'CCE2'!G20 -> 10 | N23: ='CCE3'!D20 -> 8 | O23: ='CCE3'!E20 -> 8 | P23: ='CCE3'!F20 -> 7 | Q23: ='CCE3'!G20 -> 9 | R23: ='CCE3'!H20 -> 9 | S23: =IFERROR(SUM(D23,I23,N23),"AB") -> 34 | T23: =IFERROR(SUM(E23,J23,O23),"AB") -> 36 | U23: =IFERROR(SUM(F23,K23,P23),"AB") -> 17 | V23: =IFERROR(SUM(G23,L23,Q23),"AB") -> 9 | W23: =IFERROR(SUM(H23,M23,R23),"AB") -> 9 | X23: =IFERROR(SUM(S23:W23),"AB") -> 105
A24: 11 | B24: 22111 | C24: MAHAJAN PRATHAMESH JAGDISH | D24: ='CCE1'!D21+'CCE1'!E21 -> 20 | E24: ='CCE1'!E21+'CCE1'!F21 -> 19 | F24: ='CCE1'!F21+'CCE1'!G21 -> 9 | I24: ='CCE2'!D21+'CCE2'!E21 -> 7 | J24: ='CCE2'!F21+'CCE2'!G21 -> 7 | N24: ='CCE3'!D21 -> 10 | O24: ='CCE3'!E21 -> 9 | P24: ='CCE3'!F21 -> 9 | Q24: ='CCE3'!G21 -> 10 | R24: ='CCE3'!H21 -> 7 | S24: =IFERROR(SUM(D24,I24,N24),"AB") -> 37 | T24: =IFERROR(SUM(E24,J24,O24),"AB") -> 35 | U24: =IFERROR(SUM(F24,K24,P24),"AB") -> 18 | V24: =IFERROR(SUM(G24,L24,Q24),"AB") -> 10 | W24: =IFERROR(SUM(H24,M24,R24),"AB") -> 7 | X24: =IFERROR(SUM(S24:W24),"AB") -> 107
A25: 12 | B25: 22112 | C25: PATHAN ALIZABEE AKHTAR KHAN | D25: ='CCE1'!D22+'CCE1'!E22 -> 18 | E25: ='CCE1'!E22+'CCE1'!F22 -> 18 | F25: ='CCE1'!F22+'CCE1'!G22 -> 9 | I25: ='CCE2'!D22+'CCE2'!E22 -> 6 | J25: ='CCE2'!F22+'CCE2'!G22 -> 7 | N25: ='CCE3'!D22 -> 9 | O25: ='CCE3'!E22 -> 8 | P25: ='CCE3'!F22 -> 8 | Q25: ='CCE3'!G22 -> 9 | R25: ='CCE3'!H22 -> 9 | S25: =IFERROR(SUM(D25,I25,N25),"AB") -> 33 | T25: =IFERROR(SUM(E25,J25,O25),"AB") -> 33 | U25: =IFERROR(SUM(F25,K25,P25),"AB") -> 17 | V25: =IFERROR(SUM(G25,L25,Q25),"AB") -> 9 | W25: =IFERROR(SUM(H25,M25,R25),"AB") -> 9 | X25: =IFERROR(SUM(S25:W25),"AB") -> 101
... A121: 108 | B121: 22240 | C121: KISHOR LAXMAN HAKE | D121: ='CCE1'!D118+'CCE1'!E118 -> 18 | E121: ='CCE1'!E118+'CCE1'!F118 -> 17 | F121: ='CCE1'!F118+'CCE1'!G118 -> 9 | I121: ='CCE2'!D118+'CCE2'!E118 -> 5 | J121: ='CCE2'!F118+'CCE2'!G118 -> 5 | N121: ='CCE3'!D118 -> 8 | O121: ='CCE3'!E118 -> 9 | P121: ='CCE3'!F118 -> 10 | Q121: ='CCE3'!G118 -> 8 | R121: ='CCE3'!H118 -> 9 | S121: =IFERROR(SUM(D121,I121,N121),"AB") -> 31 | T121: =IFERROR(SUM(E121,J121,O121),"AB") -> 31 | U121: =IFERROR(SUM(F121,K121,P121),"AB") -> 19 | V121: =IFERROR(SUM(G121,L121,Q121),"AB") -> 8 | W121: =IFERROR(SUM(H121,M121,R121),"AB") -> 9 | X121: =IFERROR(SUM(S121:W121),"AB") -> 98
C122: =CONCATENATE("No of students more than ",S6* 100, "% = (x)") -> No of students more than 60% = (x) | D122: =COUNTIF(D14:D121,CONCATENATE(">=",$D$13*$S$6)) -> 106 | E122: =COUNTIF(E14:E121,CONCATENATE(">=",$E$13*$S$6)) -> 108 | F122: =COUNTIF(F14:F121,CONCATENATE(">=",$F$13*$S$6)) -> 108 | G122: =COUNTIF(G14:G121,CONCATENATE(">=",$D$13*$S$6)) -> 0 | H122: =COUNTIF(H14:H121,CONCATENATE(">=",$D$13*$S$6)) -> 0 | I122: =COUNTIF(I14:I121,CONCATENATE(">=",$I$13*$S$6)) -> 104 | J122: =COUNTIF(J14:J121,CONCATENATE(">=",$J$13*$S$6)) -> 104 | K122: =COUNTIF(K14:K121,CONCATENATE(">=",$D$13*$S$6)) -> 0 | L122: =COUNTIF(L14:L121,CONCATENATE(">=",$D$13*$S$6)) -> 0 | M122: =COUNTIF(M14:M121,CONCATENATE(">=",$D$13*$S$6)) -> 0 | N122: =COUNTIF(N14:N121,CONCATENATE(">=",$N$13*$S$6)) -> 105 | O122: =COUNTIF(O14:O121,CONCATENATE(">=",$O$13*$S$6)) -> 102 | P122: =COUNTIF(P14:P121,CONCATENATE(">=",$P$13*$S$6)) -> 105 | Q122: =COUNTIF(Q14:Q121,CONCATENATE(">=",$Q$13*$S$6)) -> 100 | R122: =COUNTIF(R14:R121,CONCATENATE(">=",$R$13*$S$6)) -> 97 | S122: =COUNTIF(S14:S121,CONCATENATE(">=",$S$13*$S$6)) -> 107 | T122: =COUNTIF(T14:T121,CONCATENATE(">=",$T$13*$S$6)) -> 108 | U122: =COUNTIF(U14:U121,CONCATENATE(">=",$U$13*$S$6)) -> 108 | V122: =COUNTIF(V14:V121,CONCATENATE(">=",$V$13*$S$6)) -> 100 | W122: =COUNTIF(W14:W121,CONCATENATE(">=",$W$13*$S$6)) -> 97 | X122: =COUNTIF(X14:X121,CONCATENATE(">=",$X$13*$S$6)) -> 108
C123: No of Students (y) | D123: =COUNT(D14:D121) -> 108 | E123: =COUNT(E14:E121) -> 108 | F123: =COUNT(F14:F121) -> 108 | G123: =COUNT(G14:G121) -> 0 | H123: =COUNT(H14:H121) -> 0 | I123: =COUNT(I14:I121) -> 108 | J123: =COUNT(J14:J121) -> 108 | K123: =COUNT(K14:K121) -> 0 | ... X123: =COUNT(X14:X121) -> 108
C124: CO Attainment Percentage | D124: =IFERROR(D122/D123,"NA")*100 -> 98.148148 | E124: =IFERROR(E122/E123,"NA")*100 -> 100 | F124: =IFERROR(F122/F123,"NA")*100 -> 100 | G124: NA | H124: NA | I124: =IFERROR(I122/I123,"NA")*100 -> 96.296296 | J124: =IFERROR(J122/J123,"NA")*100 -> 96.296296 | K124: NA | L124: NA | M124: NA | N124: =IFERROR(N122/N123,"NA")*100 -> 97.222222 | O124: =IFERROR(O122/O123,"NA")*100 -> 94.444444 | P124: =IFERROR(P122/P123,"NA")*100 -> 97.222222 | Q124: =IFERROR(Q122/Q123,"NA")*100 -> 92.592593 | R124: =IFERROR(R122/R123,"NA")*100 -> 89.814815 | S124: =IFERROR(S122/S123,"NA")*100 -> 99.074074 | T124: =IFERROR(T122/T123,"NA")*100 -> 100 | U124: =IFERROR(U122/U123,"NA")*100 -> 100 | ... X124: =IFERROR(X122/X123,"NA")*100 -> 100
C125: CO Attainment Level | D125: =IF(D124<>"NA",IF(D124>=$N6,$L6,IF(D124>=$N7,$L7,IF(D124>=$N8,$L8,"0"))),"NA") -> 3 | E125: =IF(E124<>"NA",IF(E124>=$N6,$L6,IF(E124>=$N7,$L7,IF(E124>=$N8,$L8,"0"))),"NA") -> 3 | F125: =IF(F124<>"NA",IF(F124>=$N6,$L6,IF(F124>=$N7,$L7,IF(F124>=$N8,$L8,"0"))),"NA") -> 3 | G125: =IF(G124<>"NA",IF(G124>=$N6,$L6,IF(G124>=$N7,$L7,IF(G124>=$N8,$L8,"0"))),"NA") -> NA | H125: =IF(H124<>"NA",IF(H124>=$N6,$L6,IF(H124>=$N7,$L7,IF(H124>=$N8,$L8,"0"))),"NA") -> NA | I125: =IF(I124<>"NA",IF(I124>=$N6,$L6,IF(I124>=$N7,$L7,IF(I124>=$N8,$L8,"0"))),"NA") -> 3 | J125: =IF(J124<>"NA",IF(J124>=$N6,$L6,IF(J124>=$N7,$L7,IF(J124>=$N8,$L8,"0"))),"NA") -> 3 | K125: =IF(K124<>"NA",IF(K124>=$N6,$L6,IF(K124>=$N7,$L7,IF(K124>=$N8,$L8,"0"))),"NA") -> NA | ... X125: =IF(X124<>"NA",IF(X124>=$N6,$L6,IF(X124>=$N7,$L7,IF(X124>=$N8,$L8,"0"))),"NA") -> 3
C127: Attainment based on Comprehensive Concurrent Evaluation (CCE) = Avg. of all COs | D127: =AVERAGE(S125:W125) -> 3 | E127: =AVERAGE(D124:X124) -> 96.469907 | F127: =(3/100)*E127 -> 2.8940972 | G127: Average
G128: CO1 | H128: =AVERAGE(D124,I124,N124) -> 97.222222
G129: CO2 | H129: =AVERAGE(E124,J124,O124) -> 96.91358
G130: CO3 | H130: =AVERAGE(F124,P124) -> 98.611111
G131: CO4 | H131: =AVERAGE(G124,Q124) -> 92.592593
B132: =Faculty -> Dr. Ashwini Chavan, | G132: CO5 | H132: =AVERAGE(R124) -> 89.814815
A138: =SubjectDetails!A24 -> Dr. Ravi Chourasiya | D138: =SubjectDetails!E24 -> Dr. Ashwini Chavan | N138: =SubjectDetails!H24 -> Dr. Priyanka Singh
A139: =SubjectDetails!A25 -> (College Examination Officer) | D139: =SubjectDetails!E25 -> HOD (MCA) | N139: =SubjectDetails!H25 -> Director

Sheet CO Ext. Attn
A1: Dr. D.Y. Patil Educational Federation's
A2: Dr. D. Y. Patil Institute of Management and Entreprenuer Development, Varale, Pune
A3: (Permanently affiliated to Savitribai Phule Pune University, Accredited by NAAC 'A'
A4: Approved by AICTE, Recognized under 2 (f) & 12 (b) sections of UGC Act)
A6: =CONCATENATE("Faculty Name: ", Faculty) -> Faculty Name: Dr. Ashwini Chavan, | D6: Benchmark | F6: 3 | G6: 0.7 | H6: Percentage of Students to get | J6: 0.6
A7: =CONCATENATE("Subject Name & Code: ", Sub_Code) -> Subject Name & Code: Network Technologies | F7: 2 | G7: 0.6
A8: =CONCATENATE("Class: ",Class_AY) -> Class: MCA I SEM I AY 2023-24 | F8: 1 | G8: 0.5
A10: Course Outcome Attainment Calculations - External Assessment (SPPU)
A11: Roll No. | B11: Seat No. | C11: Name of the Student | D11: Equal Weightage to all COs
D13: 50
A14: 1 | B14: 2032303524 | C14: JAGTAP VAISHNAVI VILAS | D14: 32
A15: 2 | B15: 2032303491 | C15: MANE SHARVI MAHENDRA | D15: 32
A16: 3 | B16: 2032303500 | C16: SAYYAD TARNUM ISMAIL | D16: 32
A17: 4 | B17: 2032303484 | C17: SALUNKHE SANIYA SANTOSH | D17: 32
A18: 5 | B18: 2032303481 | C18: AKHARE PRATIK RAJENDRA | D18: 35
A19: 6 | B19: 2032303483 | C19: VEDANT NILKANTH THATE | D19: 32
A20: 7 | B20: 2032303463 | C20: CHANNE VIJAY SAKHARAM | D20: 32
A21: 8 | B21: 2032303487 | C21: PRAJWAL KISHOR SATPUTE | D21: 35
A22: 9 | B22: 2032303455 | C22: SHIRSAT MEGHA SHARAD | D22: 31
A23: 10 | B23: 2032303516 | C23: PRATIKSHA VISHWASRAO JAWARE | D23: 32
A24: 11 | B24: 2032303515 | C24: KOLTE PRAJAKTA ANIL | D24: 32
A25: 12 | B25: 2032303502 | C25: JAGTAP PRATHAMESH BHAUSAHEB | D25: 22
... A121: 108 | B121: 2032303555 | C121: JISHAN VAHED SHAIKH | D121: 7
C122: =CONCATENATE("No of students more than ", J6*100, "% = (x)") -> No of students more than 60% = (x) | D122: =COUNTIF(D14:D121,CONCATENATE(">=",D$13*$J$6)) -> 61
C123: No of Students (y) | D123: 108
C124: CO Attainment Percentage | D124: =IFERROR(D122/D123,0) -> 0.56481481
C125: CO Attainment Level | D125: =IF(D124>=$G6,$F6,IF(D124>=$G7,$F7,IF(D124>=$G8,$F8,"0"))) -> 1
C127: Attainment based on External Evaluation = Avg. of all COs | D127: =IFERROR(AVERAGE(D121:I125),0) -> 35.512963
B132: =Faculty -> Dr. Ashwini Chavan,
A137: =SubjectDetails!A24 -> Dr. Ravi Chourasiya | D137: =SubjectDetails!E24 -> Dr. Ashwini Chavan | I137: =SubjectDetails!H24 -> Dr. Priyanka Singh
A138: =SubjectDetails!A25 -> (College Examination Officer) | D138: =SubjectDetails!E25 -> HOD (MCA) | I138: =SubjectDetails!H25 -> Director

Sheet OverallCO Attainment
A1: Dr. D.Y. Patil Educational Federation's
A2: Dr. D. Y. Patil Institute of Management and Entreprenuer Development, Varale, Pune
A3: (Permanently affiliated to Savitribai Phule Pune University, Accredited by NAAC 'A'
A4: Approved by AICTE, Recognized under 2 (f) & 12 (b) sections of UGC Act)
B5: =CONCATENATE("Faculty Name: ", Faculty) -> Faculty Name: Dr. Ashwini Chavan,
B6: =CONCATENATE("Subject Name & Code: ", Sub_Code) -> Subject Name & Code: Network Technologies
B7: =CONCATENATE("Class: ",Class_AY) -> Class: MCA I SEM I AY 2023-24
B9: OVERALL CO ATTAINMENT FOR COURSE
B10: Particulars | C10: CO1 | D10: CO2 | E10: CO3 | F10: CO4 | G10: CO5
B11: CO ATTAINMENT PERCENTAGE - INTERNAL ASSESSMENT (A1) | C11: ='CO Int. Attn'!H128 -> 97.222222 | D11: ='CO Int. Attn'!H129 -> 96.91358 | E11: ='CO Int. Attn'!H130 -> 98.611111 | F11: ='CO Int. Attn'!H131 -> 92.592593 | G11: ='CO Int. Attn'!H132 -> 89.814815
B12: CO ATTAINMENT PERCENTAGE - EXTERNAL ASSESSMENT (SPPU) (A2) | C12: ='CO Ext. Attn'!$D124*100 -> 56.481481 | D12: ='CO Ext. Attn'!$D124*100 -> 56.481481 | E12: ='CO Ext. Attn'!$D124*100 -> 56.481481 | F12: ='CO Ext. Attn'!$D124*100 -> 56.481481 | G12: ='CO Ext. Attn'!$D124*100 -> 56.481481
B13: CO ATTAINMENT PERCENTAGE - DIRECT ASSESSMENT Direct Attainment=(Int. Weightage X A1) + ( Ext. Weightage X A2) | C13: =(int_wt*C11)+(ext_wt*C12) -> 69.925926 | D13: =(int_wt*D11)+(ext_wt*D12) -> 69.824074 | E13: =(int_wt*E11)+(ext_wt*E12) -> 70.384259 | F13: =(int_wt*F11)+(ext_wt*F12) -> 68.398148 | G13: =(int_wt*G11)+(ext_wt*G12) -> 67.481481
B14: CO ATTAINMENT PERCENTAGE - INDIRECT (SURVEY) | C14: =Sheet1!D119 -> 84.259259 | D14: =Sheet1!E119 -> 82.407407 | E14: =Sheet1!F119 -> 84.814815 | F14: =Sheet1!G119 -> 85.925926 | G14: =Sheet1!H119 -> 84.62963
B15: OVERALL CO ATTAINMENT FOR COURSE | C15: =(0.8*C13)+(0.2*C14) -> 72.792593 | D15: =(0.8*D13)+(0.2*D14) -> 72.340741 | E15: =(0.8*E13)+(0.2*E14) -> 73.27037 | F15: =(0.8*F13)+(0.2*F14) -> 71.903704 | G15: =(0.8*G13)+(0.2*G14) -> 70.911111
B16: CO ATTAINMENT LEVEL | C16: =IF(C15>=$E20,3,IF(C15>=$E21,2,IF(C15>=$E22,1,0))) -> 3 | D16: =IF(D15>=$E20,3,IF(D15>=$E21,2,IF(D15>=$E22,1,0))) -> 3 | E16: =IF(E15>=$E20,3,IF(E15>=$E21,2,IF(E15>=$E22,1,0))) -> 3 | F16: =IF(F15>=$E20,3,IF(F15>=$E21,2,IF(F15>=$E22,1,0))) -> 3 | G16: =IF(G15>=$E20,3,IF(G15>=$E21,2,IF(G15>=$E22,1,0))) -> 3
B18: Percentage of Students to get 60% of Marks
B20: Benchmark | D20: 3 | E20: 70
D21: 2 | E21: 60
D22: 1 | E22: 50
B27: =Faculty -> Dr. Ashwini Chavan,
B28: =SubjectDetails!$E$17 -> Subject Faculty
A33: =SubjectDetails!$A$24 -> Dr. Ravi Chourasiya | D33: =SubjectDetails!$E$24 -> Dr. Ashwini Chavan | H33: =SubjectDetails!$H$24 -> Dr. Priyanka Singh
A34: =SubjectDetails!$A$25 -> (College Examination Officer) | D34: =SubjectDetails!$E$25 -> HOD (MCA) | H34: =SubjectDetails!$H$25 -> Director

Sheet CO PO Attainment
B1: Dr. D.Y. Patil Educational Federation's
B2: Dr. D. Y. Patil Institute of Management and Entreprenuer Development, Varale, Pune
B3: (Permanently affiliated to Savitribai Phule Pune University, Accredited by NAAC 'A'
B4: Approved by AICTE, Recognized under 2 (f) & 12 (b) sections of UGC Act)
B6: =CONCATENATE("Faculty Name: ", Faculty) -> Faculty Name: Dr. Ashwini Chavan,
B7: =CONCATENATE("Subject Name & Code: ", Sub_Code) -> Subject Name & Code: Network Technologies
B8: =CONCATENATE("Class: ",Class_AY) -> Class: MCA I SEM I AY 2023-24
B9: CO-PO Attainment Calculations
B10: Overall CO Attainment % | D10: PO1 | E10: PO2 | F10: PO3 | G10: PO4 | H10: PO5 | I10: PO6 | J10: PO7 | K10: PO8
B11: Average Mapping (M) | D11: ='CO Mapping PO '!B18 -> 2.4 | E11: ='CO Mapping PO '!C18 -> 1 | F11: ='CO Mapping PO '!D18 -> 1.6666667 | G11: ='CO Mapping PO '!E18 -> 2 | H11: ='CO Mapping PO '!F18 -> #DIV/0! | I11: ='CO Mapping PO '!G18 -> #DIV/0! | J11: ='CO Mapping PO '!H18 -> 2 | K11: ='CO Mapping PO '!I18 -> 1.2
B12: CO1 | C12: ='OverallCO Attainment'!C15 -> 72.792593 | D12: 2 | E12: 1 | F12: 0 | G12: 0 | H12: 0 | I12: 0 | J12: 0 | K12: 1
B13: CO2 | C13: ='OverallCO Attainment'!D15 -> 72.340741 | D13: 3 | E13: 1 | F13: 1 | G13: 0 | H13: 0 | I13: 0 | J13: 0 | K13: 1
B14: CO3 | C14: ='OverallCO Attainment'!E15 -> 73.27037 | D14: 3 | E14: 0 | F14: 0 | G14: 0 | H14: 0 | I14: 0 | J14: 0 | K14: 1
B15: CO4 | C15: ='OverallCO Attainment'!F15 -> 71.903704 | D15: 2 | E15: 0 | F15: 1 | G15: 0 | H15: 0 | I15: 0 | J15: 2 | K15: 1
B16: CO5 | C16: ='OverallCO Attainment'!G15 -> 70.911111 | D16: 2 | E16: 0 | F16: 3 | G16: 2 | H16: 0 | I16: 0 | J16: 0 | K16: 2
C17: Perecentage | D17: =(C12*D12+C13*D13+C14*D14+C15*D15+C16*D16)/(D12+D13+D14+D15+D16) -> 72.337346 | E17: =(C12*E12+C13*E13+C14*E14+C15*E15+C16*E16)/(E12+E13+E14+E15+E16) -> 72.566667 | F17: =(C12*F12+C13*F13+C14*F14+C15*F15+C16*F16)/(F12+F13+F14+F15+F16) -> 71.395556 | G17: =(C12*G12+C13*G13+C14*G14+C15*G15+C16*G16)/(G12+G13+G14+G15+G16) -> 70.911111 | H17: =(C12*H12+C13*H13+C14*H14+C15*H15+C16*H16)/(H12+H13+H14+H15+H16) -> #DIV/0! | I17: =(C12*I12+C13*I13+C14*I14+C15*I15+C16*I16)/(I12+I13+I14+I15+I16) -> #DIV/0! | J17: =(C12*J12+C13*J13+C14*J14+C15*J15+C16*J16)/(J12+J13+J14+J15+J16) -> 71.903704 | K17: =(C12*K12+C13*K13+C14*K14+C15*K15+C16*K16)/(K12+K13+K14+K15+K16) -> 72.021605
C18: Level | D18: =D17/100*3 -> 2.1701204 | E18: =E17/100*3 -> 2.177 | F18: =F17/100*3 -> 2.1418667 | G18: =G17/100*3 -> 2.1273333 | H18: =H17/100*3 -> #DIV/0! | I18: =I17/100*3 -> #DIV/0! | J18: =J17/100*3 -> 2.1571111 | K18: =K17/100*3 -> 2.1606481
B24: =Faculty -> Dr. Ashwini Chavan,
B25: =Designation -> Assistant Professor
B31: =SubjectDetails!$A$24 -> Dr. Ravi Chourasiya | E31: =SubjectDetails!$E$24 -> Dr. Ashwini Chavan | I31: =SubjectDetails!$H$24 -> Dr. Priyanka Singh
B32: =SubjectDetails!$A$25 -> (College Examination Officer) | E32: =SubjectDetails!$E$25 -> HOD (MCA) | I32: =SubjectDetails!$H$25 -> Director

Sheet Sheet1
A1: Dr. D.Y. Patil Educational Federation's
A2: Dr. D. Y. Patil Institute of Management and Entreprenuer Development, Varale, Pune
A3: (Permanently affiliated to Savitribai Phule Pune University, Accredited by NAAC 'A'
A4: Approved by AICTE, Recognized under 2 (f) & 12 (b) sections of UGC Act)
A5: Indirect Attainment
A6: =CONCATENATE(Class," ", spl) -> MCA I SEM I AY 2023-24 | D6: Course Exit Survey
A7: Roll No. | B7: Seat No. | C7: Name of the Student | L7: Total Marks Obtained
D8: CO1 | E8: CO2 | F8: CO3 | G8: CO4 | H8: CO5
D9: 5 | E9: 5 | F9: 5 | G9: 5 | H9: 5 | L9: =SUM(D9:K9) -> 25
A10: 1 | B10: 221-1 | C10: NAIK ANKIT JIVAN | D10: 4 | E10: 4 | F10: 2 | G10: 5 | H10: 5 | L10: =IF(F10<>"AB",SUM(D10:K10),"AB") -> 20
A11: 2 | B11: 22102 | C11: ARGADE RAVISHANKAR UTTAM | D11: 4 | E11: 4 | F11: 4 | G11: 4 | H11: 4 | L11: =IF(F11<>"AB",SUM(D11:K11),"AB") -> 20
A12: 3 | B12: 22103 | C12: ANERAO ONKAR RANGNATH | D12: 4 | E12: 5 | F12: 4 | G12: 5 | H12: 5 | L12: =IF(F12<>"AB",SUM(D12:K12),"AB") -> 23
A13: 4 | B13: 22104 | C13: MORE KIRAN SUNIL | D13: 5 | E13: 5 | F13: 4 | G13: 5 | H13: 4 | L13: =IF(F13<>"AB",SUM(D13:K13),"AB") -> 23
A14: 5 | B14: 22105 | C14: KSHIRSAGAR GAURAV SHRIKANT | D14: 4 | E14: 4 | F14: 5 | G14: 5 | H14: 4 | L14: =IF(F14<>"AB",SUM(D14:K14),"AB") -> 22
A15: 6 | B15: 22106 | C15: SHIRSAT MEGHA SHARAD | D15: 5 | E15: 4 | F15: 5 | G15: 4 | H15: 5 | L15: =IF(F15<>"AB",SUM(D15:K15),"AB") -> 23
A16: 7 | B16: 22107 | C16: INGALE RAHUL SUNIL | D16: 5 | E16: 5 | F16: 5 | G16: 5 | H16: 5 | L16: =IF(F16<>"AB",SUM(D16:K16),"AB") -> 25
A17: 8 | B17: 22108 | C17: MD TABISH ANWAR | D17: 5 | E17: 4 | F17: 5 | G17: 5 | H17: 4 | L17: =IF(F17<>"AB",SUM(D17:K17),"AB") -> 23
A18: 9 | B18: 22109 | C18: PUND SUYOG BHARAT | D18: 4 | E18: 4 | F18: 4 | G18: 5 | H18: 5 | L18: =IF(F18<>"AB",SUM(D18:K18),"AB") -> 22
A19: 10 | B19: 22110 | C19: JAGTAP DNYANESHWAR RAGHUNATH | D19: 5 | E19: 4 | F19: 4 | G19: 4 | H19: 5 | L19: =IF(F19<>"AB",SUM(D19:K19),"AB") -> 22
A20: 11 | B20: 22111 | C20: MAHAJAN PRATHAMESH JAGDISH | D20: 4 | E20: 4 | F20: 5 | G20: 4 | H20: 4 | L20: =IF(F20<>"AB",SUM(D20:K20),"AB") -> 21
A21: 12 | B21: 22112 | C21: PATHAN ALIZABEE AKHTAR KHAN | D21: 2 | E21: 4 | F21: 4 | G21: 4 | H21: 5 | L21: =IF(F21<>"AB",SUM(D21:K21),"AB") -> 19
A22: 13 | B22: 22113 | C22: MUNDLOD PRUTHVI BALAJI | D22: 4 | E22: 5 | F22: 4 | G22: 5 | H22: 5 | L22: =IF(F22<>"AB",SUM(D22:K22),"AB") -> 23
... A117: 108 | B117: 22240 | C117: KISHOR LAXMAN HAKE | D117: 5 | E117: 3 | F117: 4 | G117: 3 | H117: 3 | L117: =IF(F117<>"AB",SUM(D117:K117),"AB") -> 18
C118: Average | D118: =AVERAGE(D10:D117) -> 4.212963 | E118: =AVERAGE(E10:E117) -> 4.1203704 | F118: =AVERAGE(F10:F117) -> 4.2407407 | G118: =AVERAGE(G10:G117) -> 4.2962963 | H118: =AVERAGE(H10:H117) -> 4.2314815 | L118: =AVERAGE(L10:L117) -> 21.101852
C119: Attainment | D119: =D118/5*100 -> 84.259259 | E119: =E118/5*100 -> 82.407407 | F119: =F118/5*100 -> 84.814815 | G119: =G118/5*100 -> 85.925926 | H119: =H118/5*100 -> 84.62963 | L119: =L118/25*100 -> 84.407407
M120: Overall Semester wise Attainment
A121: Total No. of Students: | C121: =COUNT(A10:A117) -> 108
B127: =[1]SubjectDetails!$A$24 -> Dr. Ravi Chourasiya | D127: =[1]SubjectDetails!$E$24 -> Dr. Ashwini Chavan | J127: =[1]SubjectDetails!$H$24 -> Dr. Priyanka Singh
B128: =[1]SubjectDetails!$A$25 -> (College Examination Officer) | D128: =[1]SubjectDetails!$E$25 -> HOD (MCA) | I128: =[1]SubjectDetails!$H$25 -> Director
