Workbook
Name Class: SubjectDetails!$B$10
Name Class_AY: SubjectDetails!$B$10
Name Designation: SubjectDetails!$B$7
Name dir_wt: SubjectDetails!$B$17
Name ext_wt: SubjectDetails!$B$15
Name Faculty: SubjectDetails!$B$6
Name ind_wt: SubjectDetails!$B$18
Name int_wt: SubjectDetails!$B$14
Name spl: SubjectDetails!$B$11
Name Sub_Code: SubjectDetails!$B$8
Name Target: 60%
Name Type: SubjectDetails!$B$9

Sheet SubjectDetails
A1: Dr. D.Y. Patil Educational Federation's
A2: Dr. D. Y. Patil Institute of Management and Entreprenuer Development, Varale, Pune
A3: (Permanently affiliated to Savitribai Phule Pune University, Accredited by NAAC 'A'
A4: Approved by AICTE, Recognized under 2 (f) & 12 (b) sections of UGC Act)
A6: Name of the faculty: | B6: Narsareaddy Chude
A7: Designation: | B7: Assistant Professor
A8: Subject & Code: | B8: Mini Project
A9: Type of Course: | B9: Subject Core
A10: Class & A.Y.: | B10: MCA I SEM I AY 2023-24
A11: Specialization:
B13: % | C13: Marks
A14: Internal Assessment Weightage | B14: 0.6 | C14: 75
A15: External Assessment Weightage | B15: 0.4 | C15: 50
E16: =Faculty -> Narsareaddy Chude
A17: Direct Assessment Weightage | B17: 0.8 | E17: Subject Faculty
A18: Indirect Assessment Weightage | B18: 0.2
A24: Dr. Ravi Chourasiya | E24: Dr. Ashwini Chavan | H24: Dr. Priyanka Singh
A25: (College Examination Officer) | E25: HOD (MCA) | H25: Director

Sheet Rubrics
A1: Dr. D.Y. Patil Educational Federation's
A2: Dr. D. Y. Patil Institute of Management and Entreprenuer Development, Varale, Pune
A3: (Permanently affiliated to Savitribai Phule Pune University, Accredited by NAAC 'A'
A4: Approved by AICTE, Recognized under 2 (f) & 12 (b) sections of UGC Act)
A5: =CONCATENATE("Faculty Name: ", Faculty) -> Faculty Name: Narsareaddy Chude
A6: =CONCATENATE("Subject Name & Code: ", Sub_Code) -> Subject Name & Code: Mini Project
A7: =CONCATENATE("Class: ",Class_AY) -> Class: MCA I SEM I AY 2023-24
A9: Rubrics
A10: Criteria | C10: Excellent (100%) | F10: Good (80%) | I10: Satisfactory (60%) | L10: Needs Improvement (<60%)
A11: Understanding of Concepts
A12: Application of Tools
A13: Interpretation & Decision-Making
A14: Structure & Clarity
A15: References & Format
A18: =Faculty -> Narsareaddy Chude
A19: Subject Faculty
A24: =SubjectDetails!$A$24 -> Dr. Ravi Chourasiya | E24: =SubjectDetails!$E$24 -> Dr. Ashwini Chavan | I24: =SubjectDetails!$H$24 -> Dr. Priyanka Singh
A25: =SubjectDetails!$A$25 -> (College Examination Officer) | E25: =SubjectDetails!$E$25 -> HOD (MCA) | I25: =SubjectDetails!$H$25 -> Director

Sheet CO Mapping PO 
A1: Dr. D.Y. Patil Educational Federation's
A2: Dr. D. Y. Patil Institute of Management and Entreprenuer Development, Varale, Pune
A3: (Permanently affiliated to Savitribai Phule Pune University, Accredited by NAAC 'A'
A4: Approved by AICTE, Recognized under 2 (f) & 12 (b) sections of UGC Act)
A6: =CONCATENATE("Faculty Name: ", Faculty) -> Faculty Name: Narsareaddy Chude
A7: =CONCATENATE("Subject Name & Code: ", Sub_Code) -> Subject Name & Code: Mini Project
A8: =CONCATENATE("Class: ",Class_AY) -> Class: MCA I SEM I AY 2023-24
K9: Program OutComes
A10: COURSE OUTCOMES (CO) MAPPING WITH PROGRAM OUTCOMES (PO) | K10: PO1 (Foundation Knowledge): Apply knowledge of mathematics, programming logic and coding fundamentals for solution architecture and problem solving.
B11: PO1 | C11: PO2 | D11: PO3 | E11: PO4 | F11: PO5 | G11: PO6 | H11: PO7 | I11: PO8 | K11: PO2 (Problem Analysis): Identify, review, formulate and analyze problems for primarily focussing on customer requirements using critical thinking frameworks.
A12: CO1 | B12: 3 | C12: 3 | D12: 3 | E12: 3 | F12: 3 | G12: 3 | H12: 3 | I12: 3
A13: CO2 | K13: PO3 (Development of Solutions): Design, develop and investigate problems with as an innovative approach for solutions incorporating ESG/SDG goals.
A14: CO3
A15: CO4 | K15: PO4 (Modern Tool Usage): Select, adapt and apply modern computational tools such as development of algorithms with an understanding of the limitations including human biases.
A16: CO5
K17: PO5 (Individual and Teamwork): Function and communicate effectively as an individual or a team leader in diverse and multidisciplinary groups. Use methodologies such as agile.
A18: Average | B18: =AVERAGE(B12:B17) -> 3 | C18: =AVERAGE(C12:C17) -> 3 | D18: =AVERAGE(D12:D17) -> 3 | E18: =AVERAGE(E12:E17) -> 3 | F18: =AVERAGE(F12:F17) -> 3 | G18: =AVERAGE(G12:G17) -> 3 | H18: =AVERAGE(H12:H17) -> 3 | I18: =AVERAGE(I12:I17) -> 3
A19: 3-HIGH (corresponds to a high correlation) 2-MEDIUM (corresponds to a medium correlation) 1-LOW (corresponds to a low correlation) between CO and PO/PSO | K19: PO6 (Project Management and Finance): Use the principles of project management such as scheduling, work breakdown structure and be conversant with the principles of Finance for profitable project management.
K20: PO7 (Ethics): Commit to professional ethics in managing software projects with financial aspects. Learn to use new technologies for cyber security and insulate customers from malware
K22: PO8 (Life-long learning): Change management skills and the ability to learn, keep up with contemporary technologies and ways of working.
A24: =SubjectDetails!$E$16 -> Narsareaddy Chude | K24: Course OutComes
A25: =SubjectDetails!$E$17 -> Subject Faculty | K25: Create working project using tools and techniques learnt in this semester
A28: =SubjectDetails!$A$24 -> Dr. Ravi Chourasiya | E28: =SubjectDetails!$E$24 -> Dr. Ashwini Chavan | I28: =SubjectDetails!$H$24 -> Dr. Priyanka Singh
A29: =SubjectDetails!$A$25 -> (College Examination Officer) | E29: =SubjectDetails!$E$25 -> HOD (MCA) | I29: =SubjectDetails!$H$25 -> Director

Sheet CCE1
A1: Dr. D.Y. Patil Educational Federation's
A2: Dr. D. Y. Patil Institute of Management and Entreprenuer Development, Varale, Pune
A3: (Permanently affiliated to Savitribai Phule Pune University, Accredited by NAAC 'A'
A4: Approved by AICTE, Recognized under 2 (f) & 12 (b) sections of UGC Act)
A5: Comprehensive Concurrent Evaluation (CCE) Sheet
A6: =CONCATENATE(Class," ", spl) -> MCA I SEM I AY 2023-24 | C6: =CONCATENATE("Name of Faculty: ", Faculty) -> Name of Faculty: Narsareaddy Chude | D6: =CONCATENATE("Course Name: ", Sub_Code) -> Course Name: Mini Project
A7: Roll No. | B7: Seat No. | C7: Name of the Student | D7: CCE-I (End term ) | J7: Total Marks Obtained
D8: Q1
C9: Max Marks → | D9: 50 | J9: =SUM(D9:I9) -> 50
C10: CO Mapping → | D10: CO1
A11: 1 | B11: 2032303524 | C11: JAGTAP VAISHNAVI VILAS | D11: 47 | J11: =IF(F11<>"AB",SUM(D11:I11),"AB") -> 47
A12: 2 | B12: 2032303491 | C12: MANE SHARVI MAHENDRA | D12: 47 | J12: =IF(F12<>"AB",SUM(D12:I12),"AB") -> 47
A13: 3 | B13: 2032303500 | C13: SAYYAD TARNUM ISMAIL | D13: 46 | J13: =IF(F13<>"AB",SUM(D13:I13),"AB") -> 46
A14: 4 | B14: 2032303484 | C14: SALUNKHE SANIYA SANTOSH | D14: 49 | J14: =IF(F14<>"AB",SUM(D14:I14),"AB") -> 49
A15: 5 | B15: 2032303481 | C15: AKHARE PRATIK RAJENDRA | D15: 44 | J15: =IF(F15<>"AB",SUM(D15:I15),"AB") -> 44
A16: 6 | B16: 2032303483 | C16: VEDANT NILKANTH THATE | D16: 49 | J16: =IF(F16<>"AB",SUM(D16:I16),"AB") -> 49
A17: 7 | B17: 2032303463 | C17: CHANNE VIJAY SAKHARAM | D17: 50 | J17: =IF(F17<>"AB",SUM(D17:I17),"AB") -> 50
A18: 8 | B18: 2032303487 | C18: PRAJWAL KISHOR SATPUTE | D18: 48 | J18: =IF(F18<>"AB",SUM(D18:I18),"AB") -> 48
A19: 9 | B19: 2032303455 | C19: SHIRSAT MEGHA SHARAD | D19: 49 | J19: =IF(F19<>"AB",SUM(D19:I19),"AB") -> 49
A20: 10 | B20: 2032303516 | C20: PRATIKSHA VISHWASRAO JAWARE | D20: 47 | J20: =IF(F20<>"AB",SUM(D20:I20),"AB") -> 47
A21: 11 | B21: 2032303515 | C21: KOLTE PRAJAKTA ANIL | D21: 47 | J21: =IF(F21<>"AB",SUM(D21:I21),"AB") -> 47
A22: 12 | B22: 2032303502 | C22: JAGTAP PRATHAMESH BHAUSAHEB | D22: 47 | J22: =IF(F22<>"AB",SUM(D22:I22),"AB") -> 47
... A118: 108 | B118: 2032303555 | C118: JISHAN VAHED SHAIKH | D118: 41 | J118: =IF(F118<>"AB",SUM(D118:I118),"AB") -> 41
A119: Total | C119: =COUNT(A11:A118) -> 108
A123: =Faculty -> Narsareaddy Chude
A124: =SubjectDetails!E17 -> Subject Faculty
A127: =SubjectDetails!A24 -> Dr. Ravi Chourasiya | D127: =SubjectDetails!E24 -> Dr. Ashwini Chavan | I127: =SubjectDetails!H24 -> Dr. Priyanka Singh
A128: =SubjectDetails!A25 -> (College Examination Officer) | D128: =SubjectDetails!E25 -> HOD (MCA) | I128: =SubjectDetails!H25 -> Director

Sheet CCE2
A1: Dr. D.Y. Patil Educational Federation's
A2: Dr. D. Y. Patil Institute of Management and Entreprenuer Development, Varale, Pune
A3: (Permanently affiliated to Savitribai Phule Pune University, Accredited by NAAC 'A'
A4: Approved by AICTE, Recognized under 2 (f) & 12 (b) sections of UGC Act)
A5: Comprehensive Concurrent Evaluation (CCE) Sheet
A6: =CONCATENATE(Class," ", spl) -> MCA I SEM I AY 2023-24 | C6: =CONCATENATE("Name of Faculty: ", Faculty) -> Name of Faculty: Narsareaddy Chude | D6: =CONCATENATE("Course Name: ", Sub_Code) -> Course Name: Mini Project
A7: Roll No. | B7: Seat No. | C7: Name of the Student | D7: CCE-II (Presentation) | L7: Total Marks Obtained
D8: Q1
C9: Max Marks → | D9: 25 | L9: =D9+E9+F9+G9+H9+I9+J9+K9 -> 25
C10: CO Mapping → | D10: CO1
A11: 1 | B11: 2032303524 | C11: JAGTAP VAISHNAVI VILAS | D11: 22 | L11: =IF(E11<>"AB",SUM(D11:K11),"AB") -> 22
A12: 2 | B12: 2032303491 | C12: MANE SHARVI MAHENDRA | D12: 23 | L12: =IF(E12<>"AB",SUM(D12:K12),"AB") -> 23
A13: 3 | B13: 2032303500 | C13: SAYYAD TARNUM ISMAIL | D13: 23 | L13: =IF(E13<>"AB",SUM(D13:K13),"AB") -> 23
A14: 4 | B14: 2032303484 | C14: SALUNKHE SANIYA SANTOSH | D14: 21 | L14: =IF(E14<>"AB",SUM(D14:K14),"AB") -> 21
A15: 5 | B15: 2032303481 | C15: AKHARE PRATIK RAJENDRA | D15: 21 | L15: =IF(E15<>"AB",SUM(D15:K15),"AB") -> 21
A16: 6 | B16: 2032303483 | C16: VEDANT NILKANTH THATE | D16: 20 | L16: =IF(E16<>"AB",SUM(D16:K16),"AB") -> 20
A17: 7 | B17: 2032303463 | C17: CHANNE VIJAY SAKHARAM | D17: 23 | L17: =IF(E17<>"AB",SUM(D17:K17),"AB") -> 23
A18: 8 | B18: 2032303487 | C18: PRAJWAL KISHOR SATPUTE | D18: 19 | L18: =IF(E18<>"AB",SUM(D18:K18),"AB") -> 19
A19: 9 | B19: 2032303455 | C19: SHIRSAT MEGHA SHARAD | D19: 21 | L19: =IF(E19<>"AB",SUM(D19:K19),"AB") -> 21
A20: 10 | B20: 2032303516 | C20: PRATIKSHA VISHWASRAO JAWARE | D20: 22 | L20: =IF(E20<>"AB",SUM(D20:K20),"AB") -> 22
A21: 11 | B21: 2032303515 | C21: KOLTE PRAJAKTA ANIL | D21: 17 | L21: =IF(E21<>"AB",SUM(D21:K21),"AB") -> 17
A22: 12 | B22: 2032303502 | C22: JAGTAP PRATHAMESH BHAUSAHEB | D22: 18 | L22: =IF(E22<>"AB",SUM(D22:K22),"AB") -> 18
... A118: 108 | B118: 2032303555 | C118: JISHAN VAHED SHAIKH | D118: 23 | L118: =IF(E118<>"AB",SUM(D118:K118),"AB") -> 23
A119: Total No. of Students: | C119: =COUNT(A11:A118) -> 108
C124: =Faculty -> Narsareaddy Chude
C125: =SubjectDetails!E17 -> Subject Faculty
A129: =SubjectDetails!A24 -> Dr. Ravi Chourasiya | D129: =SubjectDetails!E24 -> Dr. Ashwini Chavan | K129: =SubjectDetails!H24 -> Dr. Priyanka Singh
A130: =SubjectDetails!A25 -> (College Examination Officer) | D130: =SubjectDetails!E25 -> HOD (MCA) | K130: =SubjectDetails!H25 -> Director

Sheet CCE3
A1: Dr. D.Y. Patil Educational Federation's
A2: Dr. D. Y. Patil Institute of Management and Entreprenuer Development, Varale, Pune
A3: (Permanently affiliated to Savitribai Phule Pune University, Accredited by NAAC 'A'
A4: Approved by AICTE, Recognized under 2 (f) & 12 (b) sections of UGC Act)
A5: Comprehensive Concurrent Evaluation (CCE) Sheet
A6: =CONCATENATE(Class," ", spl) -> MCA I SEM I AY 2023-24 | C6: =CONCATENATE("Name of Faculty: ", Faculty) -> Name of Faculty: Narsareaddy Chude | D6: =CONCATENATE("Course Name: ", Sub_Code) -> Course Name: Mini Project
A7: Roll No. | B7: Seat No. | C7: Name of the Student | D7: CCE-III (End Term) | N7: Total Marks Obtained
D8: Q1
C9: Max Marks → | D9: 0 | N9: =D9+E9+F9+G9+H9+I9+J9+K9+L9+M9 -> 0
C10: CO Mapping → | D10: CO1
A11: 1 | B11: 22101 | C11: NAIK ANKIT JIVAN | N11: =IF(D11<>"AB",SUM(D11:M11),"AB") -> 0
A12: 2 | B12: 22102 | C12: ARGADE RAVISHANKAR UTTAM | N12: =IF(D12<>"AB",SUM(D12:M12),"AB") -> 0
A13: 3 | B13: 22103 | C13: ANERAO ONKAR RANGNATH | N13: =IF(D13<>"AB",SUM(D13:M13),"AB") -> 0
A14: 4 | B14: 22104 | C14: MORE KIRAN SUNIL | N14: =IF(D14<>"AB",SUM(D14:M14),"AB") -> 0
A15: 5 | B15: 22105 | C15: KSHIRSAGAR GAURAV SHRIKANT | N15: =IF(D15<>"AB",SUM(D15:M15),"AB") -> 0
A16: 6 | B16: 22106 | C16: SHIRSAT MEGHA SHARAD | N16: =IF(D16<>"AB",SUM(D16:M16),"AB") -> 0
A17: 7 | B17: 22107 | C17: INGALE RAHUL SUNIL | N17: =IF(D17<>"AB",SUM(D17:M17),"AB") -> 0
A18: 8 | B18: 22108 | C18: MD TABISH ANWAR | N18: =IF(D18<>"AB",SUM(D18:M18),"AB") -> 0
A19: 9 | B19: 22109 | C19: PUND SUYOG BHARAT | N19: =IF(D19<>"AB",SUM(D19:M19),"AB") -> 0
A20: 10 | B20: 22110 | C20: JAGTAP DNYANESHWAR RAGHUNATH | N20: =IF(D20<>"AB",SUM(D20:M20),"AB") -> 0
A21: 11 | B21: 22111 | C21: MAHAJAN PRATHAMESH JAGDISH | N21: =IF(D21<>"AB",SUM(D21:M21),"AB") -> 0
A22: 12 | B22: 22112 | C22: PATHAN ALIZABEE AKHTAR KHAN | N22: =IF(D22<>"AB",SUM(D22:M22),"AB") -> 0
... A118: 108 | B118: 22240 | C118: KISHOR LAXMAN HAKE | N118: =IF(D118<>"AB",SUM(D118:M118),"AB") -> 0
A119: Total No. of Students: | C119: =COUNT(A11:A118) -> 108
C123: =Faculty -> Narsareaddy Chude
C124: =SubjectDetails!E17 -> Subject Faculty
A126: =SubjectDetails!A24 -> Dr. Ravi Chourasiya | D126: =SubjectDetails!E24 -> Dr. Ashwini Chavan | H126: =SubjectDetails!H24 -> Dr. Priyanka Singh
A127: =SubjectDetails!A25 -> (College Examination Officer) | D127: =SubjectDetails!E25 -> HOD (MCA) | H127: =SubjectDetails!H25 -> Director

Sheet CCE
A1: Dr. D.Y. Patil Educational Federation's
A2: Dr. D. Y. Patil Institute of Management and Entreprenuer Development, Varale, Pune
A3: (Permanently affiliated to Savitribai Phule Pune University, Accredited by NAAC 'A'
A4: Approved by AICTE, Recognized under 2 (f) & 12 (b) sections of UGC Act)
A5: Comprehensive Concurrent Evaluation (CCE) Sheet
A6: =CONCATENATE(Class," ", spl) -> MCA I SEM I AY 2023-24 | C6: =CONCATENATE("Name of Faculty: ", Faculty) -> Name of Faculty: Narsareaddy Chude | D6: =CONCATENATE("Course Name: ", Sub_Code) -> Course Name: Mini Project
A7: Roll No. | B7: Seat No. | C7: Name | D7: CCE#1 (50) | E7: CCE#2 (25) | F7: CCE#3 (50) | G7: Total (75) | H7: Final (25)
A8: 1 | B8: 22101 | C8: NAIK ANKIT JIVAN | D8: ='CCE1'!J11 -> 47 | E8: ='CCE2'!L11 -> 22 | F8: ='CCE3'!N11 -> 0 | G8: =SUM(Table3[[#This Row],[CCE'#1 (50)]:[CCE'#3 (50)]]) -> 69 | H8: =Table3[[#This Row],[Total (75)]]/('CCE1'!$J$9+'CCE2'!$L$9+'CCE3'!$N$9)*25 -> 23
A9: 2 | B9: 22102 | C9: ARGADE RAVISHANKAR UTTAM | D9: ='CCE1'!J12 -> 47 | E9: ='CCE2'!L12 -> 23 | F9: ='CCE3'!N12 -> 0 | G9: =SUM(Table3[[#This Row],[CCE'#1 (50)]:[CCE'#3 (50)]]) -> 70 | H9: =Table3[[#This Row],[Total (75)]]/('CCE1'!$J$9+'CCE2'!$L$9+'CCE3'!$N$9)*25 -> 23.333333
A10: 3 | B10: 22103 | C10: ANERAO ONKAR RANGNATH | D10: ='CCE1'!J13 -> 46 | E10: ='CCE2'!L13 -> 23 | F10: ='CCE3'!N13 -> 0 | G10: =SUM(Table3[[#This Row],[CCE'#1 (50)]:[CCE'#3 (50)]]) -> 69 | H10: =Table3[[#This Row],[Total (75)]]/('CCE1'!$J$9+'CCE2'!$L$9+'CCE3'!$N$9)*25 -> 23
A11: 4 | B11: 22104 | C11: MORE KIRAN SUNIL | D11: ='CCE1'!J14 -> 49 | E11: ='CCE2'!L14 -> 21 | F11: ='CCE3'!N14 -> 0 | G11: =SUM(Table3[[#This Row],[CCE'#1 (50)]:[CCE'#3 (50)]]) -> 70 | H11: =Table3[[#This Row],[Total (75)]]/('CCE1'!$J$9+'CCE2'!$L$9+'CCE3'!$N$9)*25 -> 23.333333
A12: 5 | B12: 22105 | C12: KSHIRSAGAR GAURAV SHRIKANT | D12: ='CCE1'!J15 -> 44 | E12: ='CCE2'!L15 -> 21 | F12: ='CCE3'!N15 -> 0 | G12: =SUM(Table3[[#This Row],[CCE'#1 (50)]:[CCE'#3 (50)]]) -> 65 | H12: =Table3[[#This Row],[Total (75)]]/('CCE1'!$J$9+'CCE2'!$L$9+'CCE3'!$N$9)*25 -> 21.666667
A13: 6 | B13: 22106 | C13: SHIRSAT MEGHA SHARAD | D13: ='CCE1'!J16 -> 49 | E13: ='CCE2'!L16 -> 20 | F13: ='CCE3'!N16 -> 0 | G13: =SUM(Table3[[#This Row],[CCE'#1 (50)]:[CCE'#3 (50)]]) -> 69 | H13: =Table3[[#This Row],[Total (75)]]/('CCE1'!$J$9+'CCE2'!$L$9+'CCE3'!$N$9)*25 -> 23
A14: 7 | B14: 22107 | C14: INGALE RAHUL SUNIL | D14: ='CCE1'!J17 -> 50 | E14: ='CCE2'!L17 -> 23 | F14: ='CCE3'!N17 -> 0 | G14: =SUM(Table3[[#This Row],[CCE'#1 (50)]:[CCE'#3 (50)]]) -> 73 | H14: =Table3[[#This Row],[Total (75)]]/('CCE1'!$J$9+'CCE2'!$L$9+'CCE3'!$N$9)*25 -> 24.333333
A15: 8 | B15: 22108 | C15: MD TABISH ANWAR | D15: ='CCE1'!J18 -> 48 | E15: ='CCE2'!L18 -> 19 | F15: ='CCE3'!N18 -> 0 | G15: =SUM(Table3[[#This Row],[CCE'#1 (50)]:[CCE'#3 (50)]]) -> 67 | H15: =Table3[[#This Row],[Total (75)]]/('CCE1'!$J$9+'CCE2'!$L$9+'CCE3'!$N$9)*25 -> 22.333333
A16: 9 | B16: 22109 | C16: PUND SUYOG BHARAT | D16: ='CCE1'!J19 -> 49 | E16: ='CCE2'!L19 -> 21 | F16: ='CCE3'!N19 -> 0 | G16: =SUM(Table3[[#This Row],[CCE'#1 (50)]:[CCE'#3 (50)]]) -> 70 | H16: =Table3[[#This Row],[Total (75)]]/('CCE1'!$J$9+'CCE2'!$L$9+'CCE3'!$N$9)*25 -> 23.333333
A17: 10 | B17: 22110 | C17: JAGTAP DNYANESHWAR RAGHUNATH | D17: ='CCE1'!J20 -> 47 | E17: ='CCE2'!L20 -> 22 | F17: ='CCE3'!N20 -> 0 | G17: =SUM(Table3[[#This Row],[CCE'#1 (50)]:[CCE'#3 (50)]]) -> 69 | H17: =Table3[[#This Row],[Total (75)]]/('CCE1'!$J$9+'CCE2'!$L$9+'CCE3'!$N$9)*25 -> 23
A18: 11 | B18: 22111 | C18: MAHAJAN PRATHAMESH JAGDISH | D18: ='CCE1'!J21 -> 47 | E18: ='CCE2'!L21 -> 17 | F18: ='CCE3'!N21 -> 0 | G18: =SUM(Table3[[#This Row],[CCE'#1 (50)]:[CCE'#3 (50)]]) -> 64 | H18: =Table3[[#This Row],[Total (75)]]/('CCE1'!$J$9+'CCE2'!$L$9+'CCE3'!$N$9)*25 -> 21.333333
A19: 12 | B19: 22112 | C19: PATHAN ALIZABEE AKHTAR KHAN | D19: ='CCE1'!J22 -> 47 | E19: ='CCE2'!L22 -> 18 | F19: ='CCE3'!N22 -> 0 | G19: =SUM(Table3[[#This Row],[CCE'#1 (50)]:[CCE'#3 (50)]]) -> 65 | H19: =Table3[[#This Row],[Total (75)]]/('CCE1'!$J$9+'CCE2'!$L$9+'CCE3'!$N$9)*25 -> 21.666667
... A25: 18 | B25: 22118 | C25: SHINDE MAHESH DHANAJI | D25: ='CCE1'!J28 -> 52 | E25: ='CCE2'!L28 -> 20 | F25: ='CCE3'!N28 -> 0 | G25: =SUM(Table3[[#This Row],[CCE'#1 (50)]:[CCE'#3 (50)]]) -> 72 | H25: =Table3[[#This Row],[Total (75)]]/('CCE1'!$J$9+'CCE2'!$L$9+'CCE3'!$N$9)*25 -> 24
A26: 19 | B26: 22119 | C26: BHISE DIPAK VETALA | D26: ='CCE1'!J11 -> 47 | E26: ='CCE2'!L29 -> 14 | F26: ='CCE3'!N29 -> 0 | G26: =SUM(Table3[[#This Row],[CCE'#1 (50)]:[CCE'#3 (50)]]) -> 61 | H26: =Table3[[#This Row],[Total (75)]]/('CCE1'!$J$9+'CCE2'!$L$9+'CCE3'!$N$9)*25 -> 20.333333
A27: 20 | B27: 22120 | C27: BHAGWAT SHREYAS RAVINDRA | D27: ='CCE1'!J12 -> 47 | E27: ='CCE2'!L30 -> 22 | F27: ='CCE3'!N30 -> 0 | G27: =SUM(Table3[[#This Row],[CCE'#1 (50)]:[CCE'#3 (50)]]) -> 69 | H27: =Table3[[#This Row],[Total (75)]]/('CCE1'!$J$9+'CCE2'!$L$9+'CCE3'!$N$9)*25 -> 23
A28: 21 | B28: 22121 | C28: RAHUL VILAS THORAT | D28: ='CCE1'!J13 -> 46 | E28: ='CCE2'!L31 -> 23 | F28: ='CCE3'!N31 -> 0 | G28: =SUM(Table3[[#This Row],[CCE'#1 (50)]:[CCE'#3 (50)]]) -> 69 | H28: =Table3[[#This Row],[Total (75)]]/('CCE1'!$J$9+'CCE2'!$L$9+'CCE3'!$N$9)*25 -> 23
A29: 22 | B29: 22122 | C29: AVINASH BAPU MANE | D29: ='CCE1'!J14 -> 49 | E29: ='CCE2'!L32 -> 21 | F29: ='CCE3'!N32 -> 0 | G29: =SUM(Table3[[#This Row],[CCE'#1 (50)]:[CCE'#3 (50)]]) -> 70 | H29: =Table3[[#This Row],[Total (75)]]/('CCE1'!$J$9+'CCE2'!$L$9+'CCE3'!$N$9)*25 -> 23.333333
A30: 23 | B30: 22123 | C30: SHELKE VAIBHAV MACHHINDRA | D30: ='CCE1'!J15 -> 44 | E30: ='CCE2'!L33 -> 15 | F30: ='CCE3'!N33 -> 0 | G30: =SUM(Table3[[#This Row],[CCE'#1 (50)]:[CCE'#3 (50)]]) -> 59 | H30: =Table3[[#This Row],[Total (75)]]/('CCE1'!$J$9+'CCE2'!$L$9+'CCE3'!$N$9)*25 -> 19.666667
A31: 24 | B31: 22124 | C31: VIJAY SUDHAKAR LOKARE | D31: ='CCE1'!J16 -> 49 | E31: ='CCE2'!L34 -> 22 | F31: ='CCE3'!N34 -> 0 | G31: =SUM(Table3[[#This Row],[CCE'#1 (50)]:[CCE'#3 (50)]]) -> 71 | H31: =Table3[[#This Row],[Total (75)]]/('CCE1'!$J$9+'CCE2'!$L$9+'CCE3'!$N$9)*25 -> 23.666667
A32: 25 | B32: 22125 | C32: CHANDANKHEDE SEJAL ASHOK | D32: ='CCE1'!J17 -> 50 | E32: ='CCE2'!L35 -> 21 | F32: ='CCE3'!N35 -> 0 | G32: =SUM(Table3[[#This Row],[CCE'#1 (50)]:[CCE'#3 (50)]]) -> 71 | H32: =Table3[[#This Row],[Total (75)]]/('CCE1'!$J$9+'CCE2'!$L$9+'CCE3'!$N$9)*25 -> 23.666667
A33: 26 | B33: 22126 | C33: VAISHNAVI SAYAJI PINGAT | D33: ='CCE1'!J18 -> 48 | E33: ='CCE2'!L36 -> 22 | F33: ='CCE3'!N36 -> 0 | G33: =SUM(Table3[[#This Row],[CCE'#1 (50)]:[CCE'#3 (50)]]) -> 70 | H33: =Table3[[#This Row],[Total (75)]]/('CCE1'!$J$9+'CCE2'!$L$9+'CCE3'!$N$9)*25 -> 23.333333
A34: 27 | B34: 22127 | C34: BORSE NIKITA BHALERAO | D34: ='CCE1'!J19 -> 49 | E34: ='CCE2'!L37 -> 23 | F34: ='CCE3'!N37 -> 0 | G34: =SUM(Table3[[#This Row],[CCE'#1 (50)]:[CCE'#3 (50)]]) -> 72 | H34: =Table3[[#This Row],[Total (75)]]/('CCE1'!$J$9+'CCE2'!$L$9+'CCE3'!$N$9)*25 -> 24
A35: 28 | B35: 22128 | C35: RADHIKA NARAYAN SHELAR | D35: ='CCE1'!J20 -> 47 | E35: ='CCE2'!L38 -> 21 | F35: ='CCE3'!N38 -> 0 | G35: =SUM(Table3[[#This Row],[CCE'#1 (50)]:[CCE'#3 (50)]]) -> 68 | H35: =Table3[[#This Row],[Total (75)]]/('CCE1'!$J$9+'CCE2'!$L$9+'CCE3'!$N$9)*25 -> 22.666667
A36: 29 | B36: 22129 | C36: BRAMHANE DIPAK LAXMAN | D36: ='CCE1'!J21 -> 47 | E36: ='CCE2'!L39 -> 20 | F36: ='CCE3'!N39 -> 0 | G36: =SUM(Table3[[#This Row],[CCE'#1 (50)]:[CCE'#3 (50)]]) -> 67 | H36: =Table3[[#This Row],[Total (75)]]/('CCE1'!$J$9+'CCE2'!$L$9+'CCE3'!$N$9)*25 -> 22.333333
A37: 30 | B37: 22130 | C37: PHATKE SAKSHI SANTOSH | D37: ='CCE1'!J22 -> 47 | E37: ='CCE2'!L40 -> 23 | F37: ='CCE3'!N40 -> 0 | G37: =SUM(Table3[[#This Row],[CCE'#1 (50)]:[CCE'#3 (50)]]) -> 70 | H37: =Table3[[#This Row],[Total (75)]]/('CCE1'!$J$9+'CCE2'!$L$9+'CCE3'!$N$9)*25 -> 23.333333
... A86: 79 | B86: 22211 | C86: GANDAGE GANPATI DAYANAND | D86: ='CCE1'!J71 -> 44 | E86: ='CCE2'!L89 -> 21 | F86: ='CCE3'!N89 -> 0 | G86: =SUM(Table3[[#This Row],[CCE'#1 (50)]:[CCE'#3 (50)]]) -> 65 | H86: =Table3[[#This Row],[Total (75)]]/('CCE1'!$J$9+'CCE2'!$L$9+'CCE3'!$N$9)*25 -> 21.666667
A87: 80 | B87: 22212 | C87: SURYAWANSHI DIVYA BAJRANG | D87: ='CCE1'!J11 -> 47 | E87: ='CCE2'!L90 -> 22 | F87: ='CCE3'!N90 -> 0 | G87: =SUM(Table3[[#This Row],[CCE'#1 (50)]:[CCE'#3 (50)]]) -> 69 | H87: =Table3[[#This Row],[Total (75)]]/('CCE1'!$J$9+'CCE2'!$L$9+'CCE3'!$N$9)*25 -> 23
A88: 81 | B88: 22213 | C88: KAMBLE YOGESH ARJUN | D88: ='CCE1'!J12 -> 47 | E88: ='CCE2'!L91 -> 23 | F88: ='CCE3'!N91 -> 0 | G88: =SUM(Table3[[#This Row],[CCE'#1 (50)]:[CCE'#3 (50)]]) -> 70 | H88: =Table3[[#This Row],[Total (75)]]/('CCE1'!$J$9+'CCE2'!$L$9+'CCE3'!$N$9)*25 -> 23.333333
A89: 82 | B89: 22214 | C89: CHAUHAN MANAV JIGAR KUMAR | D89: ='CCE1'!J13 -> 46 | E89: ='CCE2'!L92 -> 22 | F89: ='CCE3'!N92 -> 0 | G89: =SUM(Table3[[#This Row],[CCE'#1 (50)]:[CCE'#3 (50)]]) -> 68 | H89: =Table3[[#This Row],[Total (75)]]/('CCE1'!$J$9+'CCE2'!$L$9+'CCE3'!$N$9)*25 -> 22.666667
A90: 83 | B90: 22215 | C90: AJAY SATISH MANE | D90: ='CCE1'!J14 -> 49 | E90: ='CCE2'!L93 -> 18 | F90: ='CCE3'!N93 -> 0 | G90: =SUM(Table3[[#This Row],[CCE'#1 (50)]:[CCE'#3 (50)]]) -> 67 | H90: =Table3[[#This Row],[Total (75)]]/('CCE1'!$J$9+'CCE2'!$L$9+'CCE3'!$N$9)*25 -> 22.333333
A91: 84 | B91: 22216 | C91: CHOUDHARI SIDDHESH MURALIDHAR | D91: ='CCE1'!J15 -> 44 | E91: ='CCE2'!L94 -> 23 | F91: ='CCE3'!N94 -> 0 | G91: =SUM(Table3[[#This Row],[CCE'#1 (50)]:[CCE'#3 (50)]]) -> 67 | H91: =Table3[[#This Row],[Total (75)]]/('CCE1'!$J$9+'CCE2'!$L$9+'CCE3'!$N$9)*25 -> 22.333333
A92: 85 | B92: 22217 | C92: VARGANTI AARTI YALLAPPA | D92: ='CCE1'!J16 -> 49 | E92: ='CCE2'!L95 -> 22 | F92: ='CCE3'!N95 -> 0 | G92: =SUM(Table3[[#This Row],[CCE'#1 (50)]:[CCE'#3 (50)]]) -> 71 | H92: =Table3[[#This Row],[Total (75)]]/('CCE1'!$J$9+'CCE2'!$L$9+'CCE3'!$N$9)*25 -> 23.666667
A93: 86 | B93: 22218 | C93: KHAIRE PRATIKSHA KAILAS | D93: ='CCE1'!J17 -> 50 | E93: ='CCE2'!L96 -> 18 | F93: ='CCE3'!N96 -> 0 | G93: =SUM(Table3[[#This Row],[CCE'#1 (50)]:[CCE'#3 (50)]]) -> 68 | H93: =Table3[[#This Row],[Total (75)]]/('CCE1'!$J$9+'CCE2'!$L$9+'CCE3'!$N$9)*25 -> 22.666667
...

Sheet CO Int. Attn
A1: Dr. D.Y. Patil Educational Federation's
A2: Dr. D. Y. Patil Institute of Management and Entreprenuer Development, Varale, Pune
A3: (Permanently affiliated to Savitribai Phule Pune University, Accredited by NAAC 'A'
A4: Approved by AICTE, Recognized under 2 (f) & 12 (b) sections of UGC Act)
A6: =CONCATENATE("Faculty Name: ", Faculty) -> Faculty Name: Narsareaddy Chude | I6: Benchmarks | L6: 3 | N6: 70 | O6: % of Students to get | S6: 0.6
A7: =CONCATENATE("Subject Name & Code: ", Sub_Code) -> Subject Name & Code: Mini Project | L7: 2 | N7: 60 | U7: 60
A8: =CONCATENATE("Class: ",Class_AY) -> Class: MCA I SEM I AY 2023-24 | L8: 1 | N8: 50
A11: Sr. No | B11: Seat No. | C11: Name of the Student | D11: CCE1 (Mid Term: 30) | I11: CCE2 (Assignment :20) | N11: CCE3 (End term:50) | S11: Combined Assessment Marks for COs (25) | X11: Total Marks Obtained (25)
D12: CO1 | I12: CO1 | N12: CO1 | S12: CO1
D13: ='CCE1'!D9+'CCE1'!E9 -> 50 | I13: ='CCE2'!D9+'CCE2'!E9 -> 25 | N13: ='CCE3'!D9+'CCE3'!E9 -> 0 | S13: =D13+I13+N13 -> 75 | X13: =SUM(S13:W13) -> 75
A14: 1 | B14: 22101 | C14: NAIK ANKIT JIVAN | D14: ='CCE1'!D11+'CCE1'!E11 -> 47 | I14: ='CCE2'!D11+'CCE2'!E11 -> 22 | N14: ='CCE3'!D11+'CCE3'!E11 -> 0 | S14: =IFERROR(SUM(D14,I14,N14),"AB") -> 69 | X14: =IFERROR(SUM(S14:W14),"AB") -> 69
A15: 2 | B15: 22102 | C15: ARGADE RAVISHANKAR UTTAM | D15: ='CCE1'!D12+'CCE1'!E12 -> 47 | I15: ='CCE2'!D12+'CCE2'!E12 -> 23 | N15: ='CCE3'!D12+'CCE3'!E12 -> 0 | S15: =IFERROR(SUM(D15,I15,N15),"AB") -> 70 | X15: =IFERROR(SUM(S15:W15),"AB") -> 70
A16: 3 | B16: 22103 | C16: ANERAO ONKAR RANGNATH | D16: ='CCE1'!D13+'CCE1'!E13 -> 46 | I16: ='CCE2'!D13+'CCE2'!E13 -> 23 | N16: ='CCE3'!D13+'CCE3'!E13 -> 0 | S16: =IFERROR(SUM(D16,I16,N16),"AB") -> 69 | X16: =IFERROR(SUM(S16:W16),"AB") -> 69
A17: 4 | B17: 22104 | C17: MORE KIRAN SUNIL | D17: ='CCE1'!D14+'CCE1'!E14 -> 49 | I17: ='CCE2'!D14+'CCE2'!E14 -> 21 | N17: ='CCE3'!D14+'CCE3'!E14 -> 0 | S17: =IFERROR(SUM(D17,I17,N17),"AB") -> 70 | X17: =IFERROR(SUM(S17:W17),"AB") -> 70
A18: 5 | B18: 22105 | C18: KSHIRSAGAR GAURAV SHRIKANT | D18: ='CCE1'!D15+'CCE1'!E15 -> 44 | I18: ='CCE2'!D15+'CCE2'!E15 -> 21 | N18: ='CCE3'!D15+'CCE3'!E15 -> 0 | S18: =IFERROR(SUM(D18,I18,N18),"AB") -> 65 | X18: =IFERROR(SUM(S18:W18),"AB") -> 65
A19: 6 | B19: 22106 | C19: SHIRSAT MEGHA SHARAD | D19: ='CCE1'!D16+'CCE1'!E16 -> 49 | I19: ='CCE2'!D16+'CCE2'!E16 -> 20 | N19: ='CCE3'!D16+'CCE3'!E16 -> 0 | S19: =IFERROR(SUM(D19,I19,N19),"AB") -> 69 | X19: =IFERROR(SUM(S19:W19),"AB") -> 69
A20: 7 | B20: 22107 | C20: INGALE RAHUL SUNIL | D20: ='CCE1'!D17+'CCE1'!E17 -> 50 | I20: ='CCE2'!D17+'CCE2'!E17 -> 23 | N20: ='CCE3'!D17+'CCE3'!E17 -> 0 | S20: =IFERROR(SUM(D20,I20,N20),"AB") -> 73 | X20: =IFERROR(SUM(S20:W20),"AB") -> 73
A21: 8 | B21: 22108 | C21: MD TABISH ANWAR | D21: ='CCE1'!D18+'CCE1'!E18 -> 48 | I21: ='CCE2'!D18+'CCE2'!E18 -> 19 | N21: ='CCE3'!D18+'CCE3'!E18 -> 0 | S21: =IFERROR(SUM(D21,I21,N21),"AB") -> 67 | X21: =IFERROR(SUM(S21:W21),"AB") -> 67
A22: 9 | B22: 22109 | C22: PUND SUYOG BHARAT | D22: ='CCE1'!D19+'CCE1'!E19 -> 49 | I22: ='CCE2'!D19+'CCE2'!E19 -> 21 | N22: ='CCE3'!D19+'CCE3'!E19 -> 0 | S22: =IFERROR(SUM(D22,I22,N22),"AB") -> 70 | X22: =IFERROR(SUM(S22:W22),"AB") -> 70
A23: 10 | B23: 22110 | C23: JAGTAP DNYANESHWAR RAGHUNATH | D23: ='CCE1'!D20+'CCE1'!E20 -> 47 | I23: ='CCE2'!D20+'CCE2'!E20 -> 22 | N23: ='CCE3'!D20+'CCE3'!E20 -> 0 | S23: =IFERROR(SUM(D23,I23,N23),"AB") -> 69 | X23: =IFERROR(SUM(S23:W23),"AB") -> 69
A24: 11 | B24: 22111 | C24: MAHAJAN PRATHAMESH JAGDISH | D24: ='CCE1'!D21+'CCE1'!E21 -> 47 | I24: ='CCE2'!D21+'CCE2'!E21 -> 17 | N24: ='CCE3'!D21+'CCE3'!E21 -> 0 | S24: =IFERROR(SUM(D24,I24,N24),"AB") -> 64 | X24: =IFERROR(SUM(S24:W24),"AB") -> 64
A25: 12 | B25: 22112 | C25: PATHAN ALIZABEE AKHTAR KHAN | D25: ='CCE1'!D22+'CCE1'!E22 -> 47 | I25: ='CCE2'!D22+'CCE2'!E22 -> 18 | N25: ='CCE3'!D22+'CCE3'!E22 -> 0 | S25: =IFERROR(SUM(D25,I25,N25),"AB") -> 65 | X25: =IFERROR(SUM(S25:W25),"AB") -> 65
... A121: 108 | B121: 22240 | C121: KISHOR LAXMAN HAKE | D121: ='CCE1'!D118+'CCE1'!E118 -> 41 | I121: ='CCE2'!D118+'CCE2'!E118 -> 23 | N121: ='CCE3'!D118+'CCE3'!E118 -> 0 | S121: =IFERROR(SUM(D121,I121,N121),"AB") -> 64 | X121: =IFERROR(SUM(S121:W121),"AB") -> 64
C122: No of Students (y) | D122: =IFERROR(COUNT(D14:D121),"NA") -> 108 | I122: =IFERROR(COUNT(I14:I121),"NA") -> 108 | S122: =IFERROR(COUNT(S14:S121),"NA") -> 108 | X122: =IFERROR(COUNT(X14:X121),"NA") -> 108
C123: =CONCATENATE("No of students more than ",70, "% = (x1)") -> No of students more than 70% = (x1) | D123: =COUNTIF(D14:D121,">="&D13*70%) -> 101 | I123: =COUNTIF(I14:I121,">="&I13*70%) -> 95 | S123: =COUNTIF(S14:S121,">="&S13*70%) -> 101 | X123: =COUNTIF(X14:X121,">="&X13*70%) -> 101
C124: =CONCATENATE("No of students between 70 and ",60, "% = (x2)") -> No of students between 70 and 60% = (x2) | D124: =COUNTIFS(D14:D121,">="&D13*60%,D14:D121,"<"&D13*70%) -> 0 | I124: =COUNTIFS(I14:I121,">="&I13*60%,I14:I121,"<"&I13*70%) -> 4 | S124: =COUNTIFS(S14:S121,">="&S13*60%,S14:S121,"<"&S13*70%) -> 0 | X124: =COUNTIFS(X14:X121,">="&X13*60%,X14:X121,"<"&X13*70%) -> 0
C125: =CONCATENATE("No of students between 60 and ",50, "% = (x3)") -> No of students between 60 and 50% = (x3) | D125: =COUNTIFS(D14:D121,">="&D13*50%,D14:D121,"<"&D13*60%) -> 0 | I125: =COUNTIFS(I14:I121,">="&I13*50%,I14:I121,"<"&I13*60%) -> 2 | S125: =COUNTIFS(S14:S121,">="&S13*50%,S14:S121,"<"&S13*60%) -> 0 | X125: =COUNTIFS(X14:X121,">="&X13*50%,X14:X121,"<"&X13*60%) -> 0
C126: No of students between 40 and 50 % = (x4) | D126: =COUNTIFS(D14:D121,">="&D13*40%,D14:D121,"<"&D13*50%) -> 0 | I126: =COUNTIFS(I14:I121,">="&I13*40%,I14:I121,"<"&I13*50%) -> 0 | S126: =COUNTIFS(S14:S121,">="&S13*40%,S14:S121,"<"&S13*50%) -> 0 | X126: =COUNTIFS(X14:X121,">="&X13*40%,X14:X121,"<"&X13*50%) -> 0
C127: No of students between less than 40 % = (x5) | D127: =COUNTIF(D14:D121,"<"&D13*40%) -> 7 | I127: =COUNTIF(I14:I121,"<"&I13*40%) -> 7 | S127: =COUNTIF(S14:S121,"<"&S13*40%) -> 7 | X127: =COUNTIF(X14:X121,"<"&X13*40%) -> 7
C128: CO Attainment Percentage | D128: =(D123*3+D124*2+D125*1)/(COUNT(D14:D121)*3)*100 -> 93.518519 | I128: =(I123*3+I124*2+I125*1)/(COUNT(I14:I121)*3)*100 -> 91.049383 | S128: =(S123*3+S124*2+S125*1)/(COUNT(S14:S121)*3)*100 -> 93.518519 | X128: =(X123*3+X124*2+X125*1)/(COUNT(X14:X121)*3)*100 -> 93.518519
C129: CO Benchmark Level | D129: =IF(D128<>"NA",IF(D128>=70,3,IF(D128>=60,2,IF(D128>=50,1,"0"))),"NA") -> 3 | I129: =IF(I128<>"NA",IF(I128>=70,3,IF(I128>=60,2,IF(I128>=50,1,"0"))),"NA") -> 3 | S129: =IF(S128<>"NA",IF(S128>=70,3,IF(S128>=60,2,IF(S128>=50,1,"0"))),"NA") -> 3 | X129: =IF(X128<>"NA",IF(X128>=70,3,IF(X128>=60,2,IF(X128>=50,1,"0"))),"NA") -> 3
C131: Attainment based on Comprehensive Concurrent Evaluation (CCE) = Avg. of all COs | D131: =AVERAGE(S125:W125) -> 0 | E131: =AVERAGE(D124:X124) -> 1 | F131: =(3/100)*E131 -> 0.03 | G131: Average
G132: CO1 | H132: =AVERAGE(D128,I128) -> 92.283951
B136: =Faculty -> Narsareaddy Chude
A142: =SubjectDetails!A24 -> Dr. Ravi Chourasiya | D142: =SubjectDetails!E24 -> Dr. Ashwini Chavan | N142: =SubjectDetails!H24 -> Dr. Priyanka Singh
A143: =SubjectDetails!A25 -> (College Examination Officer) | D143: =SubjectDetails!E25 -> HOD (MCA) | N143: =SubjectDetails!H25 -> Director

Sheet CO Ext. Attn
A1: Dr. D.Y. Patil Educational Federation's
A2: Dr. D. Y. Patil Institute of Management and Entreprenuer Development, Varale, Pune
A3: (Permanently affiliated to Savitribai Phule Pune University, Accredited by NAAC 'A'
A4: Approved by AICTE, Recognized under 2 (f) & 12 (b) sections of UGC Act)
A6: =CONCATENATE("Faculty Name: ", Faculty) -> Faculty Name: Narsareaddy Chude | D6: Benchmark | F6: 3 | G6: 0.7 | H6: Percentage of Students to get | J6: 0.6
A7: =CONCATENATE("Subject Name & Code: ", Sub_Code) -> Subject Name & Code: Mini Project | F7: 2 | G7: 0.6
A8: =CONCATENATE("Class: ",Class_AY) -> Class: MCA I SEM I AY 2023-24 | F8: 1 | G8: 0.5
A10: Course Outcome Attainment Calculations - External Assessment (SPPU)
A11: Roll No. | B11: Seat No. | C11: Name of the Student | D11: Equal Weightage to all COs
D13: 50
A14: 1 | B14: 2032303524 | C14: JAGTAP VAISHNAVI VILAS | D14: 45
A15: 2 | B15: 2032303491 | C15: MANE SHARVI MAHENDRA | D15: 45
A16: 3 | B16: 2032303500 | C16: SAYYAD TARNUM ISMAIL | D16: 43
A17: 4 | B17: 2032303484 | C17: SALUNKHE SANIYA SANTOSH | D17: 44
A18: 5 | B18: 2032303481 | C18: AKHARE PRATIK RAJENDRA | D18: 45
A19: 6 | B19: 2032303483 | C19: VEDANT NILKANTH THATE | D19: 45
A20: 7 | B20: 2032303463 | C20: CHANNE VIJAY SAKHARAM | D20: 45
A21: 8 | B21: 2032303487 | C21: PRAJWAL KISHOR SATPUTE | D21: 45
A22: 9 | B22: 2032303455 | C22: SHIRSAT MEGHA SHARAD | D22: 45
A23: 10 | B23: 2032303516 | C23: PRATIKSHA VISHWASRAO JAWARE | D23: 45
A24: 11 | B24: 2032303515 | C24: KOLTE PRAJAKTA ANIL | D24: 44
A25: 12 | B25: 2032303502 | C25: JAGTAP PRATHAMESH BHAUSAHEB | D25: 44
... A121: 108 | B121: 2032303555 | C121: JISHAN VAHED SHAIKH | D121: 41
C122: No of Students (y) | D122: =IFERROR(COUNT(D14:D121),"NA") -> 108
C123: =CONCATENATE("No of students more than ",70, "% = (x1)") -> No of students more than 70% = (x1) | D123: =COUNTIF(D14:D121,">="&D13*70%) -> 101
C124: =CONCATENATE("No of students between 70 and ",60, "% = (x2)") -> No of students between 70 and 60% = (x2) | D124: =COUNTIFS(D14:D121,">="&D13*60%,D14:D121,"<"&D13*70%) -> 0
C125: =CONCATENATE("No of students between 60 and ",50, "% = (x3)") -> No of students between 60 and 50% = (x3) | D125: =COUNTIFS(D14:D121,">="&D13*50%,D14:D121,"<"&D13*60%) -> 0
C126: No of students between 40 and 50 % = (x4) | D126: =COUNTIFS(D14:D121,">="&D13*40%,D14:D121,"<"&D13*50%) -> 0
C127: No of students between less than 40 % = (x5) | D127: =COUNTIF(D14:D121,"<"&D13*40%) -> 7
C128: CO Attainment Percentage | D128: =(D123*3+D124*2+D125*1)/(COUNT(D14:D121)*3)*100 -> 93.518519
C129: CO Benchmark Level | D129: =IF(D128<>"NA",IF(D128>=70,3,IF(D128>=60,2,IF(D128>=50,1,"0"))),"NA") -> 3
C133: Attainment based on External Evaluation = Avg. of all COs | D133: =D128 -> 93.518519
B138: =Faculty -> Narsareaddy Chude
A143: =SubjectDetails!A24 -> Dr. Ravi Chourasiya | D143: =SubjectDetails!E24 -> Dr. Ashwini Chavan | I143: =SubjectDetails!H24 -> Dr. Priyanka Singh
A144: =SubjectDetails!A25 -> (College Examination Officer) | D144: =SubjectDetails!E25 -> HOD (MCA) | I144: =SubjectDetails!H25 -> Director

Sheet OverallCO Attainment
A1: Dr. D.Y. Patil Educational Federation's
A2: Dr. D. Y. Patil Institute of Management and Entreprenuer Development, Varale, Pune
A3: (Permanently affiliated to Savitribai Phule Pune University, Accredited by NAAC 'A'
A4: Approved by AICTE, Recognized under 2 (f) & 12 (b) sections of UGC Act)
B5: =CONCATENATE("Faculty Name: ", Faculty) -> Faculty Name: Narsareaddy Chude
B6: =CONCATENATE("Subject Name & Code: ", Sub_Code) -> Subject Name & Code: Mini Project
B7: =CONCATENATE("Class: ",Class_AY) -> Class: MCA I SEM I AY 2023-24
B9: OVERALL CO ATTAINMENT FOR COURSE
B10: Particulars | C10: CO1
B11: CO ATTAINMENT PERCENTAGE - INTERNAL ASSESSMENT (A1) | C11: ='CO Int. Attn'!H132 -> 92.283951
B12: CO ATTAINMENT PERCENTAGE - EXTERNAL ASSESSMENT (SPPU) (A2) | C12: ='CO Ext. Attn'!D133 -> 93.518519
B13: CO ATTAINMENT PERCENTAGE - DIRECT ASSESSMENT Direct Attainment=(Int. Weightage X A1) + ( Ext. Weightage X A2) | C13: =(int_wt*C11)+(ext_wt*C12) -> 92.777778
B14: CO ATTAINMENT PERCENTAGE - INDIRECT (SURVEY) | C14: =Sheet1!D119 -> 83.888889
B15: OVERALL CO ATTAINMENT FOR COURSE | C15: =(0.8*C13)+(0.2*C14) -> 91
B16: CO ATTAINMENT LEVEL | C16: =IF(C15>=$E20,3,IF(C15>=$E21,2,IF(C15>=$E22,1,0))) -> 3
B18: Percentage of Students to get 60% of Marks
B20: Benchmark | D20: 3 | E20: 70
D21: 2 | E21: 60
D22: 1 | E22: 50
B27: =Faculty -> Narsareaddy Chude
B28: =SubjectDetails!$E$17 -> Subject Faculty
A33: =SubjectDetails!$A$24 -> Dr. Ravi Chourasiya | D33: =SubjectDetails!$E$24 -> Dr. Ashwini Chavan | H33: =SubjectDetails!$H$24 -> Dr. Priyanka Singh
A34: =SubjectDetails!$A$25 -> (College Examination Officer) | D34: =SubjectDetails!$E$25 -> HOD (MCA) | H34: =SubjectDetails!$H$25 -> Director

Sheet CO PO Attainment
B1: Dr. D.Y. Patil Educational Federation's
B2: Dr. D. Y. Patil Institute of Management and Entreprenuer Development, Varale, Pune
B3: (Permanently affiliated to Savitribai Phule Pune University, Accredited by NAAC 'A'
B4: Approved by AICTE, Recognized under 2 (f) & 12 (b) sections of UGC Act)
B6: =CONCATENATE("Faculty Name: ", Faculty) -> Faculty Name: Narsareaddy Chude
B7: =CONCATENATE("Subject Name & Code: ", Sub_Code) -> Subject Name & Code: Mini Project
B8: =CONCATENATE("Class: ",Class_AY) -> Class: MCA I SEM I AY 2023-24
B9: CO-PO Attainment Calculations
B10: Overall CO Attainment % | D10: PO1 | E10: PO2 | F10: PO3 | G10: PO4 | H10: PO5 | I10: PO6 | J10: PO7 | K10: PO8
B11: Average Mapping (M) | D11: ='CO Mapping PO '!B18 -> 3 | E11: ='CO Mapping PO '!C18 -> 3 | F11: ='CO Mapping PO '!D18 -> 3 | G11: ='CO Mapping PO '!E18 -> 3 | H11: ='CO Mapping PO '!F18 -> 3 | I11: ='CO Mapping PO '!G18 -> 3 | J11: ='CO Mapping PO '!H18 -> 3 | K11: ='CO Mapping PO '!I18 -> 3
B12: CO1 | C12: ='OverallCO Attainment'!C15 -> 91 | D12: 3 | E12: 3 | F12: 3 | G12: 3 | H12: 3 | I12: 3 | J12: 3 | K12: 3
C17: Perecentage | D17: =(C12*D12)/(D12) -> 91 | E17: =(C12*E12)/(E12) -> 91 | F17: =(C12*F12)/(F12) -> 91 | G17: =(C12*G12)/(G12) -> 91 | H17: =(C12*H12)/(H12) -> 91 | I17: =(C12*I12)/(I12) -> 91 | J17: =(C12*J12)/(J12) -> 91 | K17: =(C12*K12)/(K12) -> 91
C18: Level | D18: =D17/100*3 -> 2.73 | E18: =E17/100*3 -> 2.73 | F18: =F17/100*3 -> 2.73 | G18: =G17/100*3 -> 2.73 | H18: =H17/100*3 -> 2.73 | I18: =I17/100*3 -> 2.73 | J18: =J17/100*3 -> 2.73 | K18: =K17/100*3 -> 2.73
B24: =Faculty -> Narsareaddy Chude
B25: =Designation -> Assistant Professor
B31: =SubjectDetails!$A$24 -> Dr. Ravi Chourasiya | E31: =SubjectDetails!$E$24 -> Dr. Ashwini Chavan | I31: =SubjectDetails!$H$24 -> Dr. Priyanka Singh
B32: =SubjectDetails!$A$25 -> (College Examination Officer) | E32: =SubjectDetails!$E$25 -> HOD (MCA) | I32: =SubjectDetails!$H$25 -> Director

Sheet Sheet1
A1: Dr. D.Y. Patil Educational Federation's
A2: Dr. D. Y. Patil Institute of Management and Entreprenuer Development, Varale, Pune
A3: (Permanently affiliated to Savitribai Phule Pune University, Accredited by NAAC 'A'
A4: Approved by AICTE, Recognized under 2 (f) & 12 (b) sections of UGC Act)
A5: Indirect Attainment
A6: =CONCATENATE(Class," ", spl) -> MCA I SEM I AY 2023-24 | D6: Course Exit Survey
A7: Roll No. | B7: Seat No. | C7: Name of the Student | L7: Total Marks Obtained
D8: CO1
D9: 5 | L9: =SUM(D9:K9) -> 5
A10: 1 | B10: 22101 | C10: NAIK ANKIT JIVAN | D10: 3 | L10: =IF(F10<>"AB",SUM(D10:K10),"AB") -> 3
A11: 2 | B11: 22102 | C11: ARGADE RAVISHANKAR UTTAM | D11: 4 | L11: =IF(F11<>"AB",SUM(D11:K11),"AB") -> 4
A12: 3 | B12: 22103 | C12: ANERAO ONKAR RANGNATH | D12: 5 | L12: =IF(F12<>"AB",SUM(D12:K12),"AB") -> 5
A13: 4 | B13: 22104 | C13: MORE KIRAN SUNIL | D13: 4 | L13: =IF(F13<>"AB",SUM(D13:K13),"AB") -> 4
A14: 5 | B14: 22105 | C14: KSHIRSAGAR GAURAV SHRIKANT | D14: 4 | L14: =IF(F14<>"AB",SUM(D14:K14),"AB") -> 4
A15: 6 | B15: 22106 | C15: SHIRSAT MEGHA SHARAD | D15: 3 | L15: =IF(F15<>"AB",SUM(D15:K15),"AB") -> 3
A16: 7 | B16: 22107 | C16: INGALE RAHUL SUNIL | D16: 4 | L16: =IF(F16<>"AB",SUM(D16:K16),"AB") -> 4
A17: 8 | B17: 22108 | C17: MD TABISH ANWAR | D17: 4 | L17: =IF(F17<>"AB",SUM(D17:K17),"AB") -> 4
A18: 9 | B18: 22109 | C18: PUND SUYOG BHARAT | D18: 4 | L18: =IF(F18<>"AB",SUM(D18:K18),"AB") -> 4
A19: 10 | B19: 22110 | C19: JAGTAP DNYANESHWAR RAGHUNATH | D19: 5 | L19: =IF(F19<>"AB",SUM(D19:K19),"AB") -> 5
A20: 11 | B20: 22111 | C20: MAHAJAN PRATHAMESH JAGDISH | D20: 4 | L20: =IF(F20<>"AB",SUM(D20:K20),"AB") -> 4
A21: 12 | B21: 22112 | C21: PATHAN ALIZABEE AKHTAR KHAN | D21: 2 | L21: =IF(F21<>"AB",SUM(D21:K21),"AB") -> 2
... A117: 108 | B117: 22240 | C117: KISHOR LAXMAN HAKE | D117: 4 | L117: =IF(F117<>"AB",SUM(D117:K117),"AB") -> 4
C118: Average | D118: =AVERAGE(D10:D117) -> 4.1944444 | L118: =AVERAGE(L10:L117) -> 4.1944444
C119: Attainment | D119: =D118/5*100 -> 83.888889 | L119: =L118/25*100 -> 16.777778
M120: Overall Semester wise Attainment
A121: Total No. of Students: | C121: =COUNT(A10:A117) -> 108
B127: =[1]SubjectDetails!$A$24 -> Dr. Ravi Chourasiya | D127: =[1]SubjectDetails!$E$24 -> Dr. Ashwini Chavan | J127: =[1]SubjectDetails!$H$24 -> Dr. Priyanka Singh
B128: =[1]SubjectDetails!$A$25 -> (College Examination Officer) | D128: =[1]SubjectDetails!$E$25 -> HOD (MCA) | I128: =[1]SubjectDetails!$H$25 -> Director
